File: PB15_UCS_1622.csv
Index,Date,Time,Counter,FbLoad,Force(kN),LVDT1,LVDT2,Chain,OutputPower,Stress [MPa],Strain Ax. [%],Strain Ax [-],Strain Rad. [%],Strain Vol. [%],Strain Vol [-],Gemidd
0,44713.63767,0,58917538,1.96332,1.652886,-0.813465,-0.82091,21.988907,0.368544,2.336079,0.206116,0.00206116,-0.009175,0.196929,0.00196929,-0.817188
8,44713.63769,1.872701,58917540,1.948651,1.624869,-0.813953,-0.821206,21.988981,0.367561,2.294158,0.205384,0.00205384,-0.009175,0.196118,0.00196118,-0.817605
16,44713.63772,3.872701,58917542,1.935328,1.614008,-0.814158,-0.821568,21.988907,0.367101,2.277111,0.205137,0.00205137,-0.009175,0.195956,0.00195956,-0.817888
24,44713.63774,5.872701,58917544,1.889251,1.557805,-0.815288,-0.822587,21.988907,0.365024,2.206064,0.203732,0.00203732,-0.009175,0.194584,0.00194584,-0.818981
32,44713.63776,7.872701,58917546,1.895692,1.559905,-0.815307,-0.822455,21.988907,0.365037,2.20247,0.203699,0.00203699,-0.009175,0.194572,0.00194572,-0.818861
40,44713.63779,9.872701,58917548,1.904834,1.553495,-0.815288,-0.822718,21.988981,0.364942,2.205782,0.203624,0.00203624,-0.009175,0.194452,0.00194452,-0.818946
48,44713.63781,11.872701,58917550,1.896964,1.550757,-0.815292,-0.822587,21.988907,0.364951,2.200101,0.203555,0.00203555,-0.008991,0.194519,0.00194519,-0.818995
56,44713.63783,13.872701,58917552,1.887077,1.553942,-0.815311,-0.822652,21.988834,0.364979,2.203807,0.203559,0.00203559,-0.008991,0.194537,0.00194537,-0.819014
64,44713.63786,15.872701,58917554,1.893267,1.562393,-0.81534,-0.822587,21.988834,0.365,2.208088,0.203578,0.00203578,-0.008991,0.194586,0.00194586,-0.818979
72,44713.63788,17.872701,58917556,1.89924,1.555285,-0.815314,-0.822521,21.988907,0.36498,2.205564,0.20359,0.0020359,-0.009083,0.194599,0.00194599,-0.818971
80,44713.6379,19.872701,58917558,1.887346,1.559418,-0.815291,-0.822718,21.988907,0.364928,2.208638,0.203729,0.00203729,-0.009175,0.19461,0.0019461,-0.818873
88,44713.63793,21.872701,58917560,1.890357,1.55719,-0.815292,-0.822356,21.988907,0.36499,2.207839,0.203644,0.00203644,-0.008991,0.194592,0.00194592,-0.818846
96,44713.63795,23.872701,58917562,1.882372,1.556518,-0.815389,-0.822652,21.988981,0.364733,2.201994,0.203678,0.00203678,-0.008991,0.194687,0.00194687,-0.818884
104,44713.63797,25.872701,58917564,1.898591,1.560289,-0.815396,-0.822784,21.988907,0.364761,2.20474,0.203433,0.00203433,-0.008899,0.194534,0.00194534,-0.819047
112,44713.63799,27.872701,58917566,1.886525,1.552117,-0.815421,-0.822718,21.988907,0.36476,2.205142,0.203493,0.00203493,-0.008991,0.194502,0.00194502,-0.819076
120,44713.63802,29.872701,58917568,1.895072,1.559401,-0.81539,-0.822455,21.988907,0.364728,2.20576,0.203565,0.00203565,-0.009083,0.194592,0.00194592,-0.818911
128,44713.63804,31.872701,58917570,1.890254,1.559232,-0.81543,-0.822389,21.988907,0.36476,2.203671,0.203608,0.00203608,-0.008991,0.194705,0.00194705,-0.818896
136,44713.63806,33.872701,58917572,1.895879,1.556826,-0.815422,-0.822488,21.988907,0.364773,2.207162,0.203481,0.00203481,-0.008899,0.194543,0.00194543,-0.819074
144,44713.63809,35.872701,58917574,1.892442,1.555338,-0.815427,-0.822488,21.988907,0.364762,2.200334,0.203571,0.00203571,-0.008899,0.194649,0.00194649,-0.818968
152,44713.63811,37.872701,58917576,1.891288,1.556947,-0.815416,-0.822619,21.988907,0.36475,2.202588,0.203496,0.00203496,-0.009083,0.194534,0.00194534,-0.819037
160,44713.63813,39.872701,58917578,1.893822,1.554516,-0.815399,-0.822587,21.988981,0.364799,2.20233,0.2035,0.002035,-0.009083,0.19457,0.0019457,-0.818927
168,44713.63816,41.872701,58917580,1.897444,1.557368,-0.815401,-0.822455,21.988981,0.364718,2.204799,0.203581,0.00203581,-0.009083,0.19447,0.0019447,-0.818996
176,44713.63818,43.872701,58917582,1.88918,1.556623,-0.815419,-0.822817,21.988981,0.364769,2.202349,0.203476,0.00203476,-0.008808,0.19472,0.0019472,-0.819051
184,44713.6382,45.872701,58917584,1.876201,1.557157,-0.815428,-0.822488,21.988834,0.364773,2.204397,0.203642,0.00203642,-0.008808,0.194835,0.00194835,-0.818934
192,44713.63823,47.872701,58917586,1.885769,1.556099,-0.815385,-0.822619,21.98876,0.364894,2.201823,0.203576,0.00203576,-0.008991,0.194627,0.00194627,-0.81898
200,44713.63825,49.872701,58917588,1.877985,1.558343,-0.815391,-0.822554,21.98876,0.364994,2.200275,0.203542,0.00203542,-0.008899,0.194591,0.00194591,-0.819004
208,44713.63827,51.872701,58917590,1.885907,1.551931,-0.815399,-0.822652,21.988686,0.364819,2.196702,0.203486,0.00203486,-0.008899,0.194587,0.00194587,-0.819043
216,44713.6383,53.872701,58917592,1.889964,1.554639,-0.815417,-0.822685,21.988686,0.364775,2.20342,0.203466,0.00203466,-0.008991,0.194499,0.00194499,-0.81909
224,44713.63832,55.872701,58917594,1.894426,1.552485,-0.815406,-0.822685,21.988612,0.364772,2.199141,0.203591,0.00203591,-0.008991,0.194522,0.00194522,-0.81897
232,44713.63834,57.872701,58917596,1.885398,1.556455,-0.815403,-0.822718,21.988612,0.364827,2.199496,0.20347,0.0020347,-0.009083,0.194426,0.00194426,-0.819027
240,44713.63837,59.872701,58917598,1.893263,1.557523,-0.81535,-0.822258,21.988612,0.365016,2.207128,0.203694,0.00203694,-0.008716,0.194961,0.00194961,-0.818909
248,44713.63839,61.872701,58917600,1.896976,1.56455,-0.815318,-0.822587,21.988686,0.364993,2.210561,0.203658,0.00203658,-0.008624,0.194944,0.00194944,-0.818986
256,44713.63841,63.872701,58917602,1.886291,1.556247,-0.815432,-0.822225,21.988686,0.364722,2.199837,0.203713,0.00203713,-0.008991,0.194722,0.00194722,-0.818865
264,44713.63844,65.872701,58917604,1.902872,1.565195,-0.815289,-0.822291,21.988834,0.365134,2.218519,0.203699,0.00203699,-0.008991,0.194755,0.00194755,-0.818861
272,44713.63846,67.872701,58917606,1.896524,1.559124,-0.815281,-0.822356,21.98876,0.365104,2.210617,0.203906,0.00203906,-0.008899,0.195006,0.00195006,-0.818749
280,44713.63848,69.872701,58917608,1.898594,1.558506,-0.815389,-0.822619,21.988834,0.364989,2.204856,0.203611,0.00203611,-0.008899,0.194712,0.00194712,-0.818934
288,44713.6385,71.872701,58917610,1.887476,1.552701,-0.815357,-0.822324,21.988834,0.364986,2.206542,0.203709,0.00203709,-0.008716,0.194993,0.00194993,-0.818879
296,44713.63853,73.872701,58917612,1.893558,1.559923,-0.815391,-0.822554,21.988834,0.364982,2.205155,0.203689,0.00203689,-0.008899,0.194877,0.00194877,-0.818927
304,44713.63855,75.872701,58917614,1.887318,1.556015,-0.815382,-0.822587,21.988907,0.365089,2.204742,0.203728,0.00203728,-0.008716,0.194997,0.00194997,-0.818949
312,44713.63857,77.872701,58917616,1.893866,1.556982,-0.815418,-0.822488,21.988834,0.365026,2.204879,0.203668,0.00203668,-0.008624,0.195044,0.00195044,-0.818916
320,44713.6386,79.872701,58917618,1.888799,1.562348,-0.815377,-0.822324,21.98876,0.365068,2.203152,0.203736,0.00203736,-0.008991,0.194836,0.00194836,-0.818805
328,44713.63862,81.872701,58917620,1.886602,1.563902,-0.815376,-0.822488,21.988686,0.36506,2.207005,0.203742,0.00203742,-0.008991,0.194751,0.00194751,-0.818864
336,44713.63864,83.872701,58917622,1.896383,1.557909,-0.815403,-0.822225,21.988612,0.364959,2.204765,0.203563,0.00203563,-0.008991,0.194569,0.00194569,-0.818991
344,44713.63867,85.872701,58917624,1.895471,1.56104,-0.81541,-0.822225,21.988612,0.365006,2.201099,0.203741,0.00203741,-0.008624,0.195111,0.00195111,-0.818865
352,44713.63869,87.872701,58917626,1.90191,1.554078,-0.815391,-0.822488,21.988612,0.365013,2.207644,0.203519,0.00203519,-0.008899,0.19478,0.0019478,-0.818908
360,44713.63871,89.872701,58917628,1.879925,1.55987,-0.815405,-0.822356,21.988539,0.364951,2.208571,0.203618,0.00203618,-0.008808,0.19481,0.0019481,-0.818799
368,44713.63874,91.872701,58917630,1.87881,1.558583,-0.815415,-0.822192,21.988612,0.365025,2.201367,0.203608,0.00203608,-0.008808,0.194801,0.00194801,-0.818832
376,44713.63876,93.872701,58917632,1.889431,1.556389,-0.815405,-0.822521,21.988465,0.365008,2.202633,0.203747,0.00203747,-0.008808,0.194848,0.00194848,-0.818861
384,44713.63878,95.872701,58917634,1.882714,1.561481,-0.815415,-0.822356,21.988539,0.36498,2.200614,0.203556,0.00203556,-0.008899,0.194745,0.00194745,-0.819003
392,44713.63881,97.872701,58917636,1.873456,1.555513,-0.815416,-0.822521,21.988539,0.364988,2.197746,0.203612,0.00203612,-0.008624,0.194947,0.00194947,-0.818984
400,44713.63883,99.872701,58917638,1.90231,1.578368,-0.814893,-0.821798,21.988612,0.365926,2.237928,0.204298,0.00204298,-0.008624,0.195587,0.00195587,-0.81843
408,44713.63885,101.872701,58917640,1.965648,1.638364,-0.81388,-0.820943,21.988686,0.368004,2.314534,0.2058,0.002058,-0.008624,0.196962,0.00196962,-0.817351
416,44713.63887,103.872701,58917642,2.017894,1.684556,-0.812903,-0.820056,21.98876,0.369838,2.387226,0.20712,0.0020712,-0.008716,0.19839,0.0019839,-0.816509
424,44713.6389,105.872701,58917644,2.062533,1.740896,-0.811908,-0.819004,21.988834,0.372028,2.459843,0.208654,0.00208654,-0.008716,0.199838,0.00199838,-0.815495
432,44713.63892,107.872701,58917646,2.113864,1.785433,-0.810945,-0.817952,21.988907,0.373873,2.523418,0.209872,0.00209872,-0.008808,0.201041,0.00201041,-0.814573
440,44713.63894,109.872701,58917648,2.172004,1.840989,-0.809964,-0.81713,21.988981,0.375819,2.60005,0.211457,0.00211457,-0.009175,0.202282,0.00202282,-0.813446
448,44713.63897,111.872701,58917650,2.227607,1.892999,-0.808971,-0.816013,21.989055,0.377802,2.677078,0.212829,0.00212829,-0.009083,0.203771,0.00203771,-0.812486
456,44713.63899,113.872701,58917652,2.267735,1.947316,-0.807998,-0.814928,21.989055,0.379815,2.750824,0.214157,0.00214157,-0.009175,0.204982,0.00204982,-0.811574
464,44713.63901,115.872701,58917654,2.319598,1.997216,-0.807034,-0.813843,21.988981,0.381857,2.821122,0.215542,0.00215542,-0.009266,0.206333,0.00206333,-0.810604
472,44713.63904,117.872701,58917656,2.370561,2.052639,-0.806024,-0.812824,21.989055,0.383991,2.901346,0.217058,0.00217058,-0.009358,0.2077,0.002077,-0.809526
480,44713.63906,119.872701,58917658,2.429631,2.107267,-0.805042,-0.812002,21.989055,0.385839,2.978361,0.21844,0.0021844,-0.009542,0.209111,0.00209111,-0.808427
488,44713.63908,121.872701,58917660,2.494933,2.169798,-0.80406,-0.811082,21.989055,0.38806,3.058664,0.219979,0.00219979,-0.009633,0.210377,0.00210377,-0.807477
496,44713.63911,123.872701,58917662,2.542668,2.21722,-0.803094,-0.809833,21.989055,0.389848,3.134058,0.221331,0.00221331,-0.009358,0.211966,0.00211966,-0.806552
504,44713.63913,125.872701,58917664,2.587721,2.272546,-0.802141,-0.808715,21.989128,0.392019,3.212339,0.22273,0.0022273,-0.009633,0.213228,0.00213228,-0.805481
512,44713.63915,127.872701,58917666,2.646899,2.333894,-0.801209,-0.807795,21.989128,0.393844,3.292134,0.224288,0.00224288,-0.009633,0.214654,0.00214654,-0.804492
520,44713.63918,129.872701,58917668,2.69524,2.387686,-0.800219,-0.80671,21.989423,0.395849,3.375531,0.225621,0.00225621,-0.009633,0.215941,0.00215941,-0.803581
528,44713.6392,131.872701,58917670,2.769237,2.445908,-0.79924,-0.805757,21.989497,0.397756,3.4524,0.227059,0.00227059,-0.009817,0.217282,0.00217282,-0.802514
536,44713.63922,133.872701,58917672,2.82432,2.498495,-0.798354,-0.804705,21.989571,0.399773,3.531644,0.22836,0.0022836,-0.009909,0.218452,0.00218452,-0.801631
544,44713.63925,135.872701,58917674,2.885961,2.562081,-0.797366,-0.803588,21.989718,0.401752,3.618186,0.229887,0.00229887,-0.009725,0.220162,0.00220162,-0.800537
552,44713.63927,137.872701,58917676,2.948567,2.618964,-0.796342,-0.802503,21.989792,0.403812,3.70308,0.231457,0.00231457,-0.009817,0.221574,0.00221574,-0.79944
560,44713.63929,139.872701,58917678,3.005474,2.678573,-0.795438,-0.801254,21.989718,0.405956,3.788734,0.232848,0.00232848,-0.01,0.222848,0.00222848,-0.79849
568,44713.63931,141.872701,58917680,3.068037,2.736904,-0.794518,-0.800432,21.989718,0.40784,3.866447,0.23417,0.0023417,-0.010092,0.22416,0.0022416,-0.797622
576,44713.63934,143.872701,58917682,3.125361,2.80087,-0.793613,-0.799578,21.989792,0.409996,3.958852,0.235637,0.00235637,-0.010092,0.225438,0.00225438,-0.79652
584,44713.63936,145.872701,58917684,3.191283,2.871356,-0.792687,-0.798099,21.989792,0.411876,4.058196,0.237122,0.00237122,-0.010551,0.226676,0.00226676,-0.795498
592,44713.63938,147.872701,58917686,3.268962,2.935879,-0.79182,-0.797211,21.989792,0.413958,4.149515,0.238452,0.00238452,-0.010551,0.227947,0.00227947,-0.794535
600,44713.63941,149.872701,58917688,3.323686,3.002791,-0.790986,-0.796126,21.989865,0.415827,4.243606,0.239881,0.00239881,-0.010643,0.229244,0.00229244,-0.793563
608,44713.63943,151.872701,58917690,3.385736,3.069547,-0.790205,-0.794877,21.99016,0.417626,4.335163,0.241216,0.00241216,-0.010643,0.230665,0.00230665,-0.792555
616,44713.63945,153.872701,58917692,3.448817,3.144105,-0.789333,-0.793628,21.990234,0.419768,4.44261,0.242824,0.00242824,-0.010734,0.232089,0.00232089,-0.791526
624,44713.63948,155.872701,58917694,3.522346,3.213099,-0.788562,-0.792642,21.990381,0.421857,4.546022,0.244102,0.00244102,-0.010826,0.233235,0.00233235,-0.790612
632,44713.6395,157.872701,58917696,3.611625,3.294074,-0.787683,-0.791163,21.990529,0.424092,4.663451,0.245643,0.00245643,-0.010826,0.234817,0.00234817,-0.789552
640,44713.63952,159.872701,58917698,3.678101,3.376048,-0.78691,-0.790078,21.990676,0.426002,4.764729,0.247129,0.00247129,-0.010918,0.236303,0.00236303,-0.788399
648,44713.63955,161.872701,58917700,3.755281,3.446625,-0.786152,-0.788862,21.990603,0.42793,4.864035,0.248451,0.00248451,-0.01101,0.237441,0.00237441,-0.787568
656,44713.63957,163.872701,58917702,3.836512,3.52665,-0.785357,-0.787416,21.990603,0.42995,4.988763,0.250058,0.00250058,-0.011285,0.238682,0.00238682,-0.786443
664,44713.63959,165.872701,58917704,3.911669,3.596061,-0.784628,-0.786397,21.990676,0.431876,5.080971,0.251281,0.00251281,-0.011377,0.239905,0.00239905,-0.785587
672,44713.63962,167.872701,58917706,3.991539,3.676923,-0.7839,-0.785016,21.99075,0.433879,5.197555,0.25273,0.0025273,-0.01156,0.24127,0.0024127,-0.784586
680,44713.63964,169.872701,58917708,4.065296,3.754852,-0.783177,-0.783964,21.990824,0.435954,5.309466,0.254089,0.00254089,-0.011652,0.242381,0.00242381,-0.783605
688,44713.63966,171.872701,58917710,4.14652,3.837351,-0.782441,-0.78265,21.990897,0.437872,5.421993,0.25562,0.0025562,-0.01156,0.24406,0.0024406,-0.78255
696,44713.63969,173.872701,58917712,4.232882,3.920239,-0.781724,-0.781466,21.991045,0.439897,5.538174,0.257048,0.00257048,-0.011652,0.245396,0.00245396,-0.781468
704,44713.63971,175.872701,58917714,4.303908,4.001464,-0.781023,-0.78002,21.991266,0.441812,5.652071,0.258371,0.00258371,-0.011835,0.246536,0.00246536,-0.780624
712,44713.63973,177.872701,58917716,4.389032,4.085092,-0.780274,-0.778903,21.991487,0.44396,5.768362,0.259862,0.00259862,-0.012202,0.247714,0.00247714,-0.779542
720,44713.63975,179.872701,58917718,4.473686,4.168389,-0.779574,-0.777489,21.991561,0.44584,5.887462,0.261376,0.00261376,-0.012294,0.249082,0.00249082,-0.778521
728,44713.63978,181.872701,58917720,4.566799,4.251185,-0.778872,-0.776141,21.991708,0.447934,6.011129,0.262729,0.00262729,-0.012386,0.250343,0.00250343,-0.777513
736,44713.6398,183.872701,58917722,4.637948,4.332484,-0.778201,-0.774958,21.991856,0.449835,6.130191,0.264069,0.00264069,-0.012661,0.251408,0.00251408,-0.776635
744,44713.63982,185.872701,58917724,4.732567,4.417545,-0.777522,-0.773643,21.992077,0.45196,6.243152,0.265428,0.00265428,-0.012845,0.252607,0.00252607,-0.775603
752,44713.63985,187.872701,58917726,4.819666,4.507759,-0.77682,-0.772263,21.992077,0.453914,6.367682,0.267011,0.00267011,-0.01312,0.253926,0.00253926,-0.774576
760,44713.63987,189.872701,58917728,4.896672,4.594742,-0.776135,-0.770882,21.992224,0.455952,6.492229,0.268359,0.00268359,-0.012845,0.255527,0.00255527,-0.773624
768,44713.63989,191.872701,58917730,5.001912,4.693853,-0.775334,-0.769469,21.992298,0.458363,6.635226,0.270103,0.00270103,-0.013487,0.256617,0.00256617,-0.772421
776,44713.63992,193.872701,58917732,5.103147,4.774515,-0.774663,-0.768121,21.992372,0.460184,6.754181,0.271605,0.00271605,-0.013579,0.258018,0.00258018,-0.771335
784,44713.63994,195.872701,58917734,5.188528,4.860107,-0.773996,-0.766774,21.992593,0.46235,6.873011,0.272983,0.00272983,-0.01367,0.259313,0.00259313,-0.770324
792,44713.63996,197.872701,58917736,5.243678,4.942097,-0.773338,-0.765327,21.992666,0.464139,6.98757,0.274336,0.00274336,-0.013946,0.260471,0.00260471,-0.769366
800,44713.63999,199.872701,58917738,5.329989,5.031516,-0.772659,-0.764111,21.99274,0.466348,7.109332,0.275824,0.00275824,-0.014129,0.261703,0.00261703,-0.768401
808,44713.64001,201.872701,58917740,5.417376,5.112907,-0.771958,-0.762796,21.993035,0.468298,7.227073,0.27721,0.0027721,-0.014313,0.262897,0.00262897,-0.767393
816,44713.64003,203.872701,58917742,5.501318,5.194468,-0.771322,-0.761514,21.99333,0.470339,7.34495,0.278586,0.00278586,-0.014496,0.26409,0.0026409,-0.766473
824,44713.64006,205.872701,58917744,5.583024,5.274639,-0.770657,-0.760232,21.993625,0.472045,7.463076,0.280048,0.00280048,-0.014771,0.265201,0.00265201,-0.765503
832,44713.64008,207.872701,58917746,5.672047,5.367418,-0.769982,-0.75872,21.993919,0.474197,7.586481,0.281473,0.00281473,-0.015047,0.266426,0.00266426,-0.764453
840,44713.6401,209.872701,58917748,5.757752,5.446961,-0.769314,-0.757406,21.994214,0.476367,7.702825,0.282954,0.00282954,-0.015505,0.267472,0.00267472,-0.763399
848,44713.64012,211.872701,58917750,5.829342,5.528417,-0.768663,-0.756255,21.994435,0.47816,7.813896,0.284381,0.00284381,-0.015781,0.268579,0.00268579,-0.762432
856,44713.64015,213.872701,58917752,5.929047,5.619375,-0.767962,-0.754908,21.994657,0.480306,7.940118,0.285824,0.00285824,-0.016056,0.269777,0.00269777,-0.761422
864,44713.64017,215.872701,58917754,5.998403,5.688986,-0.767375,-0.753593,21.99473,0.481904,8.040555,0.287056,0.00287056,-0.016239,0.27071,0.0027071,-0.760545
872,44713.64019,217.872701,58917756,6.078273,5.769286,-0.766739,-0.752344,21.995025,0.484003,8.156951,0.288528,0.00288528,-0.016515,0.271865,0.00271865,-0.759511
880,44713.64022,219.872701,58917758,6.171107,5.857806,-0.766035,-0.750963,21.995172,0.486034,8.280769,0.289931,0.00289931,-0.017157,0.272743,0.00272743,-0.758526
888,44713.64024,221.872701,58917760,6.243415,5.938205,-0.76535,-0.749747,21.995467,0.487876,8.400381,0.291293,0.00291293,-0.017432,0.273861,0.00273861,-0.757579
896,44713.64026,223.872701,58917762,6.332437,6.022657,-0.764692,-0.748432,21.995836,0.489757,8.522989,0.292684,0.00292684,-0.017707,0.274974,0.00274974,-0.756607
904,44713.64029,225.872701,58917764,6.420226,6.111392,-0.764013,-0.747117,21.996204,0.491869,8.6427,0.294101,0.00294101,-0.018074,0.276051,0.00276051,-0.755596
912,44713.64031,227.872701,58917766,6.500097,6.19295,-0.763347,-0.745803,21.996647,0.493729,8.75636,0.295548,0.00295548,-0.018716,0.276872,0.00276872,-0.7546
920,44713.64033,229.872701,58917768,6.580102,6.275378,-0.762672,-0.744422,21.996941,0.495834,8.883471,0.296968,0.00296968,-0.018716,0.278244,0.00278244,-0.753606
928,44713.64036,231.872701,58917770,6.67777,6.366643,-0.761949,-0.743009,21.997384,0.497891,9.004439,0.298445,0.00298445,-0.019267,0.279174,0.00279174,-0.752575
936,44713.64038,233.872701,58917772,6.759275,6.448159,-0.761295,-0.742023,21.997605,0.499767,9.116926,0.299708,0.00299708,-0.019817,0.279959,0.00279959,-0.751688
944,44713.6404,235.872701,58917774,6.839553,6.537135,-0.760518,-0.740511,21.9979,0.501701,9.246639,0.301248,0.00301248,-0.020184,0.280963,0.00280963,-0.750602
952,44713.64043,237.872701,58917776,6.932379,6.624519,-0.759988,-0.739294,21.998195,0.503695,9.371117,0.302557,0.00302557,-0.020551,0.282048,0.00282048,-0.749664
960,44713.64045,239.872701,58917778,7.012205,6.714413,-0.759229,-0.738111,21.998416,0.505605,9.491002,0.304076,0.00304076,-0.021285,0.282799,0.00282799,-0.748639
968,44713.64047,241.872701,58917780,7.100732,6.801347,-0.758479,-0.736895,21.998784,0.507741,9.611495,0.305393,0.00305393,-0.021652,0.28374,0.0028374,-0.747712
976,44713.6405,243.872701,58917782,7.187168,6.889794,-0.757738,-0.735416,21.999079,0.5097,9.743168,0.306837,0.00306837,-0.022019,0.284848,0.00284848,-0.746698
984,44713.64052,245.872701,58917784,7.263709,6.969338,-0.756995,-0.734265,21.999521,0.511769,9.855485,0.308287,0.00308287,-0.022478,0.285809,0.00285809,-0.74559
992,44713.64054,247.872701,58917786,7.349504,7.061359,-0.75629,-0.733016,22.000037,0.513591,9.981778,0.309691,0.00309691,-0.022937,0.286777,0.00286777,-0.744714
1000,44713.64056,249.872701,58917788,7.448058,7.150119,-0.755524,-0.7318,22.000479,0.515793,10.106882,0.311181,0.00311181,-0.023304,0.287922,0.00287922,-0.743617
1008,44713.64059,251.872701,58917790,7.524255,7.238552,-0.754784,-0.730584,22.000922,0.517613,10.236803,0.312452,0.00312452,-0.023763,0.288681,0.00288681,-0.742697
1016,44713.64061,253.872701,58917792,7.599418,7.320008,-0.754027,-0.729269,22.001364,0.519625,10.352495,0.313999,0.00313999,-0.02413,0.289869,0.00289869,-0.741684
1024,44713.64063,255.872701,58917794,7.700582,7.405669,-0.753263,-0.728151,22.001733,0.521525,10.47824,0.31543,0.0031543,-0.025047,0.290383,0.00290383,-0.740676
1032,44713.64066,257.872701,58917796,7.790558,7.503357,-0.752495,-0.726738,22.002101,0.523663,10.611398,0.316848,0.00316848,-0.025506,0.291386,0.00291386,-0.739659
1040,44713.64068,259.872701,58917798,7.873133,7.592295,-0.751727,-0.725489,22.002396,0.525569,10.73104,0.31828,0.0031828,-0.025873,0.292315,0.00292315,-0.738799
1048,44713.6407,261.872701,58917800,7.975579,7.679343,-0.750956,-0.724503,22.002838,0.527591,10.857312,0.319724,0.00319724,-0.026423,0.293301,0.00293301,-0.737677
1056,44713.64073,263.872701,58917802,8.070954,7.779834,-0.750074,-0.723057,22.003207,0.529789,11.003657,0.32126,0.0032126,-0.026974,0.294286,0.00294286,-0.736602
1064,44713.64075,265.872701,58917804,8.163052,7.872819,-0.749274,-0.721873,22.003649,0.531879,11.132159,0.322771,0.00322771,-0.027432,0.295164,0.00295164,-0.735538
1072,44713.64077,267.872701,58917806,8.262146,7.960443,-0.748474,-0.72069,22.004091,0.53372,11.252973,0.324064,0.00324064,-0.027983,0.296063,0.00296063,-0.734651
1080,44713.6408,269.872701,58917808,8.327877,8.034032,-0.74778,-0.719474,22.00446,0.535541,11.35757,0.325452,0.00325452,-0.028442,0.29701,0.0029701,-0.733667
1088,44713.64082,271.872701,58917810,8.413545,8.143387,-0.746908,-0.718422,22.004902,0.537628,11.502955,0.326746,0.00326746,-0.029451,0.297435,0.00297435,-0.732761
1096,44713.64084,273.872701,58917812,8.518716,8.220462,-0.746124,-0.717173,22.005492,0.539471,11.627209,0.328283,0.00328283,-0.029818,0.298522,0.00298522,-0.73172
1104,44713.64087,275.872701,58917814,8.604234,8.316287,-0.745295,-0.716055,22.006155,0.541585,11.760354,0.329757,0.00329757,-0.030368,0.299307,0.00299307,-0.730653
1112,44713.64089,277.872701,58917816,8.704997,8.403842,-0.744485,-0.714806,22.006597,0.543474,11.881969,0.331045,0.00331045,-0.031011,0.30003,0.0030003,-0.729755
1120,44713.64091,279.872701,58917818,8.793175,8.499125,-0.743662,-0.713557,22.007187,0.54558,12.013175,0.332549,0.00332549,-0.031653,0.300978,0.00300978,-0.728762
1128,44713.64094,281.872701,58917820,8.888556,8.590288,-0.74283,-0.712637,22.007703,0.547441,12.14699,0.333932,0.00333932,-0.032203,0.301657,0.00301657,-0.727731
1136,44713.64096,283.872701,58917822,8.981597,8.680527,-0.741989,-0.711486,22.008219,0.549684,12.273748,0.33546,0.0033546,-0.032754,0.302683,0.00302683,-0.72665
1144,44713.64098,285.872701,58917824,9.060992,8.766904,-0.741203,-0.710369,22.008735,0.551517,12.3978,0.336726,0.00336726,-0.033396,0.303399,0.00303399,-0.725727
1152,44713.641,287.872701,58917826,9.159376,8.863257,-0.740347,-0.70912,22.009251,0.553641,12.535463,0.338278,0.00338278,-0.034405,0.303781,0.00303781,-0.724792
1160,44713.64103,289.872701,58917828,9.231975,8.947476,-0.739541,-0.708134,22.009546,0.55549,12.656679,0.339461,0.00339461,-0.034956,0.304413,0.00304413,-0.723861
1168,44713.64105,291.872701,58917830,9.3231,9.044549,-0.738688,-0.70672,22.010209,0.557522,12.785754,0.340855,0.00340855,-0.035598,0.30544,0.0030544,-0.722742
1176,44713.64107,293.872701,58917832,9.429302,9.150632,-0.737774,-0.705833,22.010651,0.559493,12.929831,0.342451,0.00342451,-0.03624,0.306162,0.00306162,-0.721802
1184,44713.6411,295.872701,58917834,9.553185,9.244262,-0.736861,-0.704485,22.011241,0.561689,13.074584,0.343942,0.00343942,-0.036974,0.306885,0.00306885,-0.720782
1192,44713.64112,297.872701,58917836,9.628947,9.343561,-0.735944,-0.703302,22.011831,0.563731,13.213756,0.345353,0.00345353,-0.037616,0.307726,0.00307726,-0.719736
1200,44713.64114,299.872701,58917838,9.724982,9.435047,-0.735102,-0.702382,22.01242,0.56581,13.349107,0.346826,0.00346826,-0.038717,0.308109,0.00308109,-0.718723
1208,44713.64117,301.872701,58917840,9.809154,9.525408,-0.734247,-0.701297,22.013084,0.567686,13.476367,0.348159,0.00348159,-0.03936,0.308812,0.00308812,-0.717773
1216,44713.64119,303.872701,58917842,9.902782,9.621956,-0.733364,-0.699883,22.013747,0.569747,13.604513,0.349662,0.00349662,-0.040185,0.309511,0.00309511,-0.716696
1224,44713.64121,305.872701,58917844,10.002993,9.717904,-0.732501,-0.69893,22.014484,0.571583,13.741864,0.351131,0.00351131,-0.040644,0.310487,0.00310487,-0.715649
1232,44713.64124,307.872701,58917846,10.09234,9.80097,-0.731657,-0.697813,22.015074,0.573624,13.858603,0.352428,0.00352428,-0.041562,0.310896,0.00310896,-0.71475
1240,44713.64126,309.872701,58917848,10.190963,9.89305,-0.730794,-0.696761,22.015737,0.575538,13.988851,0.353832,0.00353832,-0.042387,0.311445,0.00311445,-0.713801
1248,44713.64128,311.872701,58917850,10.275032,9.988028,-0.729914,-0.69538,22.016474,0.577567,14.120632,0.355259,0.00355259,-0.043305,0.311954,0.00311954,-0.712832
1256,44713.64131,313.872701,58917852,10.399194,10.099042,-0.728891,-0.694197,22.017138,0.579798,14.287674,0.356942,0.00356942,-0.044222,0.312847,0.00312847,-0.711535
1264,44713.64133,315.872701,58917854,10.471084,10.196405,-0.728008,-0.693277,22.017727,0.581735,14.416263,0.358246,0.00358246,-0.04514,0.313106,0.00313106,-0.710673
1272,44713.64135,317.872701,58917856,10.542669,10.279681,-0.727191,-0.692126,22.018317,0.58377,14.542308,0.359714,0.00359714,-0.045598,0.313997,0.00313997,-0.709679
1280,44713.64137,319.872701,58917858,10.65462,10.372712,-0.726305,-0.691107,22.01898,0.585621,14.66987,0.361067,0.00361067,-0.046608,0.314459,0.00314459,-0.708693
1288,44713.6414,321.872701,58917860,10.745417,10.472247,-0.725451,-0.689727,22.019717,0.587679,14.80501,0.362588,0.00362588,-0.047617,0.31504,0.0031504,-0.707623
1296,44713.64142,323.872701,58917862,10.84633,10.565651,-0.724562,-0.688675,22.020381,0.589628,14.94251,0.36405,0.0036405,-0.048534,0.315515,0.00315515,-0.706649
1304,44713.64144,325.872701,58917864,10.923482,10.649321,-0.723695,-0.687754,22.021265,0.591814,15.065226,0.365505,0.00365505,-0.049268,0.316092,0.00316092,-0.70563
1312,44713.64147,327.872701,58917866,11.020631,10.742362,-0.722809,-0.68644,22.022076,0.593649,15.190699,0.366735,0.00366735,-0.050094,0.316637,0.00316637,-0.704769
1320,44713.64149,329.872701,58917868,11.112548,10.843756,-0.721873,-0.685618,22.022813,0.595841,15.342094,0.368292,0.00368292,-0.051012,0.317281,0.00317281,-0.703679
1328,44713.64151,331.872701,58917870,11.205179,10.933043,-0.72101,-0.684435,22.023624,0.597688,15.45402,0.369547,0.00369547,-0.052204,0.317407,0.00317407,-0.70268
1336,44713.64154,333.872701,58917872,11.312657,11.031434,-0.720068,-0.683383,22.024435,0.599844,15.598951,0.371172,0.00371172,-0.053122,0.318051,0.00318051,-0.701593
1344,44713.64156,335.872701,58917874,11.393551,11.11445,-0.71925,-0.682331,22.025319,0.601538,15.718034,0.372453,0.00372453,-0.054131,0.318256,0.00318256,-0.700698
1352,44713.64158,337.872701,58917876,11.496967,11.210315,-0.718345,-0.680918,22.026056,0.603623,15.862033,0.374007,0.00374007,-0.05514,0.318775,0.00318775,-0.699679
1360,44713.64161,339.872701,58917878,11.577907,11.307367,-0.717481,-0.679833,22.026794,0.605502,15.989255,0.375237,0.00375237,-0.056149,0.31918,0.0031918,-0.698695
1368,44713.64163,341.872701,58917880,11.679542,11.405697,-0.716525,-0.678945,22.027678,0.607708,16.12875,0.37671,0.0037671,-0.057159,0.319575,0.00319575,-0.697756
1376,44713.64165,343.872701,58917882,11.767321,11.496903,-0.715638,-0.677729,22.028489,0.609516,16.259825,0.378077,0.00378077,-0.058535,0.319508,0.00319508,-0.69683
1384,44713.64168,345.872701,58917884,11.860924,11.583366,-0.714765,-0.676677,22.029373,0.611552,16.379839,0.379556,0.00379556,-0.059636,0.319969,0.00319969,-0.69576
1392,44713.6417,347.872701,58917886,11.952402,11.673854,-0.713882,-0.67579,22.03011,0.613494,16.503175,0.38097,0.0038097,-0.060645,0.320325,0.00320325,-0.694813
1400,44713.64172,349.872701,58917888,12.050008,11.77701,-0.712934,-0.674672,22.030995,0.615591,16.65181,0.382452,0.00382452,-0.061654,0.320746,0.00320746,-0.693767
1408,44713.64175,351.872701,58917890,12.121658,11.854794,-0.712088,-0.673588,22.032027,0.617384,16.759499,0.38368,0.0038368,-0.062847,0.320908,0.00320908,-0.692826
1416,44713.64177,353.872701,58917892,12.238694,11.951489,-0.711155,-0.67247,22.032985,0.619229,16.902059,0.385071,0.00385071,-0.063948,0.321122,0.00321122,-0.691842
1424,44713.64179,355.872701,58917894,12.315225,12.046398,-0.71021,-0.671352,22.034017,0.621365,17.042597,0.38657,0.0038657,-0.065141,0.321407,0.00321407,-0.690885
1432,44713.64181,357.872701,58917896,12.403935,12.14284,-0.709308,-0.670301,22.035049,0.623257,17.164665,0.387941,0.00387941,-0.066425,0.321435,0.00321435,-0.689981
1440,44713.64184,359.872701,58917898,12.522679,12.247241,-0.708325,-0.66938,22.036155,0.625355,17.32098,0.389485,0.00389485,-0.067893,0.321595,0.00321595,-0.688842
1448,44713.64186,361.872701,58917900,12.616881,12.343975,-0.707362,-0.668263,22.037186,0.627438,17.458049,0.390938,0.00390938,-0.069086,0.321945,0.00321945,-0.687827
1456,44713.64188,363.872701,58917902,12.699339,12.430858,-0.706466,-0.667244,22.038292,0.629234,17.586621,0.392393,0.00392393,-0.070554,0.321839,0.00321839,-0.686909
1464,44713.64191,365.872701,58917904,12.806891,12.535954,-0.705493,-0.666093,22.039471,0.631471,17.720997,0.393775,0.00393775,-0.071563,0.322212,0.00322212,-0.685751
1472,44713.64193,367.872701,58917906,12.889566,12.62186,-0.704615,-0.665041,22.040577,0.633193,17.850253,0.395181,0.00395181,-0.073031,0.32215,0.0032215,-0.684857
1480,44713.64195,369.872701,58917908,12.968212,12.716159,-0.703658,-0.66399,22.041756,0.635439,17.988452,0.396557,0.00396557,-0.074682,0.321952,0.00321952,-0.683896
1488,44713.64198,371.872701,58917910,13.064236,12.813805,-0.702745,-0.662905,22.042862,0.637278,18.115984,0.397937,0.00397937,-0.076059,0.32191,0.0032191,-0.682906
1496,44713.642,373.872701,58917912,13.157192,12.897021,-0.701828,-0.66182,22.044041,0.63939,18.243748,0.399399,0.00399399,-0.077527,0.321873,0.00321873,-0.681904
1504,44713.64202,375.872701,58917914,13.247418,12.986954,-0.700852,-0.660966,22.045221,0.641217,18.374699,0.400914,0.00400914,-0.079086,0.321827,0.00321827,-0.680848
1512,44713.64205,377.872701,58917916,13.340885,13.083588,-0.699918,-0.659947,22.046474,0.643218,18.506652,0.402236,0.00402236,-0.080738,0.321535,0.00321535,-0.679893
1520,44713.64207,379.872701,58917918,13.444958,13.18862,-0.698901,-0.658829,22.0478,0.645362,18.652592,0.403736,0.00403736,-0.082297,0.321439,0.00321439,-0.678868
1528,44713.64209,381.872701,58917920,13.531855,13.279246,-0.697945,-0.657613,22.049201,0.64734,18.777176,0.40526,0.0040526,-0.084132,0.321128,0.00321128,-0.677802
1536,44713.64212,383.872701,58917922,13.625874,13.362899,-0.697012,-0.656824,22.050601,0.649401,18.899911,0.406616,0.00406616,-0.085876,0.320743,0.00320743,-0.67685
1544,44713.64214,385.872701,58917924,13.713026,13.447857,-0.696076,-0.655476,22.052002,0.651255,19.022713,0.407975,0.00407975,-0.087711,0.320264,0.00320264,-0.675901
1552,44713.64216,387.872701,58917926,13.807325,13.542256,-0.695134,-0.654687,22.053476,0.653373,19.15007,0.409417,0.00409417,-0.089545,0.320018,0.00320018,-0.674789
1560,44713.64219,389.872701,58917928,13.875953,13.612129,-0.694239,-0.653636,22.054877,0.655242,19.248629,0.410814,0.00410814,-0.09138,0.319434,0.00319434,-0.673862
1568,44713.64221,391.872701,58917930,13.956496,13.696904,-0.693339,-0.652584,22.056424,0.657027,19.374176,0.412181,0.00412181,-0.093032,0.319065,0.00319065,-0.672936
1576,44713.64223,393.872701,58917932,14.038419,13.775213,-0.6924,-0.651598,22.057825,0.659108,19.487304,0.413582,0.00413582,-0.094959,0.318556,0.00318556,-0.671976
1584,44713.64225,395.872701,58917934,14.128045,13.861929,-0.691439,-0.650513,22.059594,0.661014,19.604845,0.415036,0.00415036,-0.096977,0.318045,0.00318045,-0.670958
1592,44713.64228,397.872701,58917936,14.21217,13.947788,-0.690474,-0.649297,22.061289,0.66314,19.725288,0.416376,0.00416376,-0.099179,0.317197,0.00317197,-0.670021
1600,44713.6423,399.872701,58917938,14.286791,14.033525,-0.689557,-0.648409,22.063058,0.665049,19.847255,0.417812,0.00417812,-0.101289,0.316558,0.00316558,-0.669067
1608,44713.64232,401.872701,58917940,14.387034,14.129346,-0.688472,-0.64716,22.064901,0.667379,19.983179,0.419435,0.00419435,-0.103583,0.315894,0.00315894,-0.667895
1616,44713.64235,403.872701,58917942,14.463319,14.199545,-0.687563,-0.64601,22.066817,0.669306,20.093401,0.420867,0.00420867,-0.105877,0.314936,0.00314936,-0.666846
1624,44713.64237,405.872701,58917944,14.549028,14.286296,-0.686604,-0.645155,22.068734,0.671435,20.20874,0.422356,0.00422356,-0.108262,0.314099,0.00314099,-0.665835
1632,44713.64239,407.872701,58917946,14.608903,14.360876,-0.685645,-0.644005,22.07065,0.673218,20.314466,0.423726,0.00423726,-0.110739,0.313022,0.00313022,-0.664851
1640,44713.64242,409.872701,58917948,14.6903,14.443133,-0.684713,-0.64292,22.07264,0.675304,20.428317,0.425131,0.00425131,-0.113125,0.312006,0.00312006,-0.663892
1648,44713.64244,411.872701,58917950,14.759583,14.516898,-0.683769,-0.641967,22.074704,0.67725,20.533003,0.426567,0.00426567,-0.115602,0.310883,0.00310883,-0.66288
1656,44713.64246,413.872701,58917952,14.832119,14.592263,-0.68286,-0.640849,22.076768,0.679437,20.634329,0.427956,0.00427956,-0.118079,0.309835,0.00309835,-0.661859
1664,44713.64249,415.872701,58917954,14.904115,14.662982,-0.681908,-0.639863,22.078906,0.681288,20.737422,0.429322,0.00429322,-0.120923,0.308438,0.00308438,-0.660931
1672,44713.64251,417.872701,58917956,15.001864,14.736599,-0.68098,-0.638778,22.081117,0.683338,20.843429,0.430822,0.00430822,-0.123676,0.307147,0.00307147,-0.659934
1680,44713.64253,419.872701,58917958,15.057817,14.814803,-0.679969,-0.637694,22.083623,0.685464,20.948938,0.432305,0.00432305,-0.126611,0.305654,0.00305654,-0.658849
1688,44713.64256,421.872701,58917960,15.118457,14.885616,-0.679012,-0.636675,22.085982,0.68732,21.056528,0.433716,0.00433716,-0.129456,0.304199,0.00304199,-0.657788
1696,44713.64258,423.872701,58917962,15.195253,14.94521,-0.678097,-0.635722,22.08834,0.689508,21.137124,0.43515,0.0043515,-0.132483,0.302609,0.00302609,-0.656919
1704,44713.6426,425.872701,58917964,15.262884,15.007694,-0.677138,-0.634472,22.09092,0.691338,21.229795,0.436628,0.00436628,-0.135694,0.300958,0.00300958,-0.655827
1712,44713.64262,427.872701,58917966,15.320875,15.08225,-0.676194,-0.633585,22.093426,0.693445,21.325951,0.438031,0.00438031,-0.138997,0.299034,0.00299034,-0.654862
1720,44713.64265,429.872701,58917968,15.381853,15.13352,-0.675272,-0.632237,22.096153,0.695452,21.404097,0.439561,0.00439561,-0.142667,0.296907,0.00296907,-0.653791
1728,44713.64267,431.872701,58917970,15.44352,15.194532,-0.674329,-0.631317,22.098954,0.697461,21.485418,0.44084,0.0044084,-0.146062,0.294716,0.00294716,-0.652837
1736,44713.64269,433.872701,58917972,15.483686,15.246777,-0.673415,-0.630364,22.101755,0.699254,21.568482,0.442259,0.00442259,-0.149365,0.29277,0.0029277,-0.651902
1744,44713.64272,435.872701,58917974,15.541357,15.301269,-0.672479,-0.629279,22.104704,0.701356,21.645772,0.44371,0.0044371,-0.153126,0.290615,0.00290615,-0.650865
1752,44713.64274,437.872701,58917976,15.593906,15.354571,-0.671539,-0.628227,22.107652,0.703204,21.726716,0.445161,0.00445161,-0.15698,0.288173,0.00288173,-0.649871
1760,44713.64276,439.872701,58917978,15.653672,15.410675,-0.670579,-0.627077,22.110895,0.7054,21.797452,0.446642,0.00446642,-0.161017,0.285596,0.00285596,-0.64879
1768,44713.64279,441.872701,58917980,15.69504,15.458612,-0.669646,-0.626025,22.114138,0.707331,21.874071,0.447986,0.00447986,-0.165145,0.28279,0.0028279,-0.647928
1776,44713.64281,443.872701,58917982,15.760912,15.521637,-0.668653,-0.62494,22.11775,0.709327,21.948416,0.449448,0.00449448,-0.169457,0.279955,0.00279955,-0.64687
1784,44713.64283,445.872701,58917984,15.804515,15.566342,-0.66772,-0.623856,22.121509,0.711455,22.018434,0.450922,0.00450922,-0.174137,0.276755,0.00276755,-0.645796
1792,44713.64286,447.872701,58917986,15.857961,15.609186,-0.666726,-0.622869,22.125342,0.713461,22.085153,0.452337,0.00452337,-0.178816,0.273522,0.00273522,-0.644712
1800,44713.64288,449.872701,58917988,15.889511,15.649814,-0.665829,-0.621653,22.129322,0.715495,22.140218,0.453687,0.00453687,-0.183678,0.270116,0.00270116,-0.643801
1808,44713.6429,451.872701,58917990,15.936723,15.690069,-0.664884,-0.620667,22.13345,0.717352,22.193605,0.455159,0.00455159,-0.188633,0.266582,0.00266582,-0.642833
1816,44713.64293,453.872701,58917992,15.954065,15.726527,-0.663961,-0.619747,22.137651,0.719494,22.249023,0.45658,0.0045658,-0.194046,0.2626,0.002626,-0.641878
1824,44713.64295,455.872701,58917994,16.002896,15.766501,-0.663022,-0.618826,22.142148,0.721546,22.29863,0.45798,0.0045798,-0.199642,0.258334,0.00258334,-0.640794
1832,44713.64297,457.872701,58917996,16.01614,15.784656,-0.662102,-0.61761,22.146865,0.723535,22.326046,0.459446,0.00459446,-0.205422,0.253965,0.00253965,-0.639913
1840,44713.643,459.872701,58917998,16.039711,15.806951,-0.661186,-0.616427,22.151804,0.725529,22.362366,0.460791,0.00460791,-0.211386,0.249549,0.00249549,-0.638829
1848,44713.64302,461.872701,58918000,16.064001,15.825154,-0.660242,-0.615539,22.156889,0.7275,22.389232,0.462259,0.00462259,-0.217717,0.244543,0.00244543,-0.637892
1856,44713.64304,463.872701,58918002,16.056213,15.830949,-0.659364,-0.61452,22.162344,0.729261,22.401887,0.463663,0.00463663,-0.224689,0.238921,0.00238921,-0.636827
1864,44713.64306,465.872701,58918004,16.069529,15.831642,-0.658439,-0.613239,22.168093,0.731463,22.394286,0.465139,0.00465139,-0.231846,0.233275,0.00233275,-0.635863
1872,44713.64309,467.872701,58918006,16.061788,15.83098,-0.657489,-0.612187,22.17399,0.733455,22.39497,0.466527,0.00466527,-0.239186,0.227407,0.00227407,-0.634915
1880,44713.64311,469.872701,58918008,16.067026,15.845529,-0.656545,-0.611036,22.179887,0.735417,22.416644,0.467941,0.00467941,-0.24625,0.221711,0.00221711,-0.63391
1888,44713.64313,471.872701,58918010,16.081024,15.859328,-0.655586,-0.61005,22.185931,0.737525,22.42891,0.469419,0.00469419,-0.253865,0.215554,0.00215554,-0.632914
1896,44713.64316,473.872701,58918012,16.10354,15.876015,-0.65465,-0.609163,22.192196,0.739345,22.455518,0.470811,0.00470811,-0.261572,0.209219,0.00209219,-0.631893
1904,44713.64318,475.872701,58918014,16.113223,15.892572,-0.65366,-0.608111,22.198535,0.741524,22.479253,0.472289,0.00472289,-0.269462,0.202787,0.00202787,-0.630881
1912,44713.6432,477.872701,58918016,16.137878,15.903379,-0.65275,-0.606895,22.205169,0.743305,22.500077,0.473563,0.00473563,-0.277903,0.195688,0.00195688,-0.629905
1920,44713.64323,479.872701,58918018,16.13806,15.923521,-0.651755,-0.606007,22.212097,0.745409,22.521437,0.475158,0.00475158,-0.286527,0.18863,0.0018863,-0.628937
1928,44713.64325,481.872701,58918020,16.149584,15.933342,-0.650822,-0.604758,22.219689,0.747326,22.537919,0.476545,0.00476545,-0.295794,0.180662,0.00180662,-0.627902
1936,44713.64327,483.872701,58918022,16.147622,15.941676,-0.649827,-0.603936,22.227281,0.749504,22.552245,0.477878,0.00477878,-0.305519,0.17246,0.0017246,-0.626898
1944,44713.6433,485.872701,58918024,16.158774,15.942304,-0.648859,-0.602983,22.235242,0.751366,22.550414,0.479353,0.00479353,-0.315336,0.164017,0.00164017,-0.625948
1952,44713.64332,487.872701,58918026,16.172647,15.948571,-0.647875,-0.601734,22.243424,0.753411,22.560954,0.48084,0.0048084,-0.325428,0.155318,0.00155318,-0.624896
1960,44713.64334,489.872701,58918028,16.156059,15.951166,-0.646871,-0.600814,22.251826,0.755499,22.564113,0.482346,0.00482346,-0.335796,0.146551,0.00146551,-0.623894
1968,44713.64337,491.872701,58918030,16.157138,15.948953,-0.645908,-0.599762,22.260303,0.757566,22.56419,0.483754,0.00483754,-0.346438,0.137316,0.00137316,-0.622874
1976,44713.64339,493.872701,58918032,16.162749,15.945901,-0.644955,-0.59871,22.268706,0.759536,22.562133,0.485093,0.00485093,-0.356806,0.128287,0.00128287,-0.621929
1984,44713.64341,495.872701,58918034,16.146778,15.945878,-0.643995,-0.597625,22.276961,0.761729,22.561091,0.486677,0.00486677,-0.367265,0.119412,0.00119412,-0.620907
1992,44713.64344,497.872701,58918036,16.148875,15.942066,-0.643041,-0.596639,22.285511,0.763634,22.55575,0.488056,0.00488056,-0.377908,0.110138,0.00110138,-0.619844
2000,44713.64346,499.872701,58918038,16.157484,15.938698,-0.642099,-0.595456,22.294135,0.765789,22.555356,0.489423,0.00489423,-0.388642,0.100781,0.00100781,-0.618898
2008,44713.64348,501.872701,58918040,16.132107,15.930725,-0.641164,-0.59447,22.302833,0.767693,22.538864,0.490952,0.00490952,-0.399468,0.091507,0.00091507,-0.617817
2016,44713.6435,503.872701,58918042,16.13523,15.92102,-0.640214,-0.593287,22.311899,0.769792,22.516521,0.492297,0.00492297,-0.410845,0.081444,0.00081444,-0.616809
2024,44713.64353,505.872701,58918044,16.113433,15.909919,-0.639232,-0.592268,22.321407,0.771915,22.506187,0.493783,0.00493783,-0.422497,0.071338,0.00071338,-0.615835
2032,44713.64355,507.872701,58918046,16.094939,15.895714,-0.63832,-0.591347,22.330842,0.773757,22.490306,0.49513,0.0049513,-0.434332,0.060794,0.00060794,-0.614844
2040,44713.64357,509.872701,58918048,16.057626,15.854065,-0.637536,-0.590493,22.340277,0.775474,22.432945,0.496418,0.00496418,-0.446076,0.05036,0.0005036,-0.613991
2048,44713.6436,511.872701,58918050,16.043852,15.854525,-0.636472,-0.589244,22.350522,0.777754,22.43925,0.49793,0.0049793,-0.458737,0.039192,0.00039192,-0.612843
2056,44713.64362,513.872701,58918052,16.049291,15.848693,-0.635378,-0.588225,22.362242,0.779917,22.419626,0.499641,0.00499641,-0.473233,0.026408,0.00026408,-0.611727
2064,44713.64364,515.872701,58918054,16.010221,15.820438,-0.634422,-0.587041,22.373741,0.78204,22.384446,0.501034,0.00501034,-0.48773,0.013419,0.00013419,-0.61068
2072,44713.64367,517.872701,58918056,15.971313,15.791753,-0.63346,-0.585792,22.385755,0.784073,22.337648,0.502434,0.00502434,-0.502684,-0.000166,-0.00000166,-0.609721
2080,44713.64369,519.872701,58918058,15.950606,15.754934,-0.632521,-0.584806,22.398507,0.785874,22.288022,0.503866,0.00503866,-0.51819,-0.014354,-0.00014354,-0.608777
2088,44713.64371,521.872701,58918060,15.916572,15.717091,-0.631602,-0.583952,22.411258,0.787942,22.239924,0.505352,0.00505352,-0.534521,-0.029108,-0.00029108,-0.607695
2096,44713.64374,523.872701,58918062,15.874921,15.687162,-0.630623,-0.582768,22.423936,0.789797,22.192545,0.506784,0.00506784,-0.550301,-0.043517,-0.00043517,-0.606735
2104,44713.64376,525.872701,58918064,15.856613,15.651966,-0.629624,-0.581749,22.437204,0.79197,22.14998,0.508292,0.00508292,-0.566724,-0.058432,-0.00058432,-0.605679
2112,44713.64378,527.872701,58918066,15.794533,15.597719,-0.628683,-0.580632,22.451651,0.794151,22.071958,0.509709,0.00509709,-0.584615,-0.074906,-0.00074906,-0.604596
2120,44713.6438,529.872701,58918068,15.743724,15.55749,-0.627746,-0.579514,22.466393,0.795905,22.003202,0.511082,0.00511082,-0.602873,-0.091791,-0.00091791,-0.603665
2128,44713.64383,531.872701,58918070,15.682716,15.508651,-0.626773,-0.578627,22.481724,0.797956,21.936458,0.512498,0.00512498,-0.621773,-0.109213,-0.00109213,-0.602735
2136,44713.64385,533.872701,58918072,15.628118,15.436087,-0.625823,-0.577575,22.498825,0.799881,21.845886,0.513883,0.00513883,-0.642966,-0.129013,-0.00129013,-0.601716
2144,44713.64387,535.872701,58918074,15.551059,15.368012,-0.624863,-0.576359,22.517031,0.802047,21.745799,0.515387,0.00515387,-0.665445,-0.150066,-0.00150066,-0.600682
2152,44713.6439,537.872701,58918076,15.47031,15.29324,-0.62392,-0.575373,22.537374,0.803932,21.649385,0.516848,0.00516848,-0.690675,-0.173795,-0.00173795,-0.599714
2160,44713.64392,539.872701,58918078,14.99659,14.737278,-0.62328,-0.574058,22.660026,0.806156,20.888513,0.518297,0.00518297,-0.839673,-0.321377,-0.00321377,-0.598622
2168,44713.64394,541.872701,58918080,14.771255,14.59699,-0.622488,-0.572776,22.688478,0.807949,20.65267,0.519719,0.00519719,-0.879125,-0.359216,-0.00359216,-0.59768
2176,44713.64397,543.872701,58918082,14.722363,14.557112,-0.621563,-0.571855,22.705209,0.810154,20.592127,0.521074,0.00521074,-0.900043,-0.378869,-0.00378869,-0.596732
2184,44713.64399,545.872701,58918084,14.681266,14.523411,-0.620773,-0.570869,22.718403,0.811803,20.543543,0.522335,0.00522335,-0.916466,-0.394131,-0.00394131,-0.595814
2192,44713.64401,547.872701,58918086,14.685331,14.5198,-0.619817,-0.569916,22.730492,0.813758,20.541806,0.523721,0.00523721,-0.931421,-0.407553,-0.00407553,-0.594886
2200,44713.64404,549.872701,58918088,14.663691,14.508208,-0.618831,-0.568733,22.744496,0.81596,20.522569,0.52523,0.0052523,-0.948853,-0.42361,-0.0042361,-0.593823
2208,44713.64406,551.872701,58918090,14.656801,14.497319,-0.617768,-0.567648,22.758206,0.818045,20.513525,0.526898,0.00526898,-0.965918,-0.438928,-0.00438928,-0.592655
2216,44713.64408,553.872701,58918092,14.640489,14.483596,-0.616886,-0.566629,22.76941,0.819909,20.491967,0.528154,0.00528154,-0.979864,-0.451653,-0.00451653,-0.591776
2224,44713.64411,555.872701,58918094,14.637844,14.487209,-0.61587,-0.565347,22.780982,0.822005,20.492291,0.529761,0.00529761,-0.993993,-0.464367,-0.00464367,-0.590651
2232,44713.64413,557.872701,58918096,14.621252,14.461396,-0.614912,-0.564263,22.793955,0.824141,20.461809,0.531248,0.00531248,-1.010232,-0.479115,-0.00479115,-0.589596
2240,44713.64415,559.872701,58918098,14.579949,14.433021,-0.614041,-0.563539,22.805601,0.826029,20.417032,0.532427,0.00532427,-1.02482,-0.492304,-0.00492304,-0.588784
2248,44713.64418,561.872701,58918100,14.512498,14.35652,-0.613481,-0.562783,22.816068,0.826924,20.312377,0.533317,0.00533317,-1.038215,-0.504899,-0.00504899,-0.588273
2256,44713.6442,563.872701,58918102,14.388273,14.245453,-0.613757,-0.562882,22.822849,0.826953,20.160572,0.533245,0.00533245,-1.04684,-0.513778,-0.00513778,-0.588212
2264,44713.64422,565.872701,58918104,14.340019,14.178263,-0.613647,-0.562915,22.827566,0.826845,20.068918,0.533281,0.00533281,-1.052987,-0.519631,-0.00519631,-0.588322
2272,44713.64425,567.872701,58918106,14.273529,14.123368,-0.613615,-0.562783,22.83162,0.826822,19.983839,0.533088,0.00533088,-1.057758,-0.52467,-0.0052467,-0.588322
2280,44713.64427,569.872701,58918108,14.11763,13.965331,-0.614536,-0.563507,22.833905,0.825323,19.768533,0.532109,0.00532109,-1.060602,-0.528492,-0.00528492,-0.589007
2281,44713.64427,570.122701,58918108,14.100417,13.947414,-0.614672,-0.563572,22.834126,0.825112,19.733258,0.531914,0.00531914,-1.061152,-0.52931,-0.0052931,-0.589144