File: PB16_UCS_1622.csv
Index,Date,Time,Counter,FbLoad,Force(kN),LVDT1,LVDT2,Chain,OutputPower,Stress [MPa],Strain Ax. [%],Strain Ax [-],Strain Rad. [%],Strain Vol. [%],Strain Vol [-],Gemidd
0,44713.67447,0,58920718,-0.984716,0.114427,-0.931335,-0.926981,21.991413,0.144211,0.161675,0.045915,0.00045915,-0.012202,0.033976,0.00033976,-0.929158
9,44713.6745,2.242037,58920720,-0.960401,0.111288,-0.931576,-0.927211,21.991413,0.143889,0.178944,0.046379,0.00046379,-0.012294,0.03421,0.0003421,-0.929195
18,44713.67452,4.492037,58920722,-0.966387,0.130368,-0.930785,-0.926981,21.991118,0.145121,0.172343,0.046293,0.00046293,-0.012294,0.034167,0.00034167,-0.928896
27,44713.67455,6.742037,58920724,-0.959318,0.129917,-0.93071,-0.927474,21.991413,0.145243,0.218485,0.047544,0.00047544,-0.011927,0.035617,0.00035617,-0.92836
36,44713.67458,8.992037,58920727,-1.000846,0.08665,-0.93219,-0.927277,21.991045,0.142676,0.094209,0.043711,0.00043711,-0.012019,0.031912,0.00031912,-0.930407
45,44713.6746,11.242037,58920729,-0.953918,0.132253,-0.93083,-0.926357,21.991487,0.145115,0.137881,0.045396,0.00045396,-0.012111,0.033469,0.00033469,-0.929245
54,44713.67463,13.492037,58920731,-0.966618,0.126947,-0.931096,-0.926751,21.991192,0.144618,0.158177,0.045945,0.00045945,-0.012019,0.033743,0.00033743,-0.929123
63,44713.67465,15.742037,58920733,-0.963427,0.120862,-0.931376,-0.927606,21.991413,0.144218,0.135754,0.045057,0.00045057,-0.011835,0.033076,0.00033076,-0.929378
72,44713.67468,17.992037,58920736,-0.946897,0.095782,-0.931972,-0.927737,21.991118,0.143149,0.149932,0.045444,0.00045444,-0.011927,0.033609,0.00033609,-0.929673
81,44713.67471,20.242037,58920738,-0.958033,0.107992,-0.931434,-0.92708,21.99134,0.144116,0.155215,0.04571,0.0004571,-0.012019,0.033691,0.00033691,-0.92932
90,44713.67473,22.492037,58920740,-0.948086,0.116981,-0.931345,-0.927441,21.991266,0.144208,0.166743,0.046246,0.00046246,-0.012019,0.034283,0.00034283,-0.929072
99,44713.67476,24.742037,58920742,-0.951374,0.11347,-0.931608,-0.927113,21.991192,0.143904,0.155065,0.045751,0.00045751,-0.011927,0.033824,0.00033824,-0.929362
108,44713.67478,26.992037,58920745,-0.946724,0.109537,-0.931677,-0.927474,21.991192,0.143838,0.148842,0.045549,0.00045549,-0.011927,0.033622,0.00033622,-0.929629
117,44713.67481,29.242037,58920747,-0.947289,0.108843,-0.931665,-0.927376,21.991118,0.143666,0.15404,0.045696,0.00045696,-0.011927,0.033769,0.00033769,-0.929538
126,44713.67484,31.492037,58920749,-0.93754,0.123204,-0.931003,-0.926883,21.991266,0.144843,0.16993,0.046356,0.00046356,-0.011927,0.034398,0.00034398,-0.928887
135,44713.67486,33.742037,58920751,-0.931747,0.120336,-0.931003,-0.926751,21.991045,0.144871,0.167099,0.046289,0.00046289,-0.012019,0.034181,0.00034181,-0.929144
144,44713.67489,35.992037,58920754,-0.909301,0.148537,-0.929891,-0.926028,21.991266,0.146683,0.201201,0.047428,0.00047428,-0.012019,0.035501,0.00035501,-0.928059
153,44713.67491,38.242037,58920756,-0.856182,0.18473,-0.928424,-0.925173,21.991266,0.149203,0.258837,0.049579,0.00049579,-0.012202,0.037351,0.00037351,-0.926975
162,44713.67494,40.492037,58920758,-0.829017,0.210879,-0.926841,-0.924154,21.991487,0.151908,0.299183,0.051391,0.00051391,-0.012202,0.039279,0.00039279,-0.92551
171,44713.67497,42.742037,58920760,-0.797558,0.229307,-0.92609,-0.923727,21.99134,0.153166,0.324799,0.052351,0.00052351,-0.012202,0.040057,0.00040057,-0.924903
180,44713.67499,44.992037,58920763,-0.763722,0.270259,-0.924216,-0.922478,21.991561,0.156238,0.374803,0.0546,0.000546,-0.012478,0.042196,0.00042196,-0.923361
189,44713.67502,47.242037,58920765,-0.74586,0.294446,-0.922778,-0.921591,21.991561,0.158569,0.421325,0.05615,0.0005615,-0.012386,0.043855,0.00043855,-0.922179
198,44713.67504,49.492037,58920767,-0.708697,0.324049,-0.921479,-0.9209,21.991782,0.160694,0.458199,0.057864,0.00057864,-0.012569,0.045246,0.00045246,-0.920979
207,44713.67507,51.742037,58920769,-0.677451,0.355191,-0.919985,-0.919487,21.991708,0.163164,0.492024,0.059151,0.00059151,-0.012569,0.046581,0.00046581,-0.919984
216,44713.6751,53.992037,58920772,-0.642783,0.374176,-0.918971,-0.918764,21.992003,0.16484,0.522466,0.06079,0.0006079,-0.012661,0.048086,0.00048086,-0.918896
225,44713.67512,56.242037,58920774,-0.623783,0.405415,-0.91747,-0.917876,21.991708,0.167165,0.564238,0.062046,0.00062046,-0.012845,0.049366,0.00049366,-0.918052
234,44713.67515,58.492037,58920776,-0.590545,0.43681,-0.916043,-0.917383,21.992077,0.169454,0.619566,0.064242,0.00064242,-0.012936,0.051305,0.00051305,-0.916432
243,44713.67517,60.742037,58920778,-0.554643,0.465265,-0.914585,-0.916397,21.991929,0.171952,0.66123,0.065774,0.00065774,-0.012936,0.052838,0.00052838,-0.915442
252,44713.6752,62.992037,58920781,-0.51307,0.492527,-0.913273,-0.91551,21.992224,0.174072,0.70534,0.067467,0.00067467,-0.013028,0.054439,0.00054439,-0.914256
261,44713.67523,65.242037,58920783,-0.47066,0.52626,-0.911858,-0.914491,21.99215,0.176296,0.746319,0.068941,0.00068941,-0.013303,0.055638,0.00055638,-0.913294
270,44713.67525,67.492037,58920785,-0.437582,0.56148,-0.910563,-0.913702,21.992298,0.178485,0.799627,0.070481,0.00070481,-0.013395,0.057163,0.00057163,-0.912093
279,44713.67528,69.742037,58920787,-0.416905,0.590148,-0.909213,-0.912617,21.992224,0.180664,0.839249,0.07213,0.0007213,-0.013579,0.058567,0.00058567,-0.910992
288,44713.6753,71.992037,58920790,-0.365923,0.617783,-0.907946,-0.911828,21.992372,0.182734,0.887172,0.073524,0.00073524,-0.013212,0.060282,0.00060282,-0.909978
297,44713.67533,74.242037,58920792,-0.327454,0.66594,-0.906242,-0.911105,21.992593,0.18545,0.938635,0.075478,0.00075478,-0.013395,0.062059,0.00062059,-0.908666
306,44713.67536,76.492037,58920794,-0.308089,0.682996,-0.905173,-0.910185,21.992372,0.187296,0.966376,0.076743,0.00076743,-0.013579,0.063164,0.00063164,-0.907692
315,44713.67538,78.742037,58920796,-0.25667,0.719177,-0.903805,-0.909166,21.992814,0.189529,1.038202,0.078725,0.00078725,-0.01367,0.065055,0.00065055,-0.906376
324,44713.67541,80.992037,58920799,-0.232147,0.767526,-0.902332,-0.908278,21.992519,0.192007,1.101173,0.080422,0.00080422,-0.013762,0.066659,0.00066659,-0.905299
333,44713.67543,83.242037,58920801,-0.191423,0.802174,-0.900971,-0.907555,21.992887,0.194258,1.130218,0.081694,0.00081694,-0.013854,0.06784,0.0006784,-0.904297
342,44713.67546,85.492037,58920803,-0.146228,0.846992,-0.899485,-0.906503,21.992666,0.196842,1.20114,0.083581,0.00083581,-0.013946,0.069635,0.00069635,-0.902836
351,44713.67549,87.742037,58920805,-0.094695,0.878323,-0.898214,-0.905616,21.993035,0.199037,1.236591,0.085004,0.00085004,-0.014129,0.070926,0.00070926,-0.901945
360,44713.67551,89.992037,58920808,-0.061294,0.909768,-0.897186,-0.904564,21.992887,0.200815,1.287163,0.086569,0.00086569,-0.014313,0.072189,0.00072189,-0.900885
369,44713.67554,92.242037,58920810,-0.016407,0.94548,-0.89597,-0.903709,21.993182,0.202961,1.344562,0.088028,0.00088028,-0.014404,0.073623,0.00073623,-0.900026
378,44713.67556,94.492037,58920812,0.030466,0.995199,-0.894268,-0.902592,21.993109,0.205854,1.410909,0.090088,0.00090088,-0.014221,0.075864,0.00075864,-0.898422
387,44713.67559,96.742037,58920814,0.07493,1.032574,-0.893097,-0.902033,21.993256,0.207723,1.465089,0.091452,0.00091452,-0.01468,0.076874,0.00076874,-0.897396
396,44713.67562,98.992037,58920817,0.11811,1.085154,-0.891556,-0.900915,21.993182,0.21036,1.51975,0.093071,0.00093071,-0.014771,0.0783,0.000783,-0.896279
405,44713.67564,101.242037,58920819,0.160415,1.110899,-0.890501,-0.899732,21.993477,0.212277,1.573047,0.094731,0.00094731,-0.014588,0.079977,0.00079977,-0.895172
414,44713.67567,103.492037,58920821,0.206372,1.174856,-0.888834,-0.898943,21.993477,0.215361,1.633475,0.096312,0.00096312,-0.014955,0.081367,0.00081367,-0.894091
423,44713.67569,105.742037,58920823,0.241551,1.204667,-0.887699,-0.898122,21.993625,0.217229,1.696465,0.097891,0.00097891,-0.014771,0.08312,0.0008312,-0.892878
432,44713.67572,107.992037,58920826,0.304942,1.249166,-0.886483,-0.897037,21.993625,0.219386,1.764086,0.099621,0.00099621,-0.015138,0.084456,0.00084456,-0.891789
441,44713.67575,110.242037,58920828,0.354835,1.290035,-0.885005,-0.895788,21.993846,0.22188,1.851189,0.101727,0.00101727,-0.015047,0.08668,0.0008668,-0.890275
450,44713.67577,112.492037,58920830,0.385807,1.335257,-0.883949,-0.895196,21.993772,0.223705,1.880051,0.102797,0.00102797,-0.015047,0.087669,0.00087669,-0.889526
459,44713.6758,114.742037,58920832,0.426993,1.365056,-0.882753,-0.894079,21.993919,0.225804,1.941049,0.104328,0.00104328,-0.015414,0.088983,0.00088983,-0.888342
468,44713.67583,116.992037,58920835,0.471987,1.433106,-0.881214,-0.892895,21.994067,0.228546,2.014227,0.106037,0.00106037,-0.015505,0.090647,0.00090647,-0.887177
477,44713.67585,119.242037,58920837,0.53725,1.459046,-0.880203,-0.892172,21.994141,0.230416,2.078301,0.107648,0.00107648,-0.015505,0.09209,0.0009209,-0.886167
486,44713.67588,121.492037,58920839,0.575991,1.510725,-0.878938,-0.891252,21.994288,0.232636,2.132082,0.109094,0.00109094,-0.015689,0.09341,0.0009341,-0.885206
495,44713.6759,123.742037,58920841,0.637473,1.547998,-0.877849,-0.890331,21.994214,0.234493,2.201466,0.110621,0.00110621,-0.015872,0.094794,0.00094794,-0.884152
504,44713.67593,125.992037,58920844,0.678945,1.600431,-0.8765,-0.889247,21.994657,0.237023,2.262072,0.112219,0.00112219,-0.016056,0.096088,0.00096088,-0.882919
513,44713.67596,128.242037,58920846,0.740035,1.648003,-0.875344,-0.888261,21.994362,0.239203,2.34457,0.11407,0.0011407,-0.016239,0.09783,0.0009783,-0.881736
522,44713.67598,130.492037,58920848,0.783933,1.710654,-0.873948,-0.886946,21.994804,0.241755,2.406056,0.115566,0.00115566,-0.016056,0.09932,0.0009932,-0.88056
531,44713.67601,132.742037,58920850,0.827617,1.762774,-0.872698,-0.886025,21.99473,0.244063,2.501653,0.117317,0.00117317,-0.016515,0.100772,0.00100772,-0.879361
540,44713.67603,134.992037,58920853,0.880138,1.803683,-0.871685,-0.885204,21.994951,0.246004,2.54168,0.118604,0.00118604,-0.016606,0.10208,0.0010208,-0.878403
549,44713.67606,137.242037,58920855,0.956773,1.844484,-0.87061,-0.884086,21.994878,0.247997,2.635934,0.120288,0.00120288,-0.016515,0.103682,0.00103682,-0.877484
558,44713.67609,139.492037,58920857,1.0073,1.92716,-0.86892,-0.882903,21.995099,0.251222,2.709472,0.122055,0.00122055,-0.01679,0.105357,0.00105357,-0.87595
567,44713.67611,141.742037,58920859,1.063252,1.968924,-0.86785,-0.881719,21.995099,0.253174,2.79562,0.123991,0.00123991,-0.016973,0.107017,0.00107017,-0.874838
576,44713.67614,143.992037,58920862,1.118697,2.024122,-0.866689,-0.880733,21.99532,0.255406,2.861124,0.125334,0.00125334,-0.017065,0.108269,0.00108269,-0.873689
585,44713.67616,146.242037,58920864,1.174372,2.082869,-0.865346,-0.879747,21.99532,0.25792,2.953003,0.127187,0.00127187,-0.017157,0.11003,0.0011003,-0.872453
594,44713.67619,148.492037,58920866,1.249617,2.13395,-0.864129,-0.878498,21.995541,0.260129,3.02605,0.128797,0.00128797,-0.01734,0.111457,0.00111457,-0.871326
603,44713.67622,150.742037,58920868,1.302334,2.194339,-0.862889,-0.877413,21.995615,0.262488,3.097191,0.130231,0.00130231,-0.01734,0.112866,0.00112866,-0.870322
612,44713.67624,152.992037,58920871,1.349292,2.256357,-0.861746,-0.876493,21.995688,0.264922,3.17012,0.131833,0.00131833,-0.017707,0.114204,0.00114204,-0.869145
621,44713.67627,155.242037,58920873,1.419206,2.307814,-0.860642,-0.875573,21.99591,0.266918,3.261519,0.13351,0.0013351,-0.017891,0.115614,0.00115614,-0.867966
630,44713.67629,157.492037,58920875,1.469193,2.370523,-0.859362,-0.874291,21.995983,0.269363,3.353259,0.135323,0.00135323,-0.018074,0.117248,0.00117248,-0.866745
639,44713.67632,159.742037,58920877,1.518333,2.428324,-0.858238,-0.873042,21.996204,0.271465,3.415998,0.136656,0.00136656,-0.017891,0.118766,0.00118766,-0.865824
648,44713.67635,161.992037,58920880,1.593474,2.52092,-0.856521,-0.871858,21.996131,0.274795,3.519001,0.138625,0.00138625,-0.018349,0.120487,0.00120487,-0.864234
657,44713.67637,164.242037,58920882,1.648079,2.544654,-0.855849,-0.871102,21.996499,0.276124,3.599834,0.140153,0.00140153,-0.018166,0.121987,0.00121987,-0.863376
666,44713.6764,166.492037,58920884,1.721071,2.608798,-0.854612,-0.869788,21.996352,0.278395,3.68242,0.141583,0.00141583,-0.018349,0.123234,0.00123234,-0.862375
675,44713.67642,168.742037,58920886,1.776076,2.66693,-0.853472,-0.8689,21.99672,0.280658,3.770258,0.143371,0.00143371,-0.018716,0.124655,0.00124655,-0.861124
684,44713.67645,170.992037,58920889,1.82333,2.714088,-0.85256,-0.86775,21.99672,0.282338,3.826881,0.144453,0.00144453,-0.018808,0.125644,0.00125644,-0.860351
693,44713.67648,173.242037,58920891,1.911855,2.76706,-0.851463,-0.866895,21.997015,0.284504,3.917562,0.145928,0.00145928,-0.018992,0.126937,0.00126937,-0.859334
702,44713.6765,175.492037,58920893,1.970098,2.837297,-0.850213,-0.865547,21.996941,0.28698,4.024147,0.147996,0.00147996,-0.019267,0.128854,0.00128854,-0.857961
711,44713.67653,177.742037,58920895,2.038312,2.908031,-0.848954,-0.86466,21.997163,0.289255,4.099293,0.149401,0.00149401,-0.019175,0.130226,0.00130226,-0.856831
720,44713.67655,179.992037,58920898,2.113165,2.956515,-0.847964,-0.863575,21.997236,0.29115,4.205518,0.151087,0.00151087,-0.019267,0.131748,0.00131748,-0.855773
729,44713.67658,182.242037,58920900,2.184653,3.043075,-0.846568,-0.862491,21.997457,0.293827,4.303124,0.1528,0.001528,-0.019817,0.132891,0.00132891,-0.854523
738,44713.67661,184.492037,58920902,2.249112,3.109288,-0.845412,-0.861504,21.997605,0.29604,4.38403,0.154268,0.00154268,-0.019726,0.134542,0.00134542,-0.853496
747,44713.67663,186.742037,58920904,2.304266,3.159423,-0.844457,-0.860584,21.997679,0.297873,4.456656,0.155721,0.00155721,-0.019909,0.135567,0.00135567,-0.85265
756,44713.67666,188.992037,58920907,2.397843,3.240242,-0.84306,-0.859631,21.997973,0.300487,4.595218,0.15755,0.0015755,-0.020276,0.137328,0.00137328,-0.851198
765,44713.67668,191.242037,58920909,2.46444,3.304189,-0.841922,-0.857987,21.997973,0.302786,4.674623,0.159195,0.00159195,-0.020551,0.138578,0.00138578,-0.850137
774,44713.67671,193.492037,58920911,2.511297,3.403333,-0.840418,-0.856968,21.998342,0.305632,4.75689,0.160641,0.00160641,-0.020735,0.139998,0.00139998,-0.848735
783,44713.67674,195.742037,58920913,2.599793,3.460274,-0.839471,-0.856015,21.998195,0.307362,4.891608,0.162489,0.00162489,-0.020827,0.141555,0.00141555,-0.847741
792,44713.67676,197.992037,58920916,2.676334,3.521416,-0.838356,-0.854799,21.99871,0.309536,4.959476,0.163775,0.00163775,-0.021102,0.142673,0.00142673,-0.846614
801,44713.67679,200.242037,58920918,2.755063,3.598637,-0.836999,-0.853616,21.998563,0.312173,5.098452,0.165867,0.00165867,-0.021285,0.144575,0.00144575,-0.845376
810,44713.67681,202.492037,58920920,2.811106,3.66625,-0.835872,-0.852958,21.999005,0.314238,5.165362,0.167158,0.00167158,-0.021469,0.145689,0.00145689,-0.844411
819,44713.67684,204.742037,58920922,2.907142,3.728341,-0.834806,-0.851709,21.998932,0.316236,5.281309,0.168917,0.00168917,-0.021652,0.14726,0.0014726,-0.843242
828,44713.67687,206.992037,58920925,2.968139,3.815198,-0.833589,-0.850822,21.999374,0.318667,5.382367,0.170337,0.00170337,-0.021836,0.148593,0.00148593,-0.842097
837,44713.67689,209.242037,58920927,3.033702,3.88908,-0.832434,-0.849441,21.9993,0.320961,5.494111,0.172024,0.00172024,-0.022019,0.149937,0.00149937,-0.840944
846,44713.67692,211.492037,58920929,3.102829,3.948252,-0.831404,-0.848422,21.999742,0.322849,5.58046,0.17361,0.0017361,-0.022386,0.151132,0.00151132,-0.839956
855,44713.67694,213.742037,58920931,3.218699,4.023774,-0.830215,-0.847272,21.999595,0.325141,5.715797,0.175373,0.00175373,-0.022662,0.15262,0.0015262,-0.838835
864,44713.67697,215.992037,58920934,3.293221,4.119635,-0.828778,-0.846154,22.000111,0.327841,5.825802,0.177035,0.00177035,-0.022937,0.15419,0.0015419,-0.837559
873,44713.677,218.242037,58920936,3.357449,4.172643,-0.827871,-0.845563,21.999964,0.329687,5.906844,0.178493,0.00178493,-0.022937,0.155434,0.00155434,-0.83645
882,44713.67702,220.492037,58920938,3.436695,4.252431,-0.826654,-0.844412,22.000406,0.331849,6.02404,0.180103,0.00180103,-0.023304,0.156797,0.00156797,-0.835413
891,44713.67705,222.742037,58920940,3.513247,4.308751,-0.825728,-0.843327,22.000258,0.333783,6.127927,0.181671,0.00181671,-0.023671,0.158022,0.00158022,-0.834412
900,44713.67708,224.992037,58920943,3.6117,4.427925,-0.824075,-0.841717,22.000922,0.336926,6.24024,0.183487,0.00183487,-0.023763,0.159715,0.00159715,-0.83294
909,44713.6771,227.242037,58920945,3.680259,4.492945,-0.823,-0.840928,22.000774,0.339039,6.346631,0.185024,0.00185024,-0.024038,0.160999,0.00160999,-0.831958
918,44713.67713,229.492037,58920947,3.754763,4.565125,-0.821895,-0.83958,22.001143,0.341223,6.448974,0.186528,0.00186528,-0.024313,0.162215,0.00162215,-0.830914
927,44713.67715,231.742037,58920949,3.842161,4.658208,-0.820649,-0.838397,22.001217,0.343677,6.582927,0.188302,0.00188302,-0.024588,0.163714,0.00163714,-0.829616
936,44713.67718,233.992037,58920952,3.893445,4.731117,-0.819556,-0.837542,22.001585,0.345822,6.677708,0.189732,0.00189732,-0.024772,0.16496,0.0016496,-0.828574
945,44713.67721,236.242037,58920954,4.02209,4.792711,-0.818449,-0.836753,22.001733,0.347854,6.806756,0.191552,0.00191552,-0.025047,0.166505,0.00166505,-0.827439
954,44713.67723,238.492037,58920956,4.085039,4.874723,-0.817224,-0.83534,22.001954,0.35023,6.915914,0.193035,0.00193035,-0.025322,0.167701,0.00167701,-0.826359
963,44713.67726,240.742037,58920958,4.155899,4.941445,-0.816265,-0.834716,22.002175,0.352061,6.971538,0.194232,0.00194232,-0.025506,0.168722,0.00168722,-0.82546
972,44713.67728,242.992037,58920961,4.238388,5.050236,-0.814855,-0.833368,22.002322,0.354813,7.149018,0.196338,0.00196338,-0.025873,0.170557,0.00170557,-0.823973
981,44713.67731,245.242037,58920963,4.32959,5.115551,-0.813855,-0.832448,22.002617,0.356619,7.259479,0.197784,0.00197784,-0.026056,0.171727,0.00171727,-0.823035
990,44713.67734,247.492037,58920965,4.417955,5.232553,-0.812337,-0.8311,22.002838,0.359523,7.403003,0.199673,0.00199673,-0.026515,0.173341,0.00173341,-0.821548
999,44713.67736,249.742037,58920967,4.51417,5.296477,-0.811381,-0.830114,22.003133,0.361335,7.488335,0.200963,0.00200963,-0.02679,0.17418,0.0017418,-0.820809
1008,44713.67739,251.992037,58920970,4.583809,5.350008,-0.810504,-0.829161,22.003207,0.363106,7.583383,0.202379,0.00202379,-0.026974,0.175387,0.00175387,-0.819842
1017,44713.67741,254.242037,58920972,4.685607,5.467488,-0.809004,-0.82801,22.003649,0.365983,7.728427,0.204377,0.00204377,-0.027249,0.177168,0.00177168,-0.818391
1026,44713.67744,256.492037,58920974,4.770575,5.550758,-0.807905,-0.826662,22.003649,0.368121,7.82844,0.205739,0.00205739,-0.027524,0.178199,0.00178199,-0.817452
1035,44713.67747,258.742037,58920976,4.839053,5.627774,-0.806812,-0.825874,22.004165,0.370281,7.965352,0.207301,0.00207301,-0.027983,0.179533,0.00179533,-0.816414
1044,44713.67749,260.992037,58920979,4.948136,5.713172,-0.805571,-0.82446,22.004165,0.372581,8.087218,0.20905,0.0020905,-0.028075,0.181008,0.00181008,-0.815035
1053,44713.67752,263.242037,58920981,5.043376,5.824956,-0.80425,-0.823408,22.004755,0.375272,8.227103,0.210661,0.00210661,-0.02835,0.182296,0.00182296,-0.814032
1062,44713.67754,265.492037,58920983,5.133242,5.873595,-0.80333,-0.822817,22.004681,0.376869,8.359444,0.212587,0.00212587,-0.029084,0.183411,0.00183411,-0.812673
1071,44713.67757,267.742037,58920985,5.238764,6.006374,-0.801817,-0.821338,22.005271,0.379787,8.492581,0.214192,0.00214192,-0.029451,0.184741,0.00184741,-0.811491
1080,44713.6776,269.992037,58920988,5.319882,6.087204,-0.80072,-0.820253,22.005271,0.381997,8.626644,0.215879,0.00215879,-0.029359,0.18645,0.0018645,-0.810417
1089,44713.67762,272.242037,58920990,5.411014,6.17369,-0.79957,-0.819201,22.005787,0.384114,8.734337,0.21741,0.0021741,-0.030185,0.18733,0.0018733,-0.809223
1098,44713.67765,274.492037,58920992,5.457304,6.246843,-0.798555,-0.818051,22.005787,0.38615,8.812149,0.218436,0.00218436,-0.030368,0.188224,0.00188224,-0.808578
1107,44713.67767,276.742037,58920994,5.595281,6.355908,-0.797201,-0.817229,22.006376,0.38878,8.987369,0.220401,0.00220401,-0.030644,0.189935,0.00189935,-0.807032
1116,44713.6777,278.992037,58920997,5.69917,6.471173,-0.795838,-0.815848,22.00645,0.391396,9.127841,0.222279,0.00222279,-0.030827,0.191544,0.00191544,-0.805763
1125,44713.67773,281.242037,58920999,5.769994,6.530241,-0.794941,-0.814796,22.006892,0.393138,9.214776,0.22357,0.0022357,-0.031102,0.192297,0.00192297,-0.804985
1134,44713.67775,283.492037,58921001,5.854962,6.601991,-0.793958,-0.813975,22.006966,0.394989,9.341723,0.224977,0.00224977,-0.031836,0.193141,0.00193141,-0.804
1143,44713.67778,285.742037,58921003,5.98388,6.725529,-0.79251,-0.812758,22.007408,0.39771,9.509041,0.226946,0.00226946,-0.031928,0.19497,0.0019497,-0.802621
1152,44713.6778,287.992037,58921006,6.034366,6.805018,-0.791472,-0.811707,22.007629,0.399921,9.614395,0.22831,0.0022831,-0.03257,0.195723,0.00195723,-0.801614
1161,44713.67783,290.242037,58921008,6.128589,6.872149,-0.790537,-0.810786,22.007924,0.401585,9.741496,0.229767,0.00229767,-0.032937,0.196829,0.00196829,-0.800647
1170,44713.67786,292.492037,58921010,6.259551,7.00054,-0.78906,-0.809669,22.008366,0.404471,9.920102,0.231867,0.00231867,-0.033121,0.198746,0.00198746,-0.799177
1179,44713.67788,294.742037,58921012,6.355844,7.106989,-0.787813,-0.808288,22.008514,0.40691,10.057187,0.233515,0.00233515,-0.033763,0.199798,0.00199798,-0.798073
1188,44713.67791,296.992037,58921015,6.444546,7.186836,-0.786777,-0.807006,22.009103,0.408975,10.174329,0.234911,0.00234911,-0.033947,0.200817,0.00200817,-0.797149
1197,44713.67793,299.242037,58921017,6.535077,7.254246,-0.785785,-0.806776,22.009103,0.410836,10.254746,0.236256,0.00236256,-0.034497,0.201759,0.00201759,-0.796105
1206,44713.67796,301.492037,58921019,6.589989,7.335889,-0.784813,-0.805297,22.009693,0.412716,10.361233,0.237546,0.00237546,-0.034864,0.202682,0.00202682,-0.795201
1215,44713.67799,303.742037,58921021,6.724423,7.491776,-0.783135,-0.803785,22.009914,0.415961,10.540303,0.239718,0.00239718,-0.035323,0.204448,0.00204448,-0.79358
1224,44713.67801,305.992037,58921024,6.838701,7.568332,-0.782061,-0.8027,22.010504,0.41793,10.721179,0.241401,0.00241401,-0.03569,0.205683,0.00205683,-0.792523
1233,44713.67804,308.242037,58921026,6.905446,7.625886,-0.781295,-0.801879,22.010578,0.419534,10.785892,0.242571,0.00242571,-0.036057,0.206514,0.00206514,-0.791684
1242,44713.67806,310.492037,58921028,7.03387,7.745934,-0.779957,-0.800925,22.01102,0.422078,10.979781,0.244363,0.00244363,-0.036515,0.207846,0.00207846,-0.790397
1251,44713.67809,312.742037,58921030,7.120458,7.848574,-0.778738,-0.799643,22.011388,0.424631,11.094563,0.246248,0.00246248,-0.036882,0.20895,0.0020895,-0.78911
1260,44713.67812,314.992037,58921033,7.228165,7.924146,-0.777685,-0.798723,22.011757,0.426583,11.243864,0.24767,0.0024767,-0.037341,0.210305,0.00210305,-0.788196
1269,44713.67814,317.242037,58921035,7.299559,8.049218,-0.77637,-0.797408,22.012125,0.429071,11.372856,0.249142,0.00249142,-0.037892,0.21125,0.0021125,-0.787005
1278,44713.67817,319.492037,58921037,7.410885,8.133907,-0.77535,-0.796258,22.012347,0.431168,11.472314,0.250674,0.00250674,-0.038534,0.212167,0.00212167,-0.785993
1287,44713.67819,321.742037,58921039,7.501898,8.258817,-0.774044,-0.79537,22.01301,0.433634,11.646302,0.252319,0.00252319,-0.038901,0.21351,0.0021351,-0.784741
1296,44713.67822,323.992037,58921042,7.633384,8.308027,-0.773157,-0.794516,22.013084,0.435512,11.740776,0.253772,0.00253772,-0.039451,0.214321,0.00214321,-0.783843
1305,44713.67825,326.242037,58921044,7.714417,8.41669,-0.77201,-0.793234,22.013821,0.437676,11.926882,0.255579,0.00255579,-0.03991,0.215577,0.00215577,-0.782493
1314,44713.67827,328.492037,58921046,7.802642,8.535908,-0.770714,-0.791952,22.013894,0.440201,12.062792,0.257045,0.00257045,-0.040369,0.216768,0.00216768,-0.781571
1323,44713.6783,330.742037,58921048,7.949681,8.630517,-0.769561,-0.791196,22.014558,0.442398,12.207828,0.258818,0.00258818,-0.040919,0.21787,0.0021787,-0.780267
1332,44713.67833,332.992037,58921051,8.047921,8.749855,-0.768281,-0.789651,22.014779,0.444999,12.424322,0.260844,0.00260844,-0.041562,0.219283,0.00219283,-0.778892
1341,44713.67835,335.242037,58921053,8.130071,8.862628,-0.767087,-0.788665,22.015516,0.44734,12.495585,0.261835,0.00261835,-0.04202,0.219887,0.00219887,-0.778201
1350,44713.67838,337.492037,58921055,8.217258,8.949368,-0.766007,-0.787712,22.015663,0.449358,12.631039,0.263475,0.00263475,-0.042479,0.220996,0.00220996,-0.776939
1359,44713.6784,339.742037,58921057,8.343411,9.050393,-0.764885,-0.786693,22.016253,0.451624,12.786117,0.265251,0.00265251,-0.04303,0.222305,0.00222305,-0.775841
1368,44713.67843,341.992037,58921060,8.452616,9.175776,-0.763501,-0.785411,22.016548,0.454246,12.946304,0.266891,0.00266891,-0.043672,0.223311,0.00223311,-0.774487
1377,44713.67846,344.242037,58921062,8.550349,9.236932,-0.762687,-0.784425,22.017211,0.45596,13.071199,0.268461,0.00268461,-0.044131,0.224331,0.00224331,-0.773561
1386,44713.67848,346.492037,58921064,8.677126,9.36695,-0.761305,-0.783241,22.017506,0.458676,13.234402,0.270287,0.00270287,-0.044773,0.225474,0.00225474,-0.772283
1395,44713.67851,348.742037,58921066,8.75439,9.478383,-0.760097,-0.782025,22.018096,0.46088,13.32313,0.271502,0.00271502,-0.045323,0.226179,0.00226179,-0.771202
1404,44713.67853,350.992037,58921069,8.891573,9.560212,-0.759083,-0.781006,22.018464,0.462946,13.509842,0.27332,0.0027332,-0.045874,0.227412,0.00227412,-0.770006
1413,44713.67856,353.242037,58921071,8.99959,9.7052,-0.757619,-0.779757,22.019128,0.465858,13.715527,0.275274,0.00275274,-0.046608,0.228715,0.00228715,-0.768689
1422,44713.67859,355.492037,58921073,9.08801,9.750309,-0.756893,-0.779067,22.019423,0.467319,13.827527,0.276728,0.00276728,-0.047066,0.229596,0.00229596,-0.767836
1431,44713.67861,357.742037,58921075,9.162047,9.834676,-0.755914,-0.778048,22.019939,0.469185,13.891877,0.277685,0.00277685,-0.047709,0.230068,0.00230068,-0.766969
1440,44713.67864,359.992037,58921078,9.263902,9.933328,-0.754824,-0.777128,22.020307,0.471277,14.046222,0.279378,0.00279378,-0.048167,0.23121,0.0023121,-0.765919
1449,44713.67866,362.242037,58921080,9.415165,10.088916,-0.753326,-0.77555,22.020971,0.47418,14.270475,0.281392,0.00281392,-0.048993,0.232399,0.00232399,-0.764418
1458,44713.67869,364.492037,58921082,9.531514,10.225577,-0.752015,-0.774432,22.021486,0.476708,14.440165,0.283141,0.00283141,-0.049635,0.233506,0.00233506,-0.763222
1467,44713.67872,366.742037,58921084,9.593534,10.297152,-0.751084,-0.773282,22.022076,0.478622,14.533694,0.284438,0.00284438,-0.050278,0.234069,0.00234069,-0.762313
1476,44713.67874,368.992037,58921087,9.725893,10.392061,-0.749975,-0.772394,22.022518,0.480679,14.706907,0.286182,0.00286182,-0.05092,0.23531,0.0023531,-0.761177
1485,44713.67877,371.242037,58921089,9.84843,10.500446,-0.748816,-0.771211,22.023182,0.483081,14.842871,0.287739,0.00287739,-0.051562,0.236181,0.00236181,-0.760063
1494,44713.67879,373.492037,58921091,9.924005,10.592826,-0.747713,-0.770159,22.02355,0.485022,14.970258,0.289154,0.00289154,-0.052204,0.236957,0.00236957,-0.759031
1503,44713.67882,375.742037,58921093,10.047928,10.707562,-0.746506,-0.768943,22.024287,0.487395,15.139411,0.290896,0.00290896,-0.05303,0.237969,0.00237969,-0.757857
1512,44713.67885,377.992037,58921096,10.183567,10.839553,-0.745215,-0.767793,22.02473,0.490054,15.352376,0.292894,0.00292894,-0.053947,0.238963,0.00238963,-0.756516
1521,44713.67887,380.242037,58921098,10.280418,10.950598,-0.744052,-0.766412,22.02554,0.492429,15.466391,0.294275,0.00294275,-0.054314,0.239894,0.00239894,-0.755424
1530,44713.6789,382.492037,58921100,10.371323,11.00883,-0.743216,-0.765722,22.025835,0.493974,15.600714,0.295784,0.00295784,-0.055048,0.240659,0.00240659,-0.754489
1539,44713.67892,384.742037,58921102,10.500212,11.146551,-0.741892,-0.764571,22.026646,0.496541,15.722542,0.297177,0.00297177,-0.056058,0.241219,0.00241219,-0.753325
1548,44713.67895,386.992037,58921105,10.572535,11.216471,-0.741041,-0.763782,22.026867,0.498223,15.869454,0.298762,0.00298762,-0.0567,0.24197,0.0024197,-0.752418
1557,44713.67898,389.242037,58921107,10.698509,11.350984,-0.739737,-0.762402,22.027899,0.500761,16.014522,0.300448,0.00300448,-0.05725,0.243197,0.00243197,-0.75117
1566,44713.679,391.492037,58921109,10.798348,11.457189,-0.738583,-0.761482,22.02812,0.503029,16.233944,0.302249,0.00302249,-0.058076,0.244086,0.00244086,-0.749909
1575,44713.67903,393.742037,58921111,10.940455,11.579417,-0.737304,-0.759904,22.029226,0.505595,16.405355,0.304001,0.00304001,-0.059177,0.244824,0.00244824,-0.748683
1584,44713.67905,395.992037,58921114,11.020695,11.642051,-0.7365,-0.759345,22.029447,0.507189,16.518939,0.305414,0.00305414,-0.059728,0.245645,0.00245645,-0.747667
1593,44713.67908,398.242037,58921116,11.114459,11.784564,-0.735139,-0.758096,22.030479,0.509866,16.63178,0.306711,0.00306711,-0.060645,0.246117,0.00246117,-0.746622
1602,44713.67911,400.492037,58921118,11.247224,11.87126,-0.734103,-0.756748,22.030995,0.51196,16.77231,0.30832,0.0030832,-0.061563,0.246776,0.00246776,-0.745582
1611,44713.67913,402.742037,58921120,11.328493,11.971214,-0.73301,-0.755927,22.031732,0.514089,16.945104,0.309921,0.00309921,-0.062296,0.247625,0.00247625,-0.74445
1620,44713.67916,404.992037,58921123,11.440582,12.076399,-0.731846,-0.754875,22.032248,0.516314,17.081127,0.311499,0.00311499,-0.063122,0.248427,0.00248427,-0.743373
1629,44713.67918,407.242037,58921125,11.562914,12.189906,-0.730687,-0.753691,22.033132,0.518618,17.29501,0.313563,0.00313563,-0.064131,0.249365,0.00249365,-0.741972
1638,44713.67921,409.492037,58921127,11.706948,12.350198,-0.7292,-0.752311,22.03387,0.521474,17.449876,0.315115,0.00315115,-0.064865,0.25025,0.0025025,-0.740903
1647,44713.67924,411.742037,58921129,11.81475,12.448606,-0.72811,-0.751029,22.03468,0.523783,17.613426,0.31683,0.0031683,-0.066242,0.250588,0.00250588,-0.739703
1656,44713.67926,413.992037,58921132,11.887165,12.506107,-0.727292,-0.750372,22.035417,0.525215,17.693342,0.318069,0.00318069,-0.066884,0.251268,0.00251268,-0.738948
1665,44713.67929,416.242037,58921134,12.007642,12.652623,-0.725837,-0.749155,22.036007,0.528145,17.862432,0.319973,0.00319973,-0.067801,0.25208,0.0025208,-0.737457
1674,44713.67931,418.492037,58921136,12.110367,12.756187,-0.724689,-0.747841,22.037113,0.53042,18.057763,0.321812,0.00321812,-0.068994,0.252828,0.00252828,-0.736215
1683,44713.67934,420.742037,58921138,12.193704,12.839375,-0.723794,-0.747019,22.037481,0.532136,18.127571,0.322846,0.00322846,-0.069636,0.25305,0.0025305,-0.735424
1692,44713.67937,422.992037,58921141,12.316189,12.975206,-0.722466,-0.745638,22.038661,0.534898,18.330175,0.324688,0.00324688,-0.070737,0.254042,0.00254042,-0.734009
1701,44713.67939,425.242037,58921143,12.417355,13.045887,-0.721512,-0.744915,22.039103,0.536751,18.444958,0.326094,0.00326094,-0.071746,0.254334,0.00254334,-0.733227
1710,44713.67942,427.492037,58921145,12.562195,13.180395,-0.720166,-0.743535,22.040356,0.539315,18.6219,0.327923,0.00327923,-0.072939,0.254983,0.00254983,-0.731938
1719,44713.67944,429.742037,58921147,12.666872,13.291052,-0.719015,-0.742187,22.040946,0.541701,18.785099,0.329552,0.00329552,-0.073948,0.255696,0.00255696,-0.730686
1728,44713.67947,431.992037,58921150,12.760729,13.365263,-0.71801,-0.740938,22.042051,0.543644,18.927379,0.331134,0.00331134,-0.075049,0.256084,0.00256084,-0.72963
1737,44713.6795,434.242037,58921152,12.876943,13.480687,-0.716869,-0.740248,22.042641,0.545816,19.102991,0.33285,0.0033285,-0.076242,0.256608,0.00256608,-0.72856
1746,44713.67952,436.492037,58921154,12.945255,13.560479,-0.715912,-0.73913,22.043747,0.547792,19.194698,0.33411,0.0033411,-0.077068,0.257134,0.00257134,-0.727607
1755,44713.67955,438.742037,58921156,13.05097,13.649091,-0.714822,-0.738144,22.044484,0.55004,19.311605,0.335719,0.00335719,-0.078169,0.257443,0.00257443,-0.72648
1764,44713.67958,440.992037,58921159,13.16567,13.753439,-0.713666,-0.737059,22.045589,0.552379,19.469569,0.337266,0.00337266,-0.07927,0.257928,0.00257928,-0.725445
1773,44713.6796,443.242037,58921161,13.300897,13.855142,-0.712504,-0.736073,22.046474,0.554508,19.593957,0.338814,0.00338814,-0.080921,0.257984,0.00257984,-0.724322
1782,44713.67963,445.492037,58921163,13.389814,13.94144,-0.711439,-0.734923,22.047506,0.556621,19.780777,0.340722,0.00340722,-0.082114,0.258696,0.00258696,-0.723136
1791,44713.67965,447.742037,58921165,13.516167,14.112928,-0.709916,-0.733444,22.048538,0.559787,19.978463,0.342576,0.00342576,-0.083215,0.259361,0.00259361,-0.721681
1800,44713.67968,449.992037,58921168,13.608949,14.224362,-0.70867,-0.732227,22.049643,0.562163,20.10741,0.344178,0.00344178,-0.084591,0.259571,0.00259571,-0.720513
1809,44713.67971,452.242037,58921170,13.666487,14.258425,-0.707915,-0.73134,22.050675,0.563692,20.180337,0.345341,0.00345341,-0.085967,0.259373,0.00259373,-0.719773
1818,44713.67973,454.492037,58921172,13.786487,14.36974,-0.706663,-0.730485,22.051707,0.566115,20.346684,0.347278,0.00347278,-0.087252,0.259969,0.00259969,-0.718429
1827,44713.67976,456.742037,58921174,13.92832,14.521071,-0.705202,-0.728776,22.053034,0.568992,20.525584,0.349071,0.00349071,-0.088811,0.260326,0.00260326,-0.717073
1836,44713.67978,458.992037,58921177,14.035578,14.618799,-0.704018,-0.727658,22.054139,0.571379,20.671798,0.350806,0.00350806,-0.090279,0.260584,0.00260584,-0.715879
1845,44713.67981,461.242037,58921179,14.112513,14.729079,-0.702772,-0.726409,22.055614,0.573861,20.841531,0.352667,0.00352667,-0.091839,0.260828,0.00260828,-0.714587
1854,44713.67984,463.492037,58921181,14.179623,14.784889,-0.701877,-0.72539,22.056498,0.57554,20.893942,0.353766,0.00353766,-0.093307,0.26042,0.0026042,-0.713847
1863,44713.67986,465.742037,58921183,14.27809,14.870621,-0.700786,-0.724634,22.057899,0.577755,21.010681,0.355295,0.00355295,-0.094775,0.260519,0.00260519,-0.712714
1872,44713.67989,467.992037,58921186,14.346117,14.921063,-0.699947,-0.723648,22.058709,0.579405,21.15402,0.356892,0.00356892,-0.09606,0.260664,0.00260664,-0.711777
1881,44713.67991,470.242037,58921188,14.441129,15.024656,-0.698766,-0.722498,22.060331,0.581795,21.272508,0.358376,0.00358376,-0.097803,0.260574,0.00260574,-0.710649
1890,44713.67994,472.492037,58921190,14.558534,15.145499,-0.697459,-0.721183,22.061363,0.584379,21.399218,0.359995,0.00359995,-0.099454,0.260793,0.00260793,-0.70931
1899,44713.67997,474.742037,58921192,14.652994,15.194519,-0.696522,-0.720361,22.062837,0.586227,21.544179,0.361648,0.00361648,-0.100739,0.260799,0.00260799,-0.70833
1908,44713.67999,476.992037,58921195,14.755881,15.324631,-0.695177,-0.719014,22.064164,0.588906,21.680798,0.363485,0.00363485,-0.103032,0.260475,0.00260475,-0.707028
1917,44713.68002,479.242037,58921197,14.855473,15.414045,-0.69398,-0.717699,22.065785,0.591134,21.819388,0.365116,0.00365116,-0.104592,0.260489,0.00260489,-0.705927
1926,44713.68004,481.492037,58921199,14.891001,15.461649,-0.693071,-0.716746,22.067112,0.593165,21.906396,0.366555,0.00366555,-0.10661,0.259969,0.00259969,-0.704994
1935,44713.68007,483.742037,58921201,14.959507,15.527629,-0.69208,-0.716023,22.068734,0.59517,21.963226,0.367807,0.00367807,-0.10817,0.259623,0.00259623,-0.704019
1944,44713.6801,485.992037,58921204,15.072029,15.677469,-0.690542,-0.714445,22.070208,0.598113,22.162173,0.369991,0.00369991,-0.11028,0.259623,0.00259623,-0.702489
1953,44713.68012,488.242037,58921206,15.148549,15.732662,-0.689538,-0.713557,22.072051,0.600061,22.255739,0.37141,0.0037141,-0.112391,0.258913,0.00258913,-0.701443
1962,44713.68015,490.492037,58921208,15.226683,15.811421,-0.688433,-0.712473,22.073451,0.602272,22.321543,0.372732,0.00372732,-0.114409,0.258396,0.00258396,-0.700392
1971,44713.68017,492.742037,58921210,15.340758,15.879132,-0.687363,-0.711224,22.075294,0.604358,22.503604,0.374559,0.00374559,-0.116427,0.25811,0.0025811,-0.699307
1980,44713.6802,494.992037,58921213,15.421788,16.005214,-0.685933,-0.71004,22.077063,0.607179,22.626109,0.376403,0.00376403,-0.118905,0.257551,0.00257551,-0.698001
1989,44713.68023,497.242037,58921215,15.501693,16.050097,-0.685016,-0.708988,22.078979,0.609008,22.737561,0.377883,0.00377883,-0.121107,0.256803,0.00256803,-0.697048
1998,44713.68025,499.492037,58921217,15.574785,16.16973,-0.683642,-0.707739,22.080748,0.611746,22.800124,0.379295,0.00379295,-0.123309,0.255987,0.00255987,-0.695933
2007,44713.68028,501.742037,58921219,15.630604,16.199502,-0.682757,-0.706852,22.082738,0.613576,22.951609,0.381135,0.00381135,-0.125786,0.255352,0.00255352,-0.694689
2016,44713.6803,503.992037,58921222,15.666093,16.25874,-0.681771,-0.7058,22.084581,0.615537,22.999064,0.382194,0.00382194,-0.128079,0.254115,0.00254115,-0.693824
2025,44713.68033,506.242037,58921224,15.798408,16.356547,-0.680428,-0.704485,22.086792,0.618135,23.150247,0.38422,0.0038422,-0.13074,0.253471,0.00253471,-0.692535
2034,44713.68036,508.492037,58921226,15.84465,16.407172,-0.679377,-0.703466,22.089004,0.620169,23.207654,0.385652,0.00385652,-0.133676,0.251976,0.00251976,-0.691467
2043,44713.68038,510.742037,58921228,15.895833,16.458979,-0.678392,-0.702546,22.090994,0.622158,23.259523,0.387102,0.00387102,-0.136428,0.250663,0.00250663,-0.690455
2052,44713.68041,512.992037,58921231,15.956709,16.559032,-0.67704,-0.701132,22.093795,0.624807,23.370796,0.388935,0.00388935,-0.139181,0.249611,0.00249611,-0.68915
2061,44713.68043,515.242037,58921233,16.045509,16.627849,-0.675883,-0.700344,22.095859,0.627064,23.514131,0.39063,0.0039063,-0.142117,0.248513,0.00248513,-0.688033
2070,44713.68046,517.492037,58921235,16.120262,16.691422,-0.674716,-0.699029,22.098733,0.629398,23.597171,0.392359,0.00392359,-0.145511,0.24679,0.0024679,-0.686808
2079,44713.68049,519.742037,58921237,16.18146,16.726791,-0.673623,-0.697977,22.101092,0.631515,23.676437,0.393868,0.00393868,-0.148814,0.24503,0.0024503,-0.685792
2088,44713.68051,521.992037,58921240,16.204938,16.773368,-0.672544,-0.696596,22.104188,0.633626,23.691015,0.395188,0.00395188,-0.152301,0.242888,0.00242888,-0.684852
2097,44713.68054,524.242037,58921242,16.225616,16.804402,-0.671542,-0.695742,22.106694,0.635638,23.752673,0.396632,0.00396632,-0.155787,0.24086,0.0024086,-0.683831
2106,44713.68056,526.492037,58921244,16.315371,16.858266,-0.670386,-0.694756,22.110084,0.638025,23.889849,0.39863,0.0039863,-0.159549,0.239081,0.00239081,-0.682629
2115,44713.68059,528.742037,58921246,16.376899,16.93104,-0.669028,-0.693474,22.11318,0.640704,23.959684,0.400354,0.00400354,-0.163769,0.236585,0.00236585,-0.681236
2124,44713.68062,530.992037,58921249,16.404097,16.950998,-0.668015,-0.692652,22.116644,0.642624,23.966425,0.401695,0.00401695,-0.167898,0.233849,0.00233849,-0.680297
2133,44713.68064,533.242037,58921251,16.457065,16.987577,-0.666883,-0.691502,22.119888,0.644862,24.026225,0.403311,0.00403311,-0.17221,0.231031,0.00231031,-0.679166
2142,44713.68067,535.492037,58921253,16.481069,17.041675,-0.665686,-0.69022,22.123794,0.647206,24.091601,0.404856,0.00404856,-0.176614,0.228242,0.00228242,-0.678069
2151,44713.68069,537.742037,58921255,16.538914,17.08196,-0.664561,-0.689464,22.126964,0.649333,24.187885,0.406668,0.00406668,-0.180926,0.225744,0.00225744,-0.676816
2160,44713.68072,539.992037,58921258,16.605074,17.111649,-0.663473,-0.688116,22.13087,0.651468,24.262655,0.408294,0.00408294,-0.185422,0.222852,0.00222852,-0.675561
2169,44713.68075,542.242037,58921260,16.613137,17.157645,-0.662287,-0.687097,22.134851,0.65378,24.270416,0.409863,0.00409863,-0.190468,0.219226,0.00219226,-0.674579
2178,44713.68077,544.492037,58921262,16.608581,17.156779,-0.661314,-0.686242,22.139052,0.6557,24.262642,0.411097,0.00411097,-0.195697,0.215342,0.00215342,-0.673756
2187,44713.6808,546.742037,58921264,16.714988,17.256294,-0.659715,-0.684698,22.143474,0.6589,24.383572,0.413239,0.00413239,-0.201477,0.211668,0.00211668,-0.672189
2196,44713.68083,548.992037,58921267,16.728955,17.269501,-0.658675,-0.68335,22.148044,0.660951,24.387791,0.414712,0.00414712,-0.206799,0.208097,0.00208097,-0.670994
2205,44713.68085,551.242037,58921269,16.725584,17.265995,-0.657635,-0.682199,22.152909,0.663066,24.427525,0.416238,0.00416238,-0.212946,0.203331,0.00203331,-0.670074
2214,44713.68088,553.492037,58921271,16.718279,17.297674,-0.656381,-0.681411,22.157995,0.665386,24.440343,0.417801,0.00417801,-0.219368,0.198487,0.00198487,-0.668921
2223,44713.6809,555.742037,58921273,16.811271,17.335474,-0.65507,-0.679833,22.163376,0.667961,24.513879,0.419729,0.00419729,-0.225882,0.193832,0.00193832,-0.667597
2232,44713.68093,557.992037,58921276,16.791831,17.294475,-0.654126,-0.679406,22.169199,0.669729,24.519167,0.421326,0.00421326,-0.233222,0.187926,0.00187926,-0.66668
2241,44713.68096,560.242037,58921278,16.797602,17.338598,-0.652723,-0.677894,22.17539,0.672471,24.536846,0.423102,0.00423102,-0.240654,0.18234,0.0018234,-0.665249
2250,44713.68098,562.492037,58921280,16.803707,17.347528,-0.651544,-0.676743,22.181877,0.674845,24.53021,0.424705,0.00424705,-0.249003,0.175702,0.00175702,-0.664305
2259,44713.68101,564.742037,58921282,16.769766,17.352589,-0.650291,-0.675625,22.189395,0.677365,24.504453,0.426265,0.00426265,-0.258086,0.16818,0.0016818,-0.662957
2268,44713.68103,566.992037,58921285,16.789459,17.329314,-0.649203,-0.674508,22.196397,0.679327,24.499012,0.427851,0.00427851,-0.26726,0.16059,0.0016059,-0.662024
2277,44713.68106,569.242037,58921287,16.754871,17.2938,-0.64811,-0.673719,22.204948,0.681395,24.468052,0.429452,0.00429452,-0.277261,0.152191,0.00152191,-0.660935
2286,44713.68109,571.492037,58921289,16.684146,17.190144,-0.647429,-0.672996,22.21335,0.682792,24.352944,0.430429,0.00430429,-0.288362,0.142245,0.00142245,-0.660058
2295,44713.68111,573.742037,58921291,16.694279,17.239922,-0.645837,-0.671451,22.223817,0.685764,24.385664,0.432485,0.00432485,-0.300656,0.131751,0.00131751,-0.65863
2304,44713.68114,575.992037,58921294,16.619728,17.133632,-0.644808,-0.670366,22.236642,0.687758,24.252327,0.433849,0.00433849,-0.316896,0.116786,0.00116786,-0.657789
2313,44713.68116,578.242037,58921296,16.558047,17.099183,-0.643377,-0.669676,22.251679,0.690512,24.163533,0.435731,0.00435731,-0.335429,0.100422,0.00100422,-0.656388
2322,44713.68119,580.492037,58921298,16.454335,17.01175,-0.642389,-0.668789,22.266494,0.692234,24.049459,0.437059,0.00437059,-0.35387,0.083189,0.00083189,-0.655512
2331,44713.68122,582.742037,58921300,16.429675,16.907665,-0.641178,-0.667638,22.288238,0.694528,23.986392,0.438829,0.00438829,-0.379009,0.059774,0.00059774,-0.654303
2340,44713.68124,584.992037,58921303,16.238818,16.796132,-0.639607,-0.666225,22.324945,0.697315,23.772104,0.440664,0.00440664,-0.426809,0.013757,0.00013757,-0.652984
2349,44713.68127,587.242037,58921305,16.258683,16.778461,-0.638361,-0.665403,22.336813,0.699727,23.753301,0.442469,0.00442469,-0.441672,0.000736,0.00000736,-0.651798
2358,44713.68129,589.492037,58921307,16.246819,16.784964,-0.637131,-0.664154,22.346395,0.701855,23.742059,0.444068,0.00444068,-0.453875,-0.009706,-0.00009706,-0.650558
2367,44713.68132,591.742037,58921309,16.226625,16.758158,-0.636242,-0.663234,22.355608,0.70366,23.694882,0.445108,0.00445108,-0.464976,-0.019906,-0.00019906,-0.649908
2376,44713.68135,593.992037,58921312,16.269358,16.796238,-0.634897,-0.661985,22.365633,0.706314,23.767226,0.447105,0.00447105,-0.477546,-0.030543,-0.00030543,-0.64851
2385,44713.68137,596.242037,58921314,16.258991,16.818715,-0.633756,-0.661097,22.373962,0.708537,23.749729,0.448461,0.00448461,-0.487913,-0.039326,-0.00039326,-0.647408
2394,44713.6814,598.492037,58921316,16.246554,16.772612,-0.632952,-0.660374,22.381996,0.710085,23.721852,0.449722,0.00449722,-0.498005,-0.048283,-0.00048283,-0.646678
2403,44713.68142,600.742037,58921318,16.282246,16.784098,-0.631717,-0.65896,22.39062,0.712328,23.789906,0.451681,0.00451681,-0.50874,-0.056967,-0.00056967,-0.645328
2412,44713.68145,602.992037,58921321,16.310366,16.844137,-0.630169,-0.657876,22.399907,0.715314,23.836321,0.453602,0.00453602,-0.5203,-0.066698,-0.00066698,-0.643838
2421,44713.68148,605.242037,58921323,16.305536,16.86054,-0.628793,-0.656462,22.410595,0.71797,23.838462,0.45534,0.0045534,-0.53342,-0.07808,-0.0007808,-0.642698
2430,44713.6815,607.492037,58921325,16.26254,16.787042,-0.628108,-0.655542,22.42003,0.719421,23.763657,0.456448,0.00456448,-0.545347,-0.088807,-0.00088807,-0.642023
2439,44713.68153,609.742037,58921327,16.235713,16.781619,-0.626876,-0.654655,22.430128,0.721767,23.74584,0.458145,0.00458145,-0.557916,-0.099772,-0.00099772,-0.640774
2448,44713.68155,611.992037,58921330,16.197574,16.749873,-0.625864,-0.653899,22.440668,0.723752,23.683953,0.459419,0.00459419,-0.570853,-0.111447,-0.00111447,-0.639707
2457,44713.68158,614.242037,58921332,16.227691,16.758634,-0.624441,-0.652419,22.451946,0.726558,23.708922,0.461434,0.00461434,-0.584982,-0.123456,-0.00123456,-0.638513
2466,44713.68161,616.492037,58921334,16.172643,16.709438,-0.623428,-0.651631,22.464403,0.728526,23.642586,0.462994,0.00462994,-0.600396,-0.137441,-0.00137441,-0.637351
2475,44713.68163,618.742037,58921336,16.152301,16.679744,-0.622244,-0.650283,22.477744,0.730759,23.591119,0.464545,0.00464545,-0.617002,-0.152435,-0.00152435,-0.636359
2484,44713.68166,620.992037,58921339,16.124352,16.60186,-0.621252,-0.649395,22.491527,0.732669,23.514797,0.466018,0.00466018,-0.634159,-0.168097,-0.00168097,-0.635326
2493,44713.68168,623.242037,58921341,16.070699,16.559249,-0.620063,-0.648541,22.505827,0.734827,23.454203,0.467717,0.00467717,-0.652141,-0.184425,-0.00184425,-0.634082
2502,44713.68171,625.492037,58921343,15.99456,16.515734,-0.618859,-0.647292,22.521601,0.737136,23.374859,0.469194,0.00469194,-0.671133,-0.201939,-0.00201939,-0.633037
2511,44713.68174,627.742037,58921345,15.952033,16.479378,-0.61758,-0.646043,22.537006,0.739775,23.31522,0.470805,0.00470805,-0.690492,-0.219691,-0.00219691,-0.63177
2520,44713.68176,629.992037,58921348,15.917011,16.438414,-0.616261,-0.644925,22.554548,0.742223,23.263849,0.472815,0.00472815,-0.712328,-0.239531,-0.00239531,-0.630513
2529,44713.68179,632.242037,58921350,15.835765,16.385324,-0.614937,-0.643512,22.573492,0.744817,23.198334,0.474632,0.00474632,-0.736182,-0.261515,-0.00261515,-0.629241
2538,44713.68181,634.492037,58921352,15.736425,16.253502,-0.61382,-0.642657,22.5973,0.746979,23.019351,0.47619,0.0047619,-0.765358,-0.289246,-0.00289246,-0.628206
2547,44713.68184,636.742037,58921354,15.600639,16.121397,-0.612655,-0.641507,22.622287,0.749221,22.834027,0.477737,0.00477737,-0.796277,-0.31854,-0.0031854,-0.62708
2556,44713.68187,638.992037,58921357,15.501253,16.029322,-0.611335,-0.640258,22.64897,0.751703,22.700729,0.479518,0.00479518,-0.829765,-0.350244,-0.00350244,-0.625821
2565,44713.68189,641.242037,58921359,15.29385,15.626366,-0.60995,-0.639567,22.737125,0.753857,22.355045,0.480705,0.00480705,-0.881143,-0.400438,-0.00400438,-0.625015
2574,44713.68192,643.492037,58921361,14.802321,15.328799,-0.608662,-0.638811,22.777002,0.75586,21.686785,0.482216,0.00482216,-0.988855,-0.506639,-0.00506639,-0.624012
2583,44713.68194,645.742037,58921363,14.720102,15.230602,-0.607567,-0.637792,22.796682,0.757928,21.601201,0.484119,0.00484119,-1.013627,-0.529508,-0.00529508,-0.622651
2592,44713.68197,647.992037,58921366,14.635418,15.157822,-0.606445,-0.637102,22.81511,0.760107,21.443049,0.485455,0.00485455,-1.036839,-0.551384,-0.00551384,-0.621592
2601,44713.682,650.242037,58921368,14.594413,15.119204,-0.60523,-0.635787,22.831104,0.762463,21.388281,0.486895,0.00486895,-1.056657,-0.569843,-0.00569843,-0.620657
2610,44713.68202,652.492037,58921370,14.536786,15.084477,-0.604053,-0.634637,22.846731,0.764781,21.358835,0.488766,0.00488766,-1.076382,-0.587644,-0.00587644,-0.619347
2619,44713.68205,654.742037,58921372,14.52239,15.054182,-0.602842,-0.633684,22.86361,0.767124,21.29319,0.490283,0.00490283,-1.096934,-0.606652,-0.00606652,-0.618085
2628,44713.68208,656.992037,58921375,14.459328,15.013466,-0.601718,-0.6325,22.879236,0.769294,21.261642,0.49192,0.0049192,-1.116843,-0.624874,-0.00624874,-0.61714
2637,44713.6821,659.242037,58921377,14.321025,14.8878,-0.601466,-0.632862,22.891472,0.769737,21.051051,0.492078,0.00492078,-1.131982,-0.639962,-0.00639962,-0.616859
2646,44713.68213,661.492037,58921379,13.981345,11.476016,-0.626706,-0.660407,22.879973,0.719621,17.954786,0.467893,0.00467893,-1.129596,-0.661703,-0.00661703,-0.637436
2655,44713.68215,663.742037,58921381,-0.603279,-0.235079,-0.854178,-0.874652,22.639461,0.276747,-0.254467,0.150425,0.00150425,-0.827012,-0.676587,-0.00676587,-0.859637
2664,44713.68218,665.992037,58921384,-0.950973,-0.416818,-1.064838,-1.064838,22.58499,0.001286,-0.590152,-0.147649,-0.00147649,-0.75132,-0.898969,-0.00898969,-1.064838
2672,44713.6822,667.992037,58921386,-0.953971,-0.410551,-1.064838,-1.064838,22.583295,0.001269,-0.578878,-0.147649,-0.00147649,-0.749118,-0.896767,-0.00896767,-1.064838