File: PB18_UCS_2622.csv
Index,Date,Time,Counter,FbLoad,Force(kN),LVDT1,LVDT2,Chain,OutputPower,Stress [MPa],Strain Ax. [%],Strain Ax [-],Strain Rad. [%],Strain Vol. [%],Gemidd
0,44714.40247,0,58983617,0.104858,-0.313498,-0.895743,-0.896544,22.180992,0.210656,-0.442165,0.093765,0.00093765,-0.248177,-0.154595,-0.896143
10,44714.40249,2.428701,58983619,0.094977,-0.311076,-0.896403,-0.896872,22.180992,0.209519,-0.434578,0.094013,0.00094013,-0.248269,-0.154072,-0.896112
20,44714.40252,4.928701,58983621,0.086571,-0.327714,-0.897991,-0.897694,22.180992,0.207146,-0.455997,0.091548,0.00091548,-0.24836,-0.156904,-0.897643
30,44714.40255,7.428701,58983624,0.06931,-0.321792,-0.897515,-0.897366,22.181066,0.207944,-0.464851,0.091364,0.00091364,-0.24836,-0.15694,-0.897489
40,44714.40258,9.928701,58983626,0.062227,-0.324845,-0.897153,-0.896938,22.181066,0.208474,-0.459259,0.091561,0.00091561,-0.248452,-0.156683,-0.897245
50,44714.40261,12.428701,58983629,0.079073,-0.327588,-0.898228,-0.89776,22.180992,0.206835,-0.464936,0.090561,0.00090561,-0.24836,-0.157753,-0.897994
60,44714.40264,14.928701,58983631,0.063294,-0.316078,-0.897483,-0.897398,22.180992,0.208017,-0.448727,0.091508,0.00091508,-0.248085,-0.156485,-0.897346
70,44714.40267,17.428701,58983634,0.068071,-0.319269,-0.897628,-0.8973,22.180992,0.207669,-0.449211,0.091428,0.00091428,-0.248452,-0.157024,-0.897441
80,44714.4027,19.928701,58983636,0.081477,-0.314706,-0.897102,-0.89707,22.181066,0.208656,-0.444805,0.091929,0.00091929,-0.248452,-0.156453,-0.897084
90,44714.40273,22.428701,58983639,0.08476,-0.319515,-0.897368,-0.897037,22.181066,0.2081,-0.45179,0.091713,0.00091713,-0.24836,-0.156647,-0.89736
100,44714.40276,24.928701,58983641,0.077454,-0.320977,-0.897259,-0.897168,22.181066,0.208351,-0.446765,0.091746,0.00091746,-0.24836,-0.156614,-0.897261
110,44714.40278,27.428701,58983644,0.070386,-0.321074,-0.897674,-0.8973,22.181066,0.207716,-0.458758,0.091465,0.00091465,-0.248269,-0.156888,-0.897453
120,44714.40281,29.928701,58983646,0.080386,-0.318469,-0.897511,-0.897398,22.18114,0.208053,-0.4464,0.091568,0.00091568,-0.248269,-0.15663,-0.897337
130,44714.40284,32.428701,58983649,0.06895,-0.307424,-0.895732,-0.896149,22.181066,0.210711,-0.433218,0.093371,0.00093371,-0.248085,-0.154714,-0.896124
140,44714.40287,34.928701,58983651,0.09754,-0.29308,-0.89422,-0.895426,22.18114,0.213227,-0.418518,0.095058,0.00095058,-0.248085,-0.153027,-0.894943
150,44714.4029,37.428701,58983654,0.124498,-0.275189,-0.891982,-0.894309,22.18114,0.216693,-0.385778,0.097554,0.00097554,-0.248269,-0.150752,-0.893195
160,44714.40293,39.928701,58983656,0.137433,-0.264961,-0.890982,-0.89375,22.18114,0.218274,-0.375014,0.098926,0.00098926,-0.248269,-0.149267,-0.892182
170,44714.40296,42.428701,58983659,0.14109,-0.251519,-0.889799,-0.892698,22.18114,0.220354,-0.35101,0.100335,0.00100335,-0.248177,-0.147811,-0.891163
180,44714.40299,44.928701,58983661,0.158673,-0.228617,-0.888385,-0.891317,22.18114,0.223021,-0.325665,0.102249,0.00102249,-0.248085,-0.145854,-0.889823
190,44714.40302,47.428701,58983664,0.180236,-0.20358,-0.887117,-0.889838,22.181066,0.225865,-0.292225,0.104222,0.00104222,-0.248269,-0.143984,-0.888485
200,44714.40304,49.928701,58983666,0.203554,-0.182637,-0.885926,-0.888622,22.181066,0.22823,-0.267434,0.106018,0.00106018,-0.248269,-0.142136,-0.887187
210,44714.40307,52.428701,58983669,0.230113,-0.154387,-0.88456,-0.886913,22.181213,0.231235,-0.217789,0.108101,0.00108101,-0.248177,-0.140099,-0.885776
220,44714.4031,54.928701,58983671,0.264204,-0.137369,-0.883477,-0.885927,22.181066,0.233464,-0.192932,0.10974,0.0010974,-0.248177,-0.138437,-0.88461
230,44714.40313,57.428701,58983674,0.291648,-0.11407,-0.88228,-0.884415,22.18114,0.236189,-0.154714,0.111675,0.00111675,-0.248177,-0.136502,-0.883311
240,44714.40316,59.928701,58983676,0.303935,-0.079944,-0.881041,-0.882804,22.181213,0.23902,-0.116828,0.113609,0.00113609,-0.248269,-0.134608,-0.881921
250,44714.40319,62.428701,58983679,0.326615,-0.062462,-0.879964,-0.881719,22.181213,0.241411,-0.088552,0.115192,0.00115192,-0.24836,-0.133108,-0.880849
260,44714.40322,64.928701,58983681,0.348477,-0.040895,-0.878911,-0.880503,22.18114,0.243586,-0.0517,0.116776,0.00116776,-0.248269,-0.131493,-0.879657
270,44714.40325,67.428701,58983684,0.38187,-0.021323,-0.877878,-0.879156,22.181213,0.24561,-0.029031,0.118264,0.00118264,-0.248269,-0.130005,-0.878699
280,44714.40328,69.928701,58983686,0.401777,0.006385,-0.876877,-0.878169,22.181287,0.247861,0.004305,0.119815,0.00119815,-0.24836,-0.128454,-0.87739
290,44714.4033,72.428701,58983689,0.415594,0.030852,-0.875668,-0.876789,22.181287,0.250206,0.042544,0.121593,0.00121593,-0.248269,-0.126677,-0.876319
300,44714.40333,74.928701,58983691,0.462947,0.06341,-0.87438,-0.87554,22.181361,0.25302,0.090149,0.123593,0.00123593,-0.248452,-0.124858,-0.874968
310,44714.40336,77.428701,58983694,0.498891,0.091377,-0.873182,-0.874258,22.181361,0.25546,0.131184,0.125431,0.00125431,-0.248544,-0.123113,-0.873682
320,44714.40339,79.928701,58983696,0.516659,0.116515,-0.871885,-0.872877,22.181434,0.258195,0.169616,0.127293,0.00127293,-0.248269,-0.120976,-0.872296
330,44714.40342,82.428701,58983699,0.548328,0.153918,-0.870546,-0.871464,22.181434,0.260876,0.220183,0.129325,0.00129325,-0.248636,-0.119293,-0.871082
340,44714.40345,84.928701,58983701,0.581462,0.181127,-0.869351,-0.870412,22.181508,0.263432,0.254742,0.130937,0.00130937,-0.248819,-0.11786,-0.869812
350,44714.40348,87.428701,58983704,0.597964,0.214024,-0.868194,-0.869065,22.181434,0.265719,0.30501,0.132636,0.00132636,-0.248452,-0.115816,-0.868638
360,44714.40351,89.928701,58983706,0.646856,0.242564,-0.866995,-0.867783,22.181508,0.268068,0.346318,0.134311,0.00134311,-0.248819,-0.114508,-0.867363
370,44714.40354,92.428701,58983709,0.664988,0.280697,-0.865771,-0.866731,22.181508,0.270454,0.392965,0.136172,0.00136172,-0.248911,-0.112722,-0.866151
380,44714.40357,94.928701,58983711,0.70449,0.311412,-0.864526,-0.865285,22.181582,0.272894,0.441403,0.137819,0.00137819,-0.248911,-0.111077,-0.865034
390,44714.40359,97.428701,58983714,0.727772,0.337879,-0.863585,-0.864331,22.181582,0.274784,0.475674,0.139119,0.00139119,-0.248636,-0.109517,-0.864101
400,44714.40362,99.928701,58983716,0.78169,0.383661,-0.862097,-0.863115,22.181656,0.2778,0.538163,0.141186,0.00141186,-0.248727,-0.107541,-0.862653
410,44714.40365,102.428701,58983719,0.79986,0.419233,-0.86075,-0.861833,22.181729,0.28035,0.584464,0.143164,0.00143164,-0.249003,-0.10593,-0.861266
420,44714.40368,104.928701,58983721,0.833196,0.441982,-0.859824,-0.860781,22.181803,0.282233,0.62974,0.144383,0.00144383,-0.249186,-0.104793,-0.86044
430,44714.40371,107.428701,58983724,0.87573,0.481314,-0.858357,-0.859269,22.181803,0.284929,0.678599,0.146481,0.00146481,-0.249186,-0.102705,-0.858947
440,44714.40374,109.928701,58983726,0.912723,0.52899,-0.857106,-0.858185,22.181877,0.287441,0.73607,0.14822,0.0014822,-0.249003,-0.100927,-0.85773
450,44714.40377,112.428701,58983729,0.953763,0.55914,-0.855814,-0.857297,22.181877,0.289894,0.791888,0.149878,0.00149878,-0.249278,-0.099341,-0.856451
460,44714.4038,114.928701,58983731,1.000531,0.614089,-0.854383,-0.855949,22.182024,0.292665,0.864205,0.15188,0.0015188,-0.24937,-0.097427,-0.85506
470,44714.40383,117.428701,58983734,1.044654,0.653953,-0.853064,-0.854635,22.182024,0.29512,0.925804,0.153644,0.00153644,-0.249278,-0.095542,-0.853933
480,44714.40385,119.928701,58983736,1.078316,0.696598,-0.851768,-0.853517,22.182098,0.297659,0.976444,0.155456,0.00155456,-0.24937,-0.094,-0.852664
490,44714.40388,122.428701,58983739,1.140659,0.762853,-0.849992,-0.851972,22.182098,0.301063,1.076424,0.157739,0.00157739,-0.249553,-0.091723,-0.850992
500,44714.40391,124.928701,58983741,1.196388,0.809671,-0.848556,-0.85069,22.182172,0.303701,1.143071,0.159671,0.00159671,-0.249645,-0.089974,-0.849684
510,44714.40394,127.428701,58983744,1.239251,0.847271,-0.847278,-0.84954,22.182245,0.306174,1.20012,0.16146,0.0016146,-0.249737,-0.088263,-0.848461
520,44714.40397,129.928701,58983746,1.282396,0.877753,-0.846386,-0.848817,22.182319,0.307729,1.237909,0.162645,0.00162645,-0.249737,-0.087105,-0.847614
530,44714.404,132.428701,58983749,1.329071,0.93291,-0.845105,-0.847601,22.182393,0.310263,1.316405,0.164334,0.00164334,-0.249737,-0.085424,-0.846465
540,44714.40403,134.928701,58983751,1.375521,0.978973,-0.843835,-0.846483,22.18254,0.312618,1.377583,0.166006,0.00166006,-0.250103,-0.083952,-0.84528
550,44714.40406,137.428701,58983754,1.419884,1.031685,-0.842421,-0.845333,22.18254,0.315023,1.454835,0.167907,0.00167907,-0.250195,-0.082288,-0.843984
560,44714.40409,139.928701,58983756,1.471234,1.080384,-0.841065,-0.844281,22.182466,0.317747,1.525999,0.16976,0.0016976,-0.250287,-0.080457,-0.842603
570,44714.40412,142.428701,58983759,1.534028,1.138062,-0.839713,-0.842999,22.18254,0.320226,1.606946,0.171586,0.00171586,-0.250379,-0.078759,-0.84135
580,44714.40414,144.928701,58983761,1.572197,1.184911,-0.838376,-0.842046,22.182614,0.322693,1.678572,0.173365,0.00173365,-0.250195,-0.076808,-0.840112
590,44714.40417,147.428701,58983764,1.6398,1.242882,-0.836943,-0.840731,22.182761,0.325331,1.758209,0.175181,0.00175181,-0.250562,-0.075381,-0.838866
600,44714.4042,149.928701,58983766,1.701463,1.306338,-0.835473,-0.839416,22.182761,0.328085,1.842709,0.177231,0.00177231,-0.250654,-0.073423,-0.837377
610,44714.40423,152.428701,58983769,1.759771,1.35491,-0.834171,-0.838265,22.182835,0.330382,1.917027,0.178901,0.00178901,-0.250562,-0.071749,-0.836202
620,44714.40426,154.928701,58983771,1.798799,1.413319,-0.832896,-0.837214,22.182909,0.332831,2.001154,0.180568,0.00180568,-0.250837,-0.070274,-0.83498
630,44714.40429,157.428701,58983774,1.862962,1.471319,-0.83163,-0.836063,22.182982,0.335045,2.077623,0.182348,0.00182348,-0.250929,-0.068533,-0.833893
640,44714.40432,159.928701,58983776,1.922389,1.527265,-0.830349,-0.834978,22.183056,0.337545,2.156747,0.183984,0.00183984,-0.251021,-0.067082,-0.832561
650,44714.40435,162.428701,58983779,1.985651,1.591179,-0.829019,-0.833828,22.183203,0.34007,2.244603,0.18582,0.0018582,-0.251021,-0.065207,-0.831402
660,44714.40438,164.928701,58983781,2.046211,1.651158,-0.827728,-0.83248,22.183277,0.34243,2.329897,0.187563,0.00187563,-0.251296,-0.063734,-0.830235
670,44714.4044,167.428701,58983784,2.094894,1.711083,-0.826443,-0.831659,22.183425,0.344933,2.414362,0.189271,0.00189271,-0.251388,-0.062117,-0.828994
680,44714.40443,169.928701,58983786,2.17538,1.776845,-0.825053,-0.830114,22.183498,0.347622,2.504662,0.19114,0.0019114,-0.251571,-0.060443,-0.827686
690,44714.40446,172.428701,58983789,2.219158,1.841456,-0.823685,-0.829029,22.183646,0.350128,2.607902,0.193031,0.00193031,-0.251847,-0.058729,-0.826301
700,44714.40449,174.928701,58983791,2.301053,1.911332,-0.822414,-0.827681,22.183793,0.352563,2.696907,0.19469,0.0019469,-0.25203,-0.057326,-0.825191
710,44714.40452,177.428701,58983794,2.347601,1.977116,-0.821175,-0.826564,22.183941,0.354996,2.789077,0.196492,0.00196492,-0.251755,-0.055263,-0.823939
720,44714.40455,179.928701,58983796,2.444376,2.054662,-0.819621,-0.82538,22.184088,0.358049,2.903393,0.198544,0.00198544,-0.251938,-0.053394,-0.822466
730,44714.40458,182.428701,58983799,2.527973,2.142441,-0.81805,-0.823901,22.184235,0.361047,3.01982,0.200678,0.00200678,-0.252305,-0.051687,-0.820987
740,44714.40461,184.928701,58983801,2.568628,2.207714,-0.816785,-0.822587,22.184604,0.363583,3.117922,0.202406,0.00202406,-0.252489,-0.050116,-0.819799
750,44714.40464,187.428701,58983804,2.664628,2.265619,-0.815576,-0.821568,22.184604,0.365877,3.21086,0.204189,0.00204189,-0.252581,-0.048383,-0.818551
760,44714.40466,189.928701,58983806,2.736825,2.338915,-0.814355,-0.820319,22.184751,0.368179,3.304315,0.205922,0.00205922,-0.252581,-0.046659,-0.817338
770,44714.40469,192.428701,58983809,2.796814,2.410889,-0.813182,-0.819267,22.184972,0.370507,3.405006,0.207443,0.00207443,-0.252672,-0.045351,-0.816251
780,44714.40472,194.928701,58983811,2.870342,2.47722,-0.811929,-0.818149,22.184972,0.372993,3.506179,0.209125,0.00209125,-0.253315,-0.044086,-0.815024
790,44714.40475,197.428701,58983814,2.938942,2.549097,-0.810752,-0.816867,22.18512,0.375128,3.599703,0.210838,0.00210838,-0.253315,-0.042477,-0.813897
800,44714.40478,199.928701,58983816,3.022181,2.632292,-0.809468,-0.815487,22.185267,0.377795,3.719728,0.212667,0.00212667,-0.253406,-0.040695,-0.812617
810,44714.40481,202.428701,58983819,3.109277,2.704442,-0.808198,-0.814369,22.185415,0.380346,3.827704,0.214533,0.00214533,-0.253498,-0.039033,-0.81131
820,44714.40484,204.928701,58983821,3.170046,2.772339,-0.807057,-0.813416,22.185636,0.382551,3.920899,0.216044,0.00216044,-0.253682,-0.037707,-0.810153
830,44714.40487,207.428701,58983824,3.234328,2.848372,-0.80591,-0.812331,22.185562,0.384798,4.026485,0.217745,0.00217745,-0.253957,-0.036245,-0.809062
840,44714.4049,209.928701,58983826,3.311439,2.916821,-0.804713,-0.811016,22.18571,0.387084,4.126418,0.219344,0.00219344,-0.25414,-0.03479,-0.807943
850,44714.40493,212.428701,58983829,3.396489,3.006784,-0.803467,-0.8098,22.185783,0.389662,4.250309,0.221143,0.00221143,-0.254416,-0.033185,-0.806622
860,44714.40495,214.928701,58983831,3.483733,3.100543,-0.802035,-0.808387,22.185931,0.392629,4.381474,0.22316,0.0022316,-0.254416,-0.031291,-0.805296
870,44714.40498,217.428701,58983834,3.579225,3.187528,-0.800724,-0.807269,22.186152,0.395102,4.510006,0.225081,0.00225081,-0.254507,-0.029419,-0.803976
880,44714.40501,219.928701,58983836,3.647012,3.258286,-0.79958,-0.806119,22.186373,0.397382,4.608799,0.226639,0.00226639,-0.25515,-0.028511,-0.80285
890,44714.40504,222.428701,58983839,3.728101,3.343343,-0.798417,-0.804935,22.186447,0.399745,4.7257,0.228339,0.00228339,-0.255333,-0.026994,-0.801665
900,44714.40507,224.928701,58983841,3.824563,3.442144,-0.796933,-0.803325,22.186668,0.402412,4.868878,0.230362,0.00230362,-0.255608,-0.025246,-0.80023
910,44714.4051,227.428701,58983844,3.910695,3.532291,-0.795696,-0.80224,22.186963,0.405224,4.994292,0.23214,0.0023214,-0.255517,-0.023462,-0.799045
920,44714.40513,229.928701,58983846,3.995818,3.618294,-0.794449,-0.801024,22.186963,0.407614,5.116589,0.233923,0.00233923,-0.250195,-0.016272,-0.797767
930,44714.40516,232.428701,58983849,4.094713,3.69894,-0.793312,-0.799808,22.085613,0.409761,5.224011,0.235478,0.00235478,-0.256801,-0.021323,-0.796677
940,44714.40519,234.928701,58983851,4.18078,3.789999,-0.792086,-0.798657,22.175906,0.412242,5.357032,0.237207,0.00237207,-0.256159,-0.01899,-0.795379
950,44714.40521,237.428701,58983854,4.28543,3.89035,-0.79068,-0.797145,22.187626,0.414909,5.496645,0.239258,0.00239258,-0.256526,-0.017262,-0.794025
960,44714.40524,239.928701,58983856,4.364093,3.984488,-0.789406,-0.795896,22.187552,0.417633,5.631406,0.241132,0.00241132,-0.256618,-0.015485,-0.792691
970,44714.40527,242.428701,58983859,4.450696,4.068006,-0.788244,-0.794779,22.188068,0.41986,5.752169,0.24274,0.0024274,-0.25726,-0.014566,-0.791598
980,44714.4053,244.928701,58983861,4.548966,4.183885,-0.786781,-0.793267,22.188437,0.422865,5.903064,0.244747,0.00244747,-0.257443,-0.012645,-0.790079
990,44714.40533,247.428701,58983864,4.663497,4.28236,-0.785424,-0.792083,22.188658,0.425651,6.057805,0.246731,0.00246731,-0.257902,-0.011247,-0.788772
1000,44714.40536,249.928701,58983866,4.759875,4.371217,-0.784203,-0.7909,22.189026,0.427845,6.17986,0.248408,0.00248408,-0.258086,-0.009735,-0.787598
1010,44714.40539,252.428701,58983869,4.848841,4.464466,-0.783071,-0.789815,22.189469,0.43029,6.31241,0.250018,0.00250018,-0.258544,-0.008411,-0.786391
1020,44714.40542,254.928701,58983871,4.933476,4.549129,-0.781934,-0.788599,22.189395,0.43239,6.434334,0.251737,0.00251737,-0.258453,-0.006665,-0.785232
1030,44714.40545,257.428701,58983874,5.034341,4.637553,-0.780775,-0.787482,22.189764,0.434885,6.565629,0.253314,0.00253314,-0.259095,-0.005698,-0.784106
1040,44714.40548,259.928701,58983876,5.109025,4.74126,-0.779505,-0.786167,22.189911,0.437341,6.706976,0.255111,0.00255111,-0.259095,-0.003983,-0.782901
1050,44714.4055,262.428701,58983879,5.22453,4.851409,-0.778168,-0.784852,22.190279,0.440104,6.855844,0.257035,0.00257035,-0.259462,-0.002427,-0.781559
1060,44714.40553,264.928701,58983881,5.333329,4.957987,-0.776863,-0.783504,22.190353,0.442647,7.005899,0.258952,0.00258952,-0.259737,-0.000785,-0.78019
1070,44714.40556,267.428701,58983884,5.468672,5.089137,-0.775271,-0.781927,22.191164,0.445967,7.188488,0.261125,0.00261125,-0.25992,0.001338,-0.778538
1080,44714.40559,269.928701,58983886,5.560446,5.174735,-0.774142,-0.780875,22.191754,0.44817,7.312064,0.262851,0.00262851,-0.260196,0.002542,-0.777484
1090,44714.40562,272.428701,58983889,5.653099,5.26439,-0.77303,-0.779757,22.191459,0.450396,7.43958,0.264335,0.00264335,-0.261021,0.003298,-0.77646
1100,44714.40565,274.928701,58983891,5.729098,5.35919,-0.771928,-0.778837,22.191017,0.452768,7.576664,0.266075,0.00266075,-0.260563,0.005388,-0.775191
1110,44714.40568,277.428701,58983894,5.829648,5.456976,-0.770723,-0.777522,22.191459,0.455168,7.711181,0.267668,0.00267668,-0.260654,0.007128,-0.774036
1120,44714.40571,279.928701,58983896,5.944798,5.56004,-0.769526,-0.776141,22.191311,0.457465,7.859529,0.269335,0.00269335,-0.262489,0.006891,-0.772949
1130,44714.40574,282.428701,58983899,6.034329,5.649947,-0.768335,-0.774892,22.192048,0.459718,7.990034,0.271031,0.00271031,-0.262765,0.008233,-0.771691
1140,44714.40576,284.928701,58983901,6.188255,5.807337,-0.766623,-0.773446,22.191901,0.463286,8.210394,0.273581,0.00273581,-0.260012,0.013569,-0.769901
1150,44714.40579,287.428701,58983904,6.290113,5.910199,-0.765326,-0.772033,22.193007,0.465878,8.360532,0.275378,0.00275378,-0.262856,0.01259,-0.768735
1160,44714.40582,289.928701,58983906,6.375597,6.0012,-0.764222,-0.770882,22.193007,0.468039,8.489774,0.276965,0.00276965,-0.263315,0.013649,-0.767608
1170,44714.40585,292.428701,58983909,6.47997,6.101298,-0.76306,-0.76983,22.193228,0.470368,8.630741,0.278658,0.00278658,-0.263866,0.014792,-0.766443
1180,44714.40588,294.928701,58983911,6.585161,6.200119,-0.761965,-0.768779,22.19308,0.472412,8.76584,0.28033,0.0028033,-0.264141,0.016113,-0.765253
1190,44714.40591,297.428701,58983914,6.688495,6.302398,-0.760814,-0.767365,22.193818,0.474958,8.907115,0.281914,0.00281914,-0.264508,0.017406,-0.764173
1200,44714.40594,299.928701,58983916,6.780809,6.401735,-0.759628,-0.766346,22.150845,0.477092,9.056989,0.28367,0.0028367,-0.238635,0.044997,-0.762891
1210,44714.40597,302.428701,58983919,6.876946,6.508113,-0.758396,-0.765196,22.082738,0.479577,9.204773,0.285386,0.00285386,-0.199367,0.086033,-0.761754
1220,44714.406,304.928701,58983921,7.013448,6.64547,-0.756886,-0.763355,22.194555,0.482503,9.390373,0.287463,0.00287463,-0.26515,0.022335,-0.760244
1230,44714.40602,307.428701,58983924,7.13399,6.765511,-0.755588,-0.76204,22.162934,0.485276,9.559456,0.289339,0.00289339,-0.266068,0.023228,-0.758823
1240,44714.40605,309.928701,58983926,7.241021,6.86462,-0.754389,-0.761251,22.195734,0.487685,9.705874,0.291001,0.00291001,-0.26671,0.024292,-0.757816
1250,44714.40608,312.428701,58983929,7.343619,6.963878,-0.753226,-0.760035,22.195808,0.489847,9.849452,0.292777,0.00292777,-0.266802,0.025913,-0.756485
1260,44714.40611,314.928701,58983931,7.450194,7.070989,-0.752048,-0.758786,22.196545,0.492395,9.993816,0.294445,0.00294445,-0.267536,0.0268,-0.755372
1270,44714.40614,317.428701,58983934,7.552451,7.177249,-0.750825,-0.757701,22.19684,0.494717,10.148795,0.296111,0.00296111,-0.267719,0.028392,-0.754244
1280,44714.40617,319.928701,58983936,7.661117,7.296101,-0.749568,-0.756157,22.197134,0.497165,10.31207,0.297951,0.00297951,-0.268178,0.029773,-0.752918
1290,44714.4062,322.428701,58983939,7.785442,7.409718,-0.748183,-0.754809,22.197503,0.499978,10.476748,0.299862,0.00299862,-0.268728,0.031087,-0.751646
1300,44714.40623,324.928701,58983941,7.905817,7.533512,-0.746925,-0.753626,22.197945,0.502424,10.644629,0.30161,0.0030161,-0.269279,0.032331,-0.750241
1310,44714.40626,327.428701,58983944,8.022592,7.62985,-0.745751,-0.752738,22.198314,0.504747,10.785505,0.303213,0.00303213,-0.269554,0.033616,-0.749174
1320,44714.40629,329.928701,58983946,8.109687,7.747077,-0.74455,-0.751325,22.200009,0.507197,10.945782,0.304965,0.00304965,-0.270196,0.034897,-0.748029
1330,44714.40631,332.428701,58983949,8.24918,7.871101,-0.743198,-0.749944,22.199198,0.509966,11.132103,0.306984,0.00306984,-0.27093,0.036054,-0.746618
1340,44714.40634,334.928701,58983951,8.365882,7.979841,-0.741979,-0.748859,22.199935,0.512378,11.287079,0.308733,0.00308733,-0.271022,0.037679,-0.745393
1350,44714.40637,337.428701,58983954,8.469237,8.085787,-0.740827,-0.747709,22.200451,0.514542,11.439127,0.310418,0.00310418,-0.271297,0.039121,-0.744191
1360,44714.4064,339.928701,58983956,8.600374,8.218724,-0.739466,-0.746263,22.200525,0.517259,11.619599,0.312229,0.00312229,-0.272398,0.039933,-0.742852
1370,44714.40643,342.428701,58983959,8.716275,8.353669,-0.738061,-0.744652,22.201115,0.520081,11.812453,0.314347,0.00314347,-0.273316,0.040988,-0.741471
1380,44714.40646,344.928701,58983961,8.834105,8.462632,-0.736836,-0.743469,22.24217,0.52245,11.970317,0.31606,0.0031606,-0.148356,0.167713,-0.740318
1390,44714.40649,347.428701,58983964,8.950527,8.562823,-0.73572,-0.742581,22.249099,0.524789,12.114478,0.317575,0.00317575,-0.13597,0.181441,-0.739181
1400,44714.40652,349.928701,58983966,9.038582,8.675985,-0.73454,-0.741464,22.232957,0.527069,12.260732,0.319373,0.00319373,-0.212946,0.106477,-0.737888
1410,44714.40655,352.428701,58983969,9.143312,8.787734,-0.733336,-0.740083,22.198756,0.529537,12.414063,0.320986,0.00320986,-0.264691,0.056327,-0.736793
1420,44714.40657,354.928701,58983971,9.308667,8.932837,-0.731857,-0.738637,22.201999,0.532632,12.634524,0.323038,0.00323038,-0.272306,0.050782,-0.735322
1430,44714.4066,357.428701,58983974,9.425,9.04417,-0.730643,-0.737322,22.203473,0.534976,12.787677,0.324941,0.00324941,-0.276619,0.048166,-0.734018
1440,44714.40663,359.928701,58983976,9.527048,9.149917,-0.729529,-0.736468,22.203768,0.53718,12.935073,0.326525,0.00326525,-0.276802,0.049723,-0.73283
1450,44714.40666,362.428701,58983979,9.626127,9.256372,-0.728396,-0.735219,22.204505,0.53945,13.085583,0.328148,0.00328148,-0.277536,0.050585,-0.731776
1460,44714.40669,364.928701,58983981,9.775523,9.411176,-0.726913,-0.733805,22.204948,0.54231,13.309997,0.330308,0.00330308,-0.278453,0.051857,-0.730266
1470,44714.40672,367.428701,58983984,9.890101,9.521558,-0.725698,-0.732556,22.205685,0.54479,13.466415,0.331877,0.00331877,-0.279096,0.052707,-0.72917
1480,44714.40675,369.928701,58983986,10.000836,9.623861,-0.724619,-0.731438,22.206348,0.546968,13.611993,0.333524,0.00333524,-0.279463,0.054062,-0.728017
1490,44714.40678,372.428701,58983989,10.115944,9.730346,-0.723482,-0.730124,22.206569,0.549332,13.759156,0.335042,0.00335042,-0.28038,0.054788,-0.726963
1500,44714.40681,374.928701,58983991,10.255839,9.877106,-0.722005,-0.728743,22.207085,0.552218,13.962275,0.337213,0.00337213,-0.281022,0.05609,-0.725434
1510,44714.40683,377.428701,58983994,10.364641,9.993452,-0.720802,-0.727626,22.207896,0.554744,14.12907,0.33889,0.0033889,-0.281756,0.057143,-0.724281
1520,44714.40686,379.928701,58983996,10.459503,10.102074,-0.719676,-0.726475,22.208412,0.557042,14.286039,0.340522,0.00340522,-0.282674,0.057852,-0.723118
1530,44714.40689,382.428701,58983999,10.624435,10.242239,-0.718343,-0.725127,22.209002,0.559826,14.488701,0.342426,0.00342426,-0.282857,0.059559,-0.721698
1540,44714.40692,384.928701,58984001,10.749532,10.363124,-0.716985,-0.72378,22.209591,0.562299,14.653515,0.344401,0.00344401,-0.283683,0.06064,-0.720347
1550,44714.40695,387.428701,58984004,10.873578,10.482678,-0.715799,-0.722465,22.210402,0.564724,14.818494,0.34612,0.0034612,-0.284417,0.06169,-0.719199
1560,44714.40698,389.928701,58984006,10.95832,10.588052,-0.71465,-0.721249,22.211065,0.567143,14.977658,0.347747,0.00347747,-0.285793,0.061981,-0.71806
1570,44714.40701,392.428701,58984009,11.085549,10.710558,-0.713425,-0.720066,22.184014,0.569573,15.145013,0.349583,0.00349583,-0.288729,0.06087,-0.716764
1580,44714.40704,394.928701,58984011,11.211716,10.850963,-0.712058,-0.718784,22.187331,0.572315,15.349638,0.351402,0.00351402,-0.229736,0.121729,-0.715502
1590,44714.40707,397.428701,58984014,11.344251,10.984096,-0.710755,-0.717469,22.202368,0.574869,15.522846,0.353244,0.00353244,-0.233405,0.119819,-0.714183
1600,44714.4071,399.928701,58984016,11.468065,11.086681,-0.709612,-0.716384,22.206717,0.577187,15.684377,0.354968,0.00354968,-0.279554,0.075251,-0.712995
1610,44714.40712,402.428701,58984019,11.571133,11.199546,-0.708449,-0.715201,22.213424,0.579448,15.838695,0.356666,0.00356666,-0.275242,0.081438,-0.711818
1620,44714.40715,404.928701,58984021,11.679643,11.317003,-0.707296,-0.714116,22.212982,0.581786,16.004916,0.358329,0.00358329,-0.261664,0.096684,-0.71064
1630,44714.40718,407.428701,58984024,11.830251,11.46558,-0.705846,-0.712571,22.217994,0.584797,16.212962,0.360328,0.00360328,-0.260746,0.099582,-0.709222
1640,44714.40721,409.928701,58984026,11.959519,11.59332,-0.704547,-0.711289,22.220058,0.587282,16.393565,0.36211,0.0036211,-0.265425,0.09684,-0.708014
1650,44714.40724,412.428701,58984029,12.074145,11.6988,-0.703352,-0.71004,22.223301,0.589647,16.549709,0.363968,0.00363968,-0.25148,0.112488,-0.706706
1660,44714.40727,414.928701,58984031,12.175356,11.81198,-0.70222,-0.708791,22.22109,0.592176,16.702036,0.365584,0.00365584,-0.246709,0.118884,-0.705575
1670,44714.4073,417.428701,58984034,12.299706,11.927332,-0.70103,-0.707542,22.2205,0.59448,16.872455,0.367323,0.00367323,-0.251938,0.115389,-0.704361
1680,44714.40733,419.928701,58984036,12.427343,12.055923,-0.699765,-0.706523,22.214972,0.597148,17.044864,0.369134,0.00369134,-0.283591,0.085546,-0.70309
1690,44714.40736,422.428701,58984039,12.56249,12.185531,-0.698431,-0.70511,22.221532,0.599866,17.234033,0.371011,0.00371011,-0.298179,0.07291,-0.701776
1700,44714.40738,424.928701,58984041,12.660433,12.28879,-0.697302,-0.703828,22.221679,0.601858,17.383011,0.372717,0.00372717,-0.298638,0.074079,-0.7005
1710,44714.40741,427.428701,58984044,12.79169,12.423615,-0.695991,-0.70248,22.222564,0.60471,17.574194,0.374497,0.00374497,-0.29928,0.075143,-0.699269
1720,44714.40744,429.928701,58984046,12.90959,12.538096,-0.694841,-0.701363,22.223375,0.606779,17.72744,0.376149,0.00376149,-0.300565,0.075584,-0.698179
1730,44714.40747,432.428701,58984049,12.995325,12.647102,-0.693649,-0.700245,22.224112,0.609227,17.880774,0.377901,0.00377901,-0.301666,0.076243,-0.696948
1740,44714.4075,434.928701,58984051,13.153197,12.787061,-0.692269,-0.698832,22.225144,0.611983,18.079712,0.37983,0.0037983,-0.302767,0.077017,-0.695635
1750,44714.40753,437.428701,58984054,13.28148,12.913243,-0.690932,-0.697517,22.225807,0.614752,18.264204,0.381789,0.00381789,-0.304235,0.077548,-0.694118
1760,44714.40756,439.928701,58984056,13.383876,13.013873,-0.689792,-0.696301,22.226913,0.617128,18.410127,0.383482,0.00383482,-0.305335,0.078162,-0.693068
1770,44714.40759,442.428701,58984059,13.489389,13.130571,-0.688617,-0.695216,22.227871,0.61935,18.567144,0.385121,0.00385121,-0.30662,0.078501,-0.691914
1780,44714.40762,444.928701,58984061,13.602515,13.244413,-0.687411,-0.694,22.228682,0.621844,18.733068,0.386886,0.00386886,-0.307813,0.079074,-0.690663
1790,44714.40765,447.428701,58984064,13.71671,13.349546,-0.686239,-0.692751,22.229861,0.624211,18.882023,0.388486,0.00388486,-0.309005,0.079586,-0.68947
1800,44714.40767,449.928701,58984066,13.827343,13.461679,-0.685044,-0.691633,22.230967,0.626607,19.040693,0.390275,0.00390275,-0.310198,0.080037,-0.688347
1810,44714.4077,452.428701,58984069,13.987974,13.637589,-0.683362,-0.68976,22.232293,0.629844,19.281135,0.392676,0.00392676,-0.311758,0.080878,-0.686638
1820,44714.40773,454.928701,58984071,14.100879,13.740888,-0.682089,-0.688346,22.23362,0.632425,19.437094,0.394431,0.00394431,-0.313501,0.081136,-0.685238
1830,44714.40776,457.428701,58984074,14.197816,13.838353,-0.68094,-0.68713,22.234652,0.634852,19.579275,0.396255,0.00396255,-0.315244,0.080974,-0.684066
1840,44714.40779,459.928701,58984076,14.316181,13.953944,-0.679767,-0.686144,22.236053,0.637225,19.7322,0.397889,0.00397889,-0.31607,0.08183,-0.683008
1850,44714.40782,462.428701,58984079,14.405817,14.052326,-0.678646,-0.685059,22.237232,0.639532,19.873606,0.399464,0.00399464,-0.31763,0.081842,-0.681869
1860,44714.40785,464.928701,58984081,14.545608,14.193327,-0.677249,-0.683646,22.238411,0.642177,20.069647,0.40146,0.0040146,-0.319556,0.081754,-0.680462
1870,44714.40788,467.428701,58984084,14.745235,14.38495,-0.675409,-0.681838,22.239959,0.645886,20.338123,0.404108,0.00404108,-0.32185,0.082258,-0.678608
1880,44714.40791,469.928701,58984086,14.843671,14.482085,-0.674135,-0.680424,22.241802,0.648584,20.484015,0.406022,0.00406022,-0.323226,0.082687,-0.677204
1890,44714.40793,472.428701,58984089,14.900411,14.539546,-0.673211,-0.679636,22.242908,0.650369,20.568321,0.40737,0.0040737,-0.325061,0.082221,-0.676386
1900,44714.40796,474.928701,58984091,14.991192,14.621437,-0.672249,-0.678551,22.244308,0.652262,20.681914,0.408732,0.00408732,-0.326896,0.081889,-0.675371
1910,44714.40799,477.428701,58984094,15.069039,14.712167,-0.671176,-0.677236,22.245635,0.654378,20.809299,0.410227,0.00410227,-0.328456,0.081771,-0.674327
1920,44714.40802,479.928701,58984096,15.186548,14.82818,-0.669971,-0.676217,22.246962,0.656779,20.96927,0.411973,0.00411973,-0.330107,0.081882,-0.673121
1930,44714.40805,482.428701,58984099,15.277374,14.923612,-0.668818,-0.6751,22.248509,0.659222,21.118413,0.413628,0.00413628,-0.332217,0.081411,-0.671937
1940,44714.40808,484.928701,58984101,15.357665,15.023222,-0.667702,-0.673949,22.250057,0.661492,21.24924,0.415296,0.00415296,-0.333777,0.081488,-0.670798
1950,44714.40811,487.428701,58984104,15.4797,15.123449,-0.666487,-0.672601,22.264283,0.66378,21.398313,0.417,0.00417,-0.278912,0.137993,-0.669543
1960,44714.40814,489.928701,58984106,15.581609,15.227952,-0.665303,-0.671352,22.246667,0.66626,21.536526,0.418707,0.00418707,-0.340658,0.078017,-0.668389
1970,44714.40817,492.428701,58984109,15.703572,15.33854,-0.663996,-0.670136,22.230524,0.66892,21.694417,0.420564,0.00420564,-0.262856,0.157708,-0.667034
1980,44714.40819,494.928701,58984111,15.791222,15.430171,-0.662859,-0.668887,22.256617,0.671238,21.828075,0.422223,0.00422223,-0.342401,0.079786,-0.665928
1990,44714.40822,497.428701,58984114,15.875777,15.514942,-0.661724,-0.667802,22.258608,0.673586,21.947258,0.423893,0.00423893,-0.344603,0.079273,-0.664758
2000,44714.40825,499.928701,58984116,15.977985,15.639297,-0.660374,-0.666455,22.260524,0.676427,22.115628,0.42567,0.0042567,-0.347172,0.078497,-0.663438
2010,44714.40828,502.428701,58984119,16.107446,15.75628,-0.659036,-0.66491,22.261482,0.679146,22.29183,0.427883,0.00427883,-0.346714,0.081287,-0.661883
2020,44714.40831,504.928701,58984121,16.193599,15.837713,-0.657925,-0.663694,22.26244,0.68158,22.397867,0.429637,0.00429637,-0.34965,0.079998,-0.66073
2030,44714.40834,507.428701,58984124,16.274564,15.914355,-0.656705,-0.662642,22.265684,0.683816,22.510851,0.431104,0.00431104,-0.355613,0.075365,-0.65969
2040,44714.40837,509.928701,58984126,16.365577,15.997229,-0.655577,-0.661294,22.267895,0.686125,22.628199,0.432806,0.00432806,-0.358824,0.073982,-0.658463
2050,44714.4084,512.428701,58984129,16.451996,16.11701,-0.654212,-0.659947,22.270991,0.689006,22.791175,0.434812,0.00434812,-0.359008,0.075765,-0.657037
2060,44714.40843,514.928701,58984131,16.567951,16.226101,-0.65279,-0.658533,22.274234,0.691858,22.946523,0.436875,0.00436875,-0.362586,0.074289,-0.655671
2070,44714.40846,517.428701,58984134,16.654677,16.299789,-0.651606,-0.657284,22.278067,0.69412,23.057636,0.438659,0.00438659,-0.368274,0.070389,-0.654419
2080,44714.40848,519.928701,58984136,16.724855,16.37141,-0.650458,-0.656035,22.28072,0.696624,23.16054,0.440285,0.00440285,-0.371944,0.068322,-0.653284
2090,44714.40851,522.428701,58984139,16.793761,16.446106,-0.649366,-0.654983,22.2833,0.698824,23.258914,0.441891,0.00441891,-0.375064,0.06689,-0.652116
2100,44714.40854,524.928701,58984141,16.856228,16.521817,-0.648231,-0.6538,22.286248,0.701254,23.36793,0.443492,0.00443492,-0.378458,0.065033,-0.651074
2110,44714.40857,527.428701,58984144,16.942604,16.606623,-0.646958,-0.652419,22.289049,0.703718,23.494541,0.445273,0.00445273,-0.382862,0.062386,-0.64981
2120,44714.4086,529.928701,58984146,17.012773,16.675173,-0.645852,-0.651203,22.29244,0.706034,23.590063,0.447002,0.00447002,-0.386807,0.060194,-0.648571
2130,44714.40863,532.428701,58984149,17.087072,16.753314,-0.644655,-0.650118,22.295904,0.708544,23.69243,0.448715,0.00448715,-0.390936,0.057823,-0.647412
2140,44714.40866,534.928701,58984151,17.152013,16.82725,-0.643416,-0.648475,22.299295,0.711057,23.796027,0.450584,0.00450584,-0.395248,0.055243,-0.646075
2150,44714.40869,537.428701,58984154,17.27074,16.928009,-0.641952,-0.647094,22.303496,0.713945,23.945418,0.4528,0.004528,-0.400569,0.052235,-0.64452
2160,44714.40872,539.928701,58984156,17.33936,16.999211,-0.640641,-0.645714,22.307992,0.716845,24.038905,0.454616,0.00454616,-0.405891,0.048627,-0.643249
2170,44714.40874,542.428701,58984159,17.392593,17.045195,-0.639486,-0.644531,22.312341,0.719241,24.114793,0.456445,0.00456445,-0.410937,0.04548,-0.641969
2180,44714.40877,544.928701,58984161,17.429504,17.09359,-0.638386,-0.643249,22.316395,0.721709,24.178956,0.458097,0.00458097,-0.416809,0.041288,-0.640846
2190,44714.4088,547.428701,58984164,17.466416,17.139603,-0.637281,-0.641967,22.32067,0.724097,24.246739,0.459781,0.00459781,-0.42213,0.037559,-0.639727
2200,44714.40883,549.928701,58984166,17.521773,17.190685,-0.636186,-0.640619,22.325388,0.726283,24.317699,0.46151,0.0046151,-0.427727,0.033783,-0.638427
2210,44714.40886,552.428701,58984169,17.605268,17.254515,-0.634989,-0.639337,22.330031,0.728797,24.40583,0.463242,0.00463242,-0.433415,0.029923,-0.637147
2220,44714.40889,554.928701,58984171,17.623998,17.300059,-0.633805,-0.638088,22.33497,0.731215,24.470262,0.464863,0.00464863,-0.439195,0.0259,-0.635917
2230,44714.40892,557.428701,58984174,17.691295,17.351853,-0.632612,-0.63674,22.340351,0.733795,24.549027,0.466737,0.00466737,-0.446076,0.020661,-0.634718
2240,44714.40895,559.928701,58984176,17.71972,17.38383,-0.631471,-0.635623,22.34551,0.736015,24.592697,0.468414,0.00468414,-0.45259,0.015824,-0.633524
2250,44714.40898,562.428701,58984179,17.772282,17.440493,-0.630269,-0.634308,22.376615,0.738737,24.672897,0.470265,0.00470265,-0.38644,0.083913,-0.632237
2260,44714.40901,564.928701,58984181,17.791278,17.471502,-0.629085,-0.63296,22.357525,0.741206,24.715505,0.472029,0.00472029,-0.468279,0.003823,-0.631063
2270,44714.40903,567.428701,58984184,17.825253,17.503129,-0.627906,-0.63158,22.363643,0.743629,24.76379,0.47382,0.0047382,-0.475068,-0.001251,-0.629811
2280,44714.40906,569.928701,58984186,17.891317,17.566942,-0.626475,-0.630298,22.370645,0.74671,24.848755,0.476023,0.00476023,-0.484243,-0.008389,-0.628182
2290,44714.40909,572.428701,58984189,17.885048,17.554856,-0.62543,-0.628885,22.37293,0.748836,24.842788,0.477494,0.00477494,-0.473509,0.004047,-0.627243
2300,44714.40912,574.928701,58984191,17.896595,17.570091,-0.62433,-0.627603,22.387598,0.751028,24.85906,0.479223,0.00479223,-0.312308,0.166668,-0.626006
2310,44714.40915,577.428701,58984194,17.938057,17.601526,-0.623153,-0.626255,22.317132,0.753753,24.895139,0.480851,0.00480851,-0.477179,0.003672,-0.62478
2320,44714.40918,579.928701,58984196,17.95075,17.628574,-0.621896,-0.625006,22.344773,0.756237,24.939312,0.482883,0.00482883,-0.442131,0.04081,-0.623425
2330,44714.40921,582.428701,58984199,17.945846,17.636117,-0.620758,-0.623593,22.302833,0.758631,24.949982,0.484596,0.00484596,-0.460114,0.024496,-0.622267
2340,44714.40924,584.928701,58984201,17.968952,17.650442,-0.619587,-0.622179,22.304528,0.761425,24.967335,0.486375,0.00486375,-0.562137,-0.075761,-0.621043
2350,44714.40927,587.428701,58984204,17.981635,17.652532,-0.618384,-0.62093,22.381849,0.764036,24.981783,0.488252,0.00488252,-0.50562,-0.017364,-0.619707
2360,44714.40929,589.928701,58984206,17.949424,17.645913,-0.617231,-0.619747,22.390915,0.766404,24.961779,0.490123,0.00490123,-0.514428,-0.024305,-0.618397
2370,44714.40932,592.428701,58984209,17.948743,17.630511,-0.616094,-0.618136,22.408458,0.768958,24.937866,0.491789,0.00491789,-0.570945,-0.079156,-0.617218
2380,44714.40935,594.928701,58984211,17.912756,17.621299,-0.614962,-0.616756,22.424673,0.771594,24.924958,0.493611,0.00493611,-0.587551,-0.093939,-0.615895
2390,44714.40938,597.428701,58984214,17.904204,17.605,-0.613823,-0.615474,22.435435,0.774127,24.909979,0.495311,0.00495311,-0.598744,-0.103433,-0.614663
2400,44714.40941,599.928701,58984216,17.884124,17.590367,-0.612679,-0.614027,22.458137,0.776527,24.888425,0.497283,0.00497283,-0.578284,-0.081002,-0.613386
2410,44714.40944,602.428701,58984219,17.869134,17.576629,-0.611544,-0.612614,22.46971,0.779182,24.870032,0.498909,0.00498909,-0.594799,-0.095864,-0.612229
2420,44714.40947,604.928701,58984221,17.868442,17.556826,-0.610388,-0.611201,22.490422,0.781717,24.844257,0.500818,0.00500818,-0.616727,-0.115908,-0.610931
2430,44714.4095,607.428701,58984224,17.843233,17.541674,-0.609224,-0.609623,22.508038,0.784392,24.82174,0.502796,0.00502796,-0.64003,-0.137234,-0.609526
2440,44714.40953,609.928701,58984226,17.813589,17.511896,-0.608057,-0.608341,22.528161,0.786887,24.778253,0.504688,0.00504688,-0.658747,-0.154047,-0.608202
2450,44714.40955,612.428701,58984229,17.790235,17.468519,-0.606906,-0.60673,22.547694,0.789552,24.71493,0.506412,0.00506412,-0.681225,-0.174813,-0.606995
2460,44714.40958,614.928701,58984231,17.729654,17.437594,-0.605824,-0.605251,22.560961,0.792076,24.665237,0.508308,0.00508308,-0.685904,-0.177619,-0.605547
2470,44714.40961,617.428701,58984234,17.693985,17.402511,-0.604712,-0.603838,22.575482,0.794624,24.61766,0.510097,0.00510097,-0.707281,-0.197059,-0.604415
2480,44714.40964,619.928701,58984236,17.653741,17.371655,-0.603585,-0.602523,22.591919,0.79727,24.573356,0.511872,0.00511872,-0.756091,-0.244108,-0.603175
2490,44714.40967,622.428701,58984239,17.631388,17.33496,-0.602466,-0.601274,22.605776,0.799682,24.527832,0.513678,0.00513678,-0.744164,-0.230486,-0.601816
2500,44714.4097,624.928701,58984241,17.578948,17.302276,-0.601313,-0.599762,22.62354,0.802514,24.475866,0.515597,0.00515597,-0.76655,-0.250828,-0.600478
2510,44714.40973,627.428701,58984244,17.552099,17.266225,-0.600148,-0.598217,22.631279,0.804991,24.427624,0.517384,0.00517384,-0.829306,-0.311958,-0.599255
2520,44714.40976,629.928701,58984246,17.516794,17.22439,-0.598998,-0.597001,22.65295,0.807613,24.372237,0.519328,0.00519328,-0.814443,-0.295228,-0.597954
2530,44714.40979,632.428701,58984249,17.461989,17.17917,-0.59782,-0.595489,22.674915,0.810155,24.304053,0.521156,0.00521156,-0.838848,-0.317564,-0.596585
2540,44714.40982,634.928701,58984251,17.415201,17.132472,-0.596667,-0.593812,22.698944,0.812849,24.23907,0.523169,0.00523169,-0.870317,-0.347135,-0.595256
2550,44714.40984,637.428701,58984254,17.379569,17.08564,-0.595465,-0.592268,22.722973,0.815421,24.173635,0.525041,0.00525041,-0.942981,-0.41794,-0.593935
2560,44714.40987,639.928701,58984256,17.315832,17.033588,-0.594267,-0.591051,22.74774,0.818016,24.096676,0.526872,0.00526872,-0.974634,-0.447762,-0.592673
2570,44714.4099,642.428701,58984259,17.237096,16.972016,-0.593068,-0.589474,22.803464,0.820832,24.016837,0.528608,0.00528608,-1.021334,-0.492761,-0.591288
2580,44714.40993,644.928701,58984261,17.162066,16.89231,-0.591933,-0.58829,22.837443,0.823226,23.895079,0.53051,0.0053051,-1.063538,-0.533027,-0.590174
2590,44714.40996,647.428701,58984264,17.042035,16.776996,-0.590762,-0.58668,22.889482,0.826031,23.736401,0.532551,0.00532551,-1.128679,-0.596286,-0.588698
2600,44714.40999,649.928701,58984266,16.927105,16.65442,-0.589556,-0.585431,22.939236,0.828648,23.573308,0.534288,0.00534288,-1.190975,-0.656649,-0.587491
2610,44714.41002,652.428701,58984269,16.808672,16.539849,-0.588387,-0.583623,22.997392,0.83126,23.408542,0.536272,0.00536272,-1.263181,-0.726858,-0.586057
2620,44714.41005,654.928701,58984271,16.637575,16.356873,-0.588176,-0.583327,23.025475,0.831881,23.147452,0.536661,0.00536661,-1.298963,-0.762205,-0.585753
2630,44714.41008,657.428701,58984274,16.598871,16.318422,-0.587384,-0.582735,23.044345,0.833555,23.087469,0.537792,0.00537792,-1.321716,-0.783915,-0.585029
2640,44714.4101,659.928701,58984276,16.574885,16.319956,-0.586166,-0.58119,23.072207,0.836133,23.084164,0.539671,0.00539671,-1.35603,-0.816359,-0.583681
2650,44714.41013,662.428701,58984279,16.554903,16.295127,-0.584908,-0.579711,23.097342,0.838865,23.050038,0.541686,0.00541686,-1.388417,-0.846769,-0.582304
2660,44714.41016,664.928701,58984281,16.513584,16.247984,-0.583576,-0.578166,23.123213,0.84179,22.986233,0.543515,0.00543515,-1.42062,-0.877122,-0.581023
2670,44714.41019,667.428701,58984284,16.432058,16.181589,-0.582332,-0.576819,23.149601,0.844398,22.891209,0.545416,0.00545416,-1.453099,-0.907684,-0.579676
2680,44714.41022,669.928701,58984286,16.364259,16.113641,-0.581096,-0.57557,23.176579,0.847041,22.80125,0.54743,0.0054743,-1.486404,-0.938974,-0.578359
2690,44714.41025,672.428701,58984289,16.301642,16.052735,-0.579849,-0.574058,23.202156,0.849725,22.719995,0.549284,0.00549284,-1.518515,-0.96914,-0.576921
2700,44714.41028,674.928701,58984291,16.228569,15.990069,-0.578554,-0.572743,23.230165,0.852449,22.619271,0.551169,0.00551169,-1.553471,-1.002267,-0.575665
2710,44714.41031,677.428701,58984294,16.16158,15.911546,-0.577257,-0.571362,23.262155,0.855228,22.515433,0.553057,0.00553057,-1.592464,-1.039408,-0.574316
2720,44714.41034,679.928701,58984296,16.049199,15.80777,-0.575954,-0.569785,23.296283,0.857975,22.369726,0.555223,0.00555223,-1.635127,-1.080093,-0.572827
2730,44714.41037,682.428701,58984299,15.945619,15.703632,-0.574624,-0.568174,23.333211,0.860742,22.219352,0.557109,0.00557109,-1.681644,-1.124382,-0.571507
2740,44714.41039,684.928701,58984301,15.836267,15.581694,-0.573278,-0.566761,23.367265,0.863448,22.049787,0.559125,0.00559125,-1.723664,-1.164539,-0.570084
2750,44714.41042,687.428701,58984304,15.681143,15.454149,-0.571979,-0.565281,23.401834,0.866262,21.869239,0.561072,0.00561072,-1.766694,-1.205647,-0.568697
2760,44714.41045,689.928701,58984306,15.553253,15.316584,-0.570616,-0.563967,23.435741,0.869235,21.683046,0.563108,0.00563108,-1.808164,-1.245088,-0.567308
2770,44714.41048,692.428701,58984309,15.388967,15.158117,-0.569322,-0.562586,23.473038,0.871823,21.44806,0.565084,0.00565084,-1.855415,-1.290331,-0.565893
2780,44714.41051,694.928701,58984311,15.244113,15.000535,-0.568004,-0.561074,23.327167,0.874654,21.225634,0.566965,0.00566965,-1.903582,-1.336618,-0.564546
2790,44714.41054,697.428701,58984314,15.054984,14.818562,-0.566782,-0.559529,23.506502,0.877242,20.968304,0.568875,0.00568875,-1.918079,-1.349204,-0.563231
2800,44714.41057,699.928701,58984316,14.866609,14.647042,-0.565573,-0.55828,23.543504,0.87971,20.724366,0.570724,0.00570724,-1.953493,-1.382688,-0.561982
2810,44714.4106,702.428701,58984319,14.678117,14.458415,-0.564231,-0.556834,23.578884,0.882665,20.462625,0.572704,0.00572704,-1.998267,-1.425562,-0.560564
2820,44714.41063,704.928701,58984321,14.469053,14.252614,-0.562951,-0.555355,23.662397,0.88525,20.175942,0.574616,0.00574616,-2.045242,-1.470594,-0.55923
2830,44714.41065,707.428701,58984324,14.248856,14.036842,-0.561622,-0.554073,23.580211,0.887726,19.869844,0.576616,0.00576616,-2.050471,-1.473855,-0.557845
2840,44714.41068,709.928701,58984326,14.004827,13.800697,-0.560575,-0.55289,23.599007,0.890266,19.525717,0.57822,0.0057822,-2.076987,-1.498767,-0.55668
2850,44714.41071,712.428701,58984329,13.765604,13.571565,-0.559162,-0.551246,23.616107,0.89294,19.207437,0.580198,0.00580198,-2.111484,-1.531336,-0.55538
2860,44714.41074,714.928701,58984331,13.486904,13.291453,-0.557727,-0.550063,23.663208,0.895773,18.806288,0.582294,0.00582294,-2.171304,-1.588946,-0.553877
2870,44714.41077,717.428701,58984334,13.063497,12.828612,-0.556165,-0.548616,23.714657,0.898783,18.182179,0.584302,0.00584302,-2.236812,-1.652561,-0.552472
2880,44714.4108,719.928701,58984336,12.236565,12.007361,-0.554664,-0.547992,23.951117,0.900955,17.01586,0.585876,0.00585876,-2.448843,-1.862961,-0.551373
2890,44714.41083,722.428701,58984339,11.585522,11.366825,-0.5529,-0.546611,24.026817,0.9043,16.107499,0.58816,0.0058816,-2.542519,-1.954358,-0.549748
2900,44714.41086,724.928701,58984341,11.04531,10.840049,-0.551474,-0.545592,24.090355,0.906701,15.356783,0.589929,0.00589929,-2.622065,-2.032134,-0.548533
2910,44714.41089,727.428701,58984344,10.54915,10.342109,-0.550123,-0.544639,24.149913,0.908932,14.652889,0.591514,0.00591514,-2.69684,-2.105375,-0.547424
2920,44714.41091,729.928701,58984346,10.124083,9.925136,-0.548583,-0.543587,24.208954,0.911598,14.053852,0.59342,0.0059342,-2.770881,-2.177436,-0.54609
2930,44714.41094,732.428701,58984349,9.678148,9.500494,-0.54736,-0.542536,24.268217,0.913922,13.450333,0.595032,0.00595032,-2.844923,-2.249891,-0.544935
2940,44714.41097,734.928701,58984351,9.356097,9.178018,-0.546095,-0.541681,24.317308,0.916042,13.003672,0.596492,0.00596492,-2.905294,-2.308753,-0.543939
2950,44714.411,737.428701,58984354,9.107488,8.913947,-0.544523,-0.540268,24.369642,0.919061,12.624562,0.598712,0.00598712,-2.970252,-2.37154,-0.54238
2960,44714.41103,739.928701,58984356,8.746678,8.57724,-0.544666,-0.540629,24.410477,0.918603,12.141951,0.598357,0.00598357,-3.02209,-2.423733,-0.542666
2970,44714.41106,742.428701,58984359,8.549412,8.390352,-0.545181,-0.541221,24.426915,0.917284,11.875451,0.597505,0.00597505,-3.043101,-2.445596,-0.54323
2980,44714.41109,744.928701,58984361,-0.246936,-0.403584,-1.064838,-1.064838,23.59569,0.001591,-0.568711,-0.147649,-0.00147649,-2.01001,-2.157659,-1.064838
2986,44714.41111,746.428701,58984363,-0.256022,-0.404562,-1.064838,-1.064838,23.58795,0.001522,-0.570936,-0.147649,-0.00147649,-1.999459,-2.147108,-1.064838