File: PB2_UCS_4422.csv
Index,Date,Time,Counter,Force(kN),LVDT1,LVDT2,Chain,OutputPower,Stress [MPa],Axial Strain (%),Strain Ax [-],Strain Rad. [%],Strain Vol. [%],Strain Vol [-],Gemidd,,Derivatives
2571,44655.40473,642.772853,58351880,0.156557,-0.931716,-0.926916,22.218952,0.143664,0.20983,0.188081,0.00188081,0,0.188081,0.00188081,-0.929696,,4951.258112
2580,44655.40475,645.022853,58351882,0.195383,-0.930751,-0.925535,22.218731,0.145981,0.273611,0.189988,0.00189988,-0.000093,0.189895,0.00189895,-0.92835,,3774.160222
2589,44655.40478,647.272853,58351884,0.221335,-0.930014,-0.924417,22.218952,0.147862,0.325185,0.19138,0.0019138,0,0.19123,0.0019123,-0.927458,,3931.9194
2598,44655.40481,649.522853,58351887,0.239926,-0.929188,-0.923267,22.218952,0.149832,0.363571,0.192867,0.00192867,-0.000186,0.192961,0.00192961,-0.92636,,4070.138375
2607,44655.40483,651.772853,58351889,0.301624,-0.928224,-0.921656,22.218805,0.152635,0.430911,0.194584,0.00194584,-0.000093,0.194469,0.00194469,-0.925009,,4123.960455
2616,44655.40486,654.022853,58351891,0.32957,-0.92756,-0.920342,22.2191,0.154469,0.476489,0.195796,0.00195796,-0.000186,0.195634,0.00195634,-0.924178,,4248.842344
2625,44655.40488,656.272853,58351893,0.37417,-0.926682,-0.918928,22.218952,0.156856,0.543127,0.197579,0.00197579,-0.000186,0.197299,0.00197299,-0.922832,,4361.608567
2634,44655.40491,658.522853,58351896,0.406735,-0.925906,-0.918008,22.2191,0.158922,0.597595,0.198868,0.00198868,-0.000186,0.198681,0.00198681,-0.922221,,4344.028329
2643,44655.40494,660.772853,58351898,0.447556,-0.925188,-0.916397,22.218952,0.161043,0.645294,0.200597,0.00200597,-0.00028,0.200363,0.00200363,-0.920696,,4531.036054
2652,44655.40496,663.022853,58351900,0.503284,-0.924295,-0.914491,22.219173,0.163736,0.704676,0.202132,0.00202132,-0.00028,0.20166,0.0020166,-0.919598,,4664.738028
2661,44655.40499,665.272853,58351902,0.54461,-0.923567,-0.913012,22.219247,0.165987,0.770504,0.203812,0.00203812,-0.000559,0.203439,0.00203439,-0.918279,,4803.239848
2670,44655.40501,667.522853,58351905,0.593085,-0.922837,-0.912025,22.219026,0.168233,0.869738,0.205647,0.00205647,-0.000653,0.205181,0.00205181,-0.916859,,4726.535424
2679,44655.40504,669.772853,58351907,0.630191,-0.922139,-0.910086,22.219394,0.170228,0.912916,0.206927,0.00206927,-0.000559,0.206368,0.00206368,-0.916181,,4812.731782
2688,44655.40507,672.022853,58351909,0.697265,-0.921261,-0.908443,22.2191,0.172914,1.012052,0.208849,0.00208849,-0.000653,0.208215,0.00208215,-0.914749,,4868.614731
2697,44655.40509,674.272853,58351911,0.744704,-0.920509,-0.906766,22.219542,0.175186,1.078328,0.210428,0.00210428,-0.000746,0.209682,0.00209682,-0.913666,,4834.688426
2706,44655.40512,676.522853,58351914,0.776622,-0.919992,-0.905616,22.219394,0.176664,1.1192,0.211274,0.00211274,-0.000653,0.210621,0.00210621,-0.913059,,4952.2041
2715,44655.40515,678.772853,58351916,0.834253,-0.919219,-0.90417,22.219468,0.179143,1.227047,0.213461,0.00213461,-0.001026,0.212704,0.00212704,-0.911294,,4943.832725
2724,44655.40517,681.022853,58351918,0.890452,-0.918189,-0.902658,22.219542,0.181837,1.308851,0.215135,0.00215135,-0.001119,0.214017,0.00214017,-0.910352,,4963.667094
2733,44655.4052,683.272853,58351920,0.941427,-0.917361,-0.901146,22.219542,0.183953,1.364316,0.216518,0.00216518,-0.000932,0.21561,0.0021561,-0.909274,,5063.52587
2742,44655.40522,685.522853,58351923,1.004661,-0.916359,-0.899601,22.219763,0.186551,1.440808,0.218154,0.00218154,-0.000932,0.217183,0.00217183,-0.90801,,5180.616108
2751,44655.40525,687.772853,58351925,1.044585,-0.915678,-0.898417,22.219542,0.188384,1.532667,0.219882,0.00219882,-0.001119,0.218763,0.00218763,-0.906893,,5081.16175
2760,44655.40528,690.022853,58351927,1.106327,-0.91458,-0.897168,22.219837,0.191065,1.642244,0.221961,0.00221961,-0.001212,0.220749,0.00220749,-0.905648,,5158.805185
2769,44655.4053,692.272853,58351929,1.142486,-0.913887,-0.896018,22.219689,0.192611,1.671642,0.222613,0.00222613,-0.001305,0.221399,0.00221399,-0.904983,,5138.51105
2778,44655.40533,694.522853,58351932,1.221194,-0.912476,-0.894506,22.219984,0.195793,1.766839,0.22467,0.0022467,-0.001492,0.223178,0.00223178,-0.903463,,5361.922941
2787,44655.40535,696.772853,58351934,1.279088,-0.911473,-0.892961,22.219837,0.198033,1.860116,0.226268,0.00226268,-0.001305,0.224861,0.00224861,-0.902287,,5203.060914
2796,44655.40538,699.022853,58351936,1.317152,-0.91067,-0.892106,22.219984,0.199865,1.910813,0.227647,0.00227647,-0.001399,0.226248,0.00226248,-0.901349,,5503.259927
2805,44655.40541,701.272853,58351938,1.393362,-0.909292,-0.890561,22.220132,0.202667,2.017926,0.229422,0.00229422,-0.001678,0.227761,0.00227761,-0.900008,,5356.67517
2814,44655.40543,703.522853,58351941,1.440232,-0.908313,-0.88974,22.220058,0.20468,2.093602,0.230989,0.00230989,-0.001678,0.229217,0.00229217,-0.898895,,5624.567056
2823,44655.40546,705.772853,58351943,1.490255,-0.907341,-0.888721,22.220426,0.206614,2.160517,0.232293,0.00232293,-0.001772,0.230521,0.00230521,-0.897964,,5561.121082
2832,44655.40548,708.022853,58351945,1.552273,-0.906161,-0.887143,22.220205,0.209032,2.255851,0.234125,0.00234125,-0.001772,0.232167,0.00232167,-0.896627,,5634.413664
2841,44655.40551,710.272853,58351947,1.611555,-0.905057,-0.885927,22.220426,0.211487,2.343893,0.235586,0.00235586,-0.001772,0.233815,0.00233815,-0.895521,,5702.219922
2850,44655.40554,712.522853,58351950,1.671675,-0.903914,-0.884809,22.220426,0.213892,2.417907,0.237304,0.00237304,-0.001958,0.235297,0.00235297,-0.894259,,5721.336618
2859,44655.40556,714.772853,58351952,1.724252,-0.902814,-0.88356,22.220574,0.215984,2.485915,0.238315,0.00238315,-0.002144,0.236264,0.00236264,-0.893646,,5753.475905
2868,44655.40559,717.022853,58351954,1.781258,-0.901804,-0.882804,22.220574,0.217931,2.573759,0.240169,0.00240169,-0.002144,0.238025,0.00238025,-0.892383,,5894.022646
2877,44655.40561,719.272853,58351956,1.838831,-0.900679,-0.881752,22.2205,0.220371,2.67976,0.241696,0.00241696,-0.002238,0.239455,0.00239455,-0.891203,,5881.954619
2886,44655.40564,721.522853,58351959,1.88584,-0.899913,-0.880832,22.220795,0.221846,2.715135,0.242701,0.00242701,-0.002144,0.240556,0.00240556,-0.890413,,6072.371333
2895,44655.40567,723.772853,58351961,1.969038,-0.89849,-0.879616,22.220721,0.224697,2.862932,0.244948,0.00244948,-0.002517,0.242378,0.00242378,-0.888905,,6217.17507
2904,44655.40569,726.022853,58351963,2.012309,-0.897548,-0.878564,22.220942,0.226629,2.899849,0.245886,0.00245886,-0.002517,0.243272,0.00243272,-0.888193,,6419.844665
2913,44655.40572,728.272853,58351965,2.106599,-0.895976,-0.876822,22.220942,0.229679,3.071208,0.24837,0.0024837,-0.002797,0.245573,0.00245573,-0.886483,,6452.723273
2922,44655.40574,730.522853,58351968,2.136856,-0.895329,-0.876263,22.220942,0.230993,3.090114,0.249009,0.00249009,-0.002797,0.246212,0.00246212,-0.88595,,6731.988889
2931,44655.40577,732.772853,58351970,2.196702,-0.894259,-0.875343,22.221163,0.233076,3.189417,0.250694,0.00250694,-0.002704,0.24793,0.0024793,-0.884783,,6829.798008
2940,44655.4058,735.022853,58351972,2.288379,-0.892673,-0.873929,22.221016,0.236173,3.335395,0.252974,0.00252974,-0.002797,0.249858,0.00249858,-0.883081,,7031.846081
2949,44655.40582,737.272853,58351974,2.32159,-0.89196,-0.87314,22.221458,0.237671,3.346766,0.253539,0.00253539,-0.00317,0.250427,0.00250427,-0.882654,,7187.087973
2958,44655.40585,739.522853,58351977,2.377047,-0.890924,-0.87199,22.221163,0.239701,3.484028,0.255663,0.00255663,-0.003263,0.252493,0.00252493,-0.881246,,7387.110199
2967,44655.40587,741.772853,58351979,2.459004,-0.889726,-0.870708,22.221532,0.24214,3.562776,0.256949,0.00256949,-0.003263,0.253642,0.00253642,-0.8802,,7587.627167
2976,44655.4059,744.022853,58351981,2.534237,-0.888606,-0.869821,22.221458,0.244437,3.667399,0.258487,0.00258487,-0.003543,0.255037,0.00255037,-0.879017,,7648.130146
2985,44655.40593,746.272853,58351983,2.643121,-0.887007,-0.86798,22.221679,0.247594,3.785269,0.260324,0.00260324,-0.003543,0.256875,0.00256875,-0.877733,,8053.044056
2994,44655.40595,748.522853,58351986,2.715618,-0.885846,-0.86729,22.221679,0.249882,3.949259,0.262421,0.00262421,-0.003636,0.258785,0.00258785,-0.876434,,8103.957722
3003,44655.40598,750.772853,58351988,2.794505,-0.884804,-0.86581,22.221827,0.251886,4.040527,0.263654,0.00263654,-0.003916,0.259738,0.00259738,-0.875407,,8112.257537
3012,44655.406,753.022853,58351990,2.865066,-0.883715,-0.864824,22.221974,0.253893,4.156427,0.265188,0.00265188,-0.00373,0.261422,0.00261422,-0.874244,,8203.629608
3021,44655.40603,755.272853,58351992,2.952478,-0.882492,-0.863707,22.221753,0.256501,4.301872,0.267009,0.00267009,-0.003916,0.263093,0.00263093,-0.873007,,8378.369597
3030,44655.40606,757.522853,58351995,3.045537,-0.881291,-0.862458,22.222195,0.25896,4.403277,0.268467,0.00268467,-0.004009,0.264457,0.00264457,-0.871783,,8543.403036
3039,44655.40608,759.772853,58351997,3.113824,-0.880315,-0.861636,22.222048,0.26087,4.526871,0.269918,0.00269918,-0.004289,0.265809,0.00265809,-0.870936,,8554.713068
3048,44655.40611,762.022853,58351999,3.197095,-0.879196,-0.860321,22.222269,0.263198,4.637567,0.271499,0.00271499,-0.004289,0.26721,0.0026721,-0.869783,,8634.532951
3057,44655.40613,764.272853,58352001,3.293322,-0.877957,-0.859138,22.222343,0.265567,4.779801,0.273204,0.00273204,-0.004475,0.268718,0.00268718,-0.868575,,8738.060054
3066,44655.40616,766.522853,58352004,3.394744,-0.876734,-0.85802,22.22249,0.268023,4.897819,0.274544,0.00274544,-0.004475,0.270061,0.00270061,-0.867454,,8814.728904
3075,44655.40619,768.772853,58352006,3.469824,-0.875771,-0.856936,22.222564,0.269815,5.004904,0.275975,0.00275975,-0.004848,0.271183,0.00271183,-0.866537,,9011.995916
3084,44655.40621,771.022853,58352008,3.574861,-0.874375,-0.855982,22.222564,0.272647,5.240293,0.278392,0.00278392,-0.004662,0.273823,0.00273823,-0.864723,,8942.461798
3093,44655.40624,773.272853,58352010,3.657267,-0.873466,-0.854865,22.222711,0.274351,5.329363,0.279451,0.00279451,-0.005128,0.274464,0.00274464,-0.864141,,8988.802038
3102,44655.40626,775.522853,58352013,3.738701,-0.872398,-0.85378,22.222785,0.276609,5.429021,0.28077,0.0028077,-0.004942,0.275829,0.00275829,-0.863106,,9271.481313
3111,44655.40629,777.772853,58352015,3.87058,-0.87104,-0.852531,22.222932,0.279379,5.591652,0.282683,0.00282683,-0.005315,0.277374,0.00277374,-0.861754,,9312.427612
3120,44655.40632,780.022853,58352017,3.948237,-0.870002,-0.851413,22.222932,0.281295,5.745884,0.284244,0.00284244,-0.005501,0.278743,0.00278743,-0.860637,,9270.898794
3129,44655.40634,782.272853,58352019,4.058647,-0.868765,-0.850296,22.223154,0.283847,5.894528,0.285922,0.00285922,-0.005315,0.28041,0.0028041,-0.859431,,9477.830475
3138,44655.40637,784.522853,58352022,4.1529,-0.867659,-0.849113,22.223227,0.285895,6.011627,0.287274,0.00287274,-0.005501,0.28184,0.0028184,-0.858399,,9652.314206
3147,44655.4064,786.772853,58352024,4.24752,-0.866559,-0.848126,22.223301,0.288118,6.144293,0.288949,0.00288949,-0.005874,0.283075,0.00283075,-0.857229,,9856.927641
3156,44655.40642,789.022853,58352026,4.341279,-0.865498,-0.846845,22.223448,0.29028,6.258106,0.290122,0.00290122,-0.005781,0.284227,0.00284227,-0.856414,,9953.75644
3165,44655.40645,791.272853,58352028,4.443619,-0.864331,-0.845628,22.223522,0.292549,6.440661,0.292047,0.00292047,-0.005874,0.286,0.00286,-0.855031,,10085.11973
3174,44655.40647,793.522853,58352031,4.561146,-0.863112,-0.844412,22.22367,0.294987,6.593809,0.293606,0.00293606,-0.005967,0.287682,0.00287682,-0.85388,,9899.79786
3183,44655.4065,795.772853,58352033,4.635554,-0.862179,-0.843426,22.223743,0.296834,6.726709,0.295014,0.00295014,-0.006433,0.288734,0.00288734,-0.852992,,10063.56508
3192,44655.40652,798.022853,58352035,4.744001,-0.860952,-0.842407,22.223891,0.299257,6.881819,0.296722,0.00296722,-0.006247,0.290475,0.00290475,-0.85162,,10254.26242
3201,44655.40655,800.272853,58352037,4.855716,-0.859798,-0.841322,22.223964,0.301662,7.061358,0.298376,0.00298376,-0.006806,0.291684,0.00291684,-0.850402,,10352.69803
3210,44655.40658,802.522853,58352040,4.957129,-0.858678,-0.839942,22.224259,0.303881,7.199722,0.299951,0.00299951,-0.0069,0.293052,0.00293052,-0.849443,,10344.88395
3219,44655.4066,804.772853,58352042,5.020923,-0.858008,-0.839515,22.224038,0.305359,7.268351,0.300666,0.00300666,-0.0069,0.293878,0.00293878,-0.848759,,10662.48507
3228,44655.40663,807.022853,58352044,5.151333,-0.856742,-0.8382,22.22448,0.307778,7.453252,0.302368,0.00302368,-0.006993,0.295317,0.00295317,-0.847616,,10474.86708
3237,44655.40666,809.272853,58352046,5.287982,-0.855307,-0.836819,22.224333,0.31066,7.698755,0.304753,0.00304753,-0.007179,0.297574,0.00297574,-0.845987,,10636.03927
3246,44655.40668,811.522853,58352049,5.417264,-0.854065,-0.835702,22.224775,0.313149,7.838896,0.306141,0.00306141,-0.007273,0.298816,0.00298816,-0.844906,,10778.92065
3255,44655.40671,813.772853,58352051,5.533329,-0.852933,-0.834551,22.224701,0.315285,8.016238,0.307785,0.00307785,-0.007459,0.300318,0.00300318,-0.84373,,10710.45379
3264,44655.40673,816.022853,58352053,5.643534,-0.851844,-0.833236,22.224849,0.317559,8.192648,0.309419,0.00309419,-0.007739,0.301681,0.00301681,-0.842599,,10795.98002
3273,44655.40676,818.272853,58352055,5.709699,-0.851059,-0.832645,22.224923,0.319022,8.258955,0.310426,0.00310426,-0.007832,0.302572,0.00302572,-0.841806,,11025.10556
3282,44655.40679,820.522853,58352058,5.841363,-0.849765,-0.830968,22.22507,0.32167,8.459353,0.312231,0.00312231,-0.007925,0.304138,0.00304138,-0.840651,,11168.37513
3291,44655.40681,822.772853,58352060,5.967948,-0.848608,-0.830015,22.225365,0.323977,8.617558,0.313649,0.00313649,-0.008018,0.305689,0.00305689,-0.839512,,11189.66956
3300,44655.40684,825.022853,58352062,6.090278,-0.847498,-0.829029,22.225217,0.326308,8.799576,0.315166,0.00315166,-0.008391,0.306926,0.00306926,-0.838246,,10993.37104
3309,44655.40686,827.272853,58352064,6.131496,-0.846844,-0.828405,22.225512,0.327565,8.902283,0.316409,0.00316409,-0.008205,0.30808,0.0030808,-0.837619,,11351.76773
3318,44655.40689,829.522853,58352067,6.302687,-0.845433,-0.826991,22.225586,0.33035,9.143349,0.318251,0.00318251,-0.008764,0.309486,0.00309486,-0.836239,,11173.34729
3327,44655.40692,831.772853,58352069,6.429563,-0.844182,-0.825479,22.225881,0.332897,9.265823,0.319672,0.00319672,-0.008578,0.311094,0.00311094,-0.835087,,11582.54133
3336,44655.40694,834.022853,58352071,6.547512,-0.843057,-0.824394,22.225807,0.335045,9.475399,0.321457,0.00321457,-0.009137,0.31233,0.0031233,-0.833829,,11571.12317
3345,44655.40697,836.272853,58352073,6.647494,-0.842053,-0.823507,22.226249,0.337154,9.686403,0.323281,0.00323281,-0.009324,0.314031,0.00314031,-0.832626,,11578.21649
3354,44655.40699,838.522853,58352076,6.76745,-0.840927,-0.822324,22.226028,0.339456,9.81945,0.324621,0.00324621,-0.009231,0.315391,0.00315391,-0.831567,,11930.2399
3363,44655.40702,840.772853,58352078,6.887178,-0.839797,-0.821239,22.226397,0.341655,10.0081,0.326235,0.00326235,-0.00951,0.316685,0.00316685,-0.830499,,11534.65972
3372,44655.40705,843.022853,58352080,7.012896,-0.838639,-0.820088,22.226397,0.343876,10.138956,0.327478,0.00327478,-0.009603,0.317874,0.00317874,-0.829577,,12063.90705
3381,44655.40707,845.272853,58352082,7.176564,-0.837266,-0.818675,22.226618,0.346598,10.392152,0.329537,0.00329537,-0.00979,0.319747,0.00319747,-0.828012,,12018.64388
3390,44655.4071,847.522853,58352085,7.312322,-0.836009,-0.817623,22.226765,0.349186,10.574855,0.331141,0.00331141,-0.009976,0.321123,0.00321123,-0.826976,,12125.75173
3399,44655.40712,849.772853,58352087,7.387093,-0.835281,-0.816801,22.226765,0.350517,10.685159,0.332318,0.00332318,-0.010163,0.322061,0.00322061,-0.826024,,12488.25246
3408,44655.40715,852.022853,58352089,7.552777,-0.833813,-0.815388,22.227208,0.353458,10.931525,0.334285,0.00334285,-0.010349,0.323935,0.00323935,-0.824687,,12220.44056
3417,44655.40718,854.272853,58352091,7.702323,-0.832473,-0.814336,22.227134,0.355967,11.117456,0.335919,0.00335919,-0.010722,0.325336,0.00325336,-0.823414,,12332.26016
3426,44655.4072,856.522853,58352094,7.862304,-0.831103,-0.812989,22.227502,0.358793,11.38149,0.337938,0.00337938,-0.010722,0.327192,0.00327192,-0.822018,,12430.07926
3435,44655.40723,858.772853,58352096,7.962724,-0.830112,-0.81197,22.227355,0.360673,11.543043,0.339326,0.00339326,-0.010909,0.328417,0.00328417,-0.821112,,12573.04696
3444,44655.40725,861.022853,58352098,8.045855,-0.829359,-0.810918,22.227797,0.362243,11.671604,0.340427,0.00340427,-0.011282,0.329145,0.00329145,-0.820301,,12739.30992
3453,44655.40728,863.272853,58352100,8.236325,-0.827777,-0.80957,22.227871,0.365322,11.972739,0.34267,0.0034267,-0.011561,0.331151,0.00331151,-0.818633,,12528.1485
3462,44655.40731,865.522853,58352103,8.29974,-0.827162,-0.808978,22.227945,0.366469,11.979258,0.343324,0.00343324,-0.011468,0.331763,0.00331763,-0.818092,,12954.03127
3471,44655.40733,867.772853,58352105,8.526689,-0.825424,-0.807335,22.228166,0.369912,12.334949,0.345681,0.00345681,-0.011841,0.333897,0.00333897,-0.816459,,12694.68705
3480,44655.40736,870.022853,58352107,8.630614,-0.824385,-0.80625,22.228313,0.37199,12.508515,0.347146,0.00347146,-0.012028,0.335118,0.00335118,-0.815448,,12838.45736
3489,44655.40738,872.272853,58352109,8.7515,-0.823372,-0.805659,22.228534,0.373923,12.647631,0.348235,0.00348235,-0.012214,0.33602,0.0033602,-0.814499,,12836.47616
3498,44655.40741,874.522853,58352112,8.914198,-0.822015,-0.804015,22.228608,0.376546,12.952651,0.350475,0.00350475,-0.012587,0.337981,0.00337981,-0.813056,,12784.14663
3507,44655.40744,876.772853,58352114,8.976564,-0.821326,-0.803522,22.228903,0.377859,13.017432,0.351354,0.00351354,-0.012587,0.338767,0.00338767,-0.812406,,13148.90624
3516,44655.40746,879.022853,58352116,9.120517,-0.82012,-0.80224,22.228755,0.380098,13.208884,0.352878,0.00352878,-0.01268,0.340096,0.00340096,-0.81133,,13369.09202
3525,44655.40749,881.272853,58352118,9.333172,-0.818463,-0.80086,22.229271,0.383523,13.514243,0.355096,0.00355096,-0.01296,0.341992,0.00341992,-0.809655,,13166.6373
3534,44655.40751,883.522853,58352121,9.48531,-0.817215,-0.799611,22.229198,0.385874,13.738297,0.356786,0.00356786,-0.013426,0.343466,0.00343466,-0.808446,,13054.90041
3543,44655.40754,885.772853,58352123,9.600807,-0.816214,-0.798592,22.229493,0.387859,13.945953,0.35828,0.0035828,-0.013333,0.344927,0.00344927,-0.807388,,13146.93926
3552,44655.40757,888.022853,58352125,9.700574,-0.815311,-0.798066,22.22964,0.389574,14.054792,0.359289,0.00359289,-0.013613,0.345642,0.00345642,-0.806724,,13576.92607
3561,44655.40759,890.272853,58352127,9.84747,-0.814043,-0.796652,22.229787,0.391896,14.315388,0.361358,0.00361358,-0.014079,0.347279,0.00347279,-0.805354,,13385.98463
3570,44655.40762,892.522853,58352130,9.959023,-0.813088,-0.7956,22.230009,0.393852,14.428049,0.362169,0.00362169,-0.013892,0.348263,0.00348263,-0.804665,,13631.64585
3579,44655.40765,894.772853,58352132,10.046604,-0.812279,-0.795009,22.230082,0.395455,14.637388,0.363728,0.00363728,-0.014359,0.349534,0.00349534,-0.803417,,13487.89442
3588,44655.40767,897.022853,58352134,10.279955,-0.810634,-0.793398,22.230377,0.398562,14.898122,0.365767,0.00365767,-0.014452,0.351163,0.00351163,-0.801942,,13745.78483
3597,44655.4077,899.272853,58352136,10.378592,-0.809672,-0.792412,22.230377,0.400351,15.079933,0.367115,0.00367115,-0.014825,0.352347,0.00352347,-0.801139,,13836.03548
3606,44655.40772,901.522853,58352139,10.629484,-0.80793,-0.7909,22.230672,0.403836,15.39173,0.369411,0.00369411,-0.014918,0.354534,0.00354534,-0.799423,,13604.71926
3615,44655.40775,903.772853,58352141,10.74902,-0.80686,-0.790013,22.230819,0.405878,15.617727,0.370896,0.00370896,-0.015105,0.355766,0.00355766,-0.798386,,13748.94902
3624,44655.40778,906.022853,58352143,10.873931,-0.805892,-0.789059,22.231114,0.407832,15.755863,0.372121,0.00372121,-0.015664,0.356472,0.00356472,-0.797592,,14008.30148
3633,44655.4078,908.272853,58352145,10.9953,-0.804881,-0.788007,22.231188,0.409814,15.888178,0.373254,0.00373254,-0.015571,0.357776,0.00357776,-0.79658,,14067.54891
3642,44655.40783,910.522853,58352148,11.167501,-0.803509,-0.786923,22.231483,0.412353,16.164499,0.375155,0.00375155,-0.01585,0.359165,0.00359165,-0.795326,,14100.83797
3651,44655.40785,912.772853,58352150,11.385264,-0.801932,-0.785542,22.23163,0.415356,16.500811,0.377305,0.00377305,-0.01641,0.360895,0.00360895,-0.793782,,13884.86231
3660,44655.40788,915.022853,58352152,11.467215,-0.801134,-0.784753,22.231851,0.417025,16.614297,0.378532,0.00378532,-0.016503,0.362029,0.00362029,-0.792925,,14370.59498
3669,44655.40791,917.272853,58352154,11.638828,-0.799787,-0.783537,22.232072,0.419575,16.894559,0.380263,0.00380263,-0.016783,0.363455,0.00363455,-0.791653,,13917.03572
3678,44655.40793,919.522853,58352157,11.822854,-0.798425,-0.781959,22.23222,0.422168,17.06966,0.381761,0.00381761,-0.016876,0.364837,0.00364837,-0.790484,,14257.86247
3687,44655.40796,921.772853,58352159,11.948371,-0.797423,-0.781434,22.232515,0.424196,17.34226,0.383548,0.00383548,-0.017156,0.366392,0.00366392,-0.789306,,14151.60449
3696,44655.40798,924.022853,58352161,12.066474,-0.796413,-0.780086,22.232588,0.426078,17.544546,0.384928,0.00384928,-0.017435,0.367371,0.00367371,-0.788413,,13733.03263
3705,44655.40801,926.272853,58352163,12.206162,-0.795374,-0.779461,22.232809,0.428098,17.640318,0.385939,0.00385939,-0.017622,0.368398,0.00368398,-0.787588,,14212.67139
3714,44655.40804,928.522853,58352166,12.381394,-0.794014,-0.778179,22.233031,0.430744,17.985571,0.388118,0.00388118,-0.017808,0.370252,0.00370252,-0.785903,,14241.62382
3723,44655.40806,930.772853,58352168,12.569165,-0.792742,-0.776733,22.233252,0.433246,18.211098,0.389648,0.00389648,-0.018368,0.371443,0.00371443,-0.784798,,14050.55355
3732,44655.40809,933.022853,58352170,12.640903,-0.791951,-0.776207,22.233399,0.434697,18.35436,0.390785,0.00390785,-0.018554,0.372408,0.00372408,-0.784098,,14052.95846
3741,44655.40811,935.272853,58352172,12.855924,-0.790446,-0.774728,22.23362,0.437603,18.671769,0.392936,0.00392936,-0.018648,0.374103,0.00374103,-0.782686,,14274.10851
3750,44655.40814,937.522853,58352175,13.013138,-0.789321,-0.773578,22.233989,0.439826,18.905808,0.394626,0.00394626,-0.018927,0.375698,0.00375698,-0.781339,,14539.28051
3759,44655.40817,939.772853,58352177,13.166614,-0.788099,-0.772789,22.234062,0.442216,19.121391,0.395978,0.00395978,-0.0193,0.376769,0.00376769,-0.780376,,14186.6064
3768,44655.40819,942.022853,58352179,13.340992,-0.786755,-0.771277,22.234431,0.444744,19.314314,0.39765,0.0039765,-0.019766,0.377884,0.00377884,-0.779193,,14576.19279
3777,44655.40822,944.272853,58352181,13.477271,-0.785712,-0.770291,22.234431,0.446689,19.534987,0.399052,0.00399052,-0.019673,0.379379,0.00379379,-0.778159,,14286.3116
3786,44655.40824,946.522853,58352184,13.613171,-0.784585,-0.769403,22.2348,0.448855,19.785393,0.400812,0.00400812,-0.020046,0.380766,0.00380766,-0.776999,,14515.95539
3795,44655.40827,948.772853,58352186,13.703155,-0.783845,-0.768713,22.234873,0.450171,19.812831,0.401445,0.00401445,-0.020512,0.380933,0.00380933,-0.77644,,15019.85547
3804,44655.4083,951.022853,58352188,13.839379,-0.782771,-0.767628,22.235316,0.452408,20.086603,0.403151,0.00403151,-0.020512,0.382647,0.00382647,-0.775198,,14854.66989
3813,44655.40832,953.272853,58352190,14.02311,-0.781457,-0.766346,22.235316,0.454856,20.367625,0.404844,0.00404844,-0.021072,0.38373,0.0038373,-0.774028,,14875.3966
3822,44655.40835,955.522853,58352193,14.19124,-0.780248,-0.765294,22.235758,0.457236,20.584377,0.406539,0.00406539,-0.021165,0.385244,0.00385244,-0.772738,,14871.93692
3831,44655.40837,957.772853,58352195,14.287995,-0.779403,-0.764801,22.235758,0.458854,20.698534,0.407466,0.00407466,-0.021724,0.38581,0.0038581,-0.772065,,14993.17521
3840,44655.4084,960.022853,58352197,14.495215,-0.778029,-0.763256,22.2362,0.461509,21.005443,0.409285,0.00409285,-0.022004,0.387268,0.00387268,-0.770774,,15035.16147
3849,44655.40843,962.272853,58352199,14.695949,-0.776647,-0.762139,22.236274,0.464229,21.298392,0.411082,0.00411082,-0.022097,0.388985,0.00388985,-0.769443,,14578.63002
3858,44655.40845,964.522853,58352202,14.839753,-0.77553,-0.761021,22.236716,0.46644,21.522616,0.412904,0.00412904,-0.022657,0.390154,0.00390154,-0.768208,,15122.32891
3867,44655.40848,966.772853,58352204,14.946942,-0.774641,-0.760232,22.23679,0.468056,21.715596,0.414124,0.00414124,-0.02275,0.391287,0.00391287,-0.767331,,15025.92317
3876,44655.4085,969.022853,58352206,15.111322,-0.773434,-0.758951,22.237232,0.470262,21.868656,0.415387,0.00415387,-0.023123,0.392171,0.00392171,-0.766316,,15203.73047
3885,44655.40853,971.272853,58352208,15.316186,-0.77204,-0.757899,22.237379,0.473088,22.19359,0.417402,0.00417402,-0.023589,0.393854,0.00393854,-0.764947,,15078.76497
3894,44655.40856,973.522853,58352211,15.42135,-0.771147,-0.756945,22.237601,0.474752,22.431693,0.418881,0.00418881,-0.023869,0.394982,0.00394982,-0.763914,,14978.15232
3903,44655.40858,975.772853,58352213,15.642328,-0.769749,-0.755795,22.237895,0.477449,22.669533,0.420539,0.00420539,-0.024149,0.39639,0.0039639,-0.762666,,15006.17576
3912,44655.40861,978.022853,58352215,15.799717,-0.768588,-0.754382,22.238264,0.479713,22.946275,0.422179,0.00422179,-0.024522,0.397601,0.00397601,-0.761585,,14731.36777
3921,44655.40863,980.272853,58352217,15.967376,-0.767338,-0.753626,22.238411,0.482043,23.158858,0.42385,0.0042385,-0.024895,0.398908,0.00398908,-0.760311,,15137.36998
3930,44655.40866,982.522853,58352220,16.064636,-0.766543,-0.752705,22.238706,0.483577,23.328187,0.425005,0.00425005,-0.025174,0.399831,0.00399831,-0.759514,,15152.89055
3939,44655.40869,984.772853,58352222,16.296194,-0.765021,-0.751226,22.239075,0.486616,23.659149,0.426935,0.00426935,-0.025734,0.401282,0.00401282,-0.758203,,14969.18328
3948,44655.40871,987.022853,58352224,16.429059,-0.764042,-0.750174,22.239222,0.488424,23.786381,0.428148,0.00428148,-0.026107,0.402055,0.00402055,-0.757247,,15161.18406
3957,44655.40874,989.272853,58352226,16.627893,-0.762646,-0.749122,22.239738,0.491169,24.121237,0.430088,0.00430088,-0.0262,0.403888,0.00403888,-0.755862,,14691.02472
3966,44655.40876,991.522853,58352229,16.757351,-0.761603,-0.748235,22.239812,0.493068,24.344231,0.431618,0.00431618,-0.02648,0.405127,0.00405127,-0.754763,,14930.9466
3975,44655.40879,993.772853,58352231,16.963156,-0.760243,-0.74692,22.240328,0.495714,24.582978,0.43324,0.0043324,-0.027132,0.406065,0.00406065,-0.753689,,14815.55674
3984,44655.40882,996.022853,58352233,17.130174,-0.759022,-0.74577,22.240401,0.498053,24.82589,0.434859,0.00434859,-0.027412,0.407447,0.00407447,-0.752424,,15056.44103
3993,44655.40884,998.272853,58352235,17.275817,-0.757915,-0.744816,22.240917,0.500192,25.035495,0.436265,0.00436265,-0.027785,0.408445,0.00408445,-0.75145,,15032.99964
4002,44655.40887,1000.522853,58352238,17.352565,-0.75712,-0.744192,22.240917,0.501612,25.271904,0.437881,0.00437881,-0.028251,0.40963,0.0040963,-0.750264,,15297.42139
4011,44655.4089,1002.772853,58352240,17.535325,-0.755913,-0.74291,22.241581,0.503978,25.424533,0.439002,0.00439002,-0.028624,0.410413,0.00410413,-0.749366,,15182.94104
4020,44655.40892,1005.022853,58352242,17.763857,-0.754418,-0.741661,22.241581,0.506842,25.763848,0.441059,0.00441059,-0.028997,0.411969,0.00411969,-0.747947,,15224.37195
4029,44655.40895,1007.272853,58352244,17.947676,-0.753122,-0.740511,22.24217,0.509403,26.004339,0.442666,0.00442666,-0.02937,0.413257,0.00413257,-0.746743,,15003.86954
4038,44655.40897,1009.522853,58352247,18.045475,-0.752189,-0.739623,22.242244,0.51104,26.204958,0.443942,0.00443942,-0.029743,0.4142,0.004142,-0.745909,,15170.25465
4047,44655.409,1011.772853,58352249,18.245133,-0.750871,-0.73844,22.242834,0.513641,26.418969,0.445512,0.00445512,-0.030209,0.415326,0.00415326,-0.744765,,15147.08399
4056,44655.40903,1014.022853,58352251,18.342669,-0.750013,-0.737421,22.242908,0.515253,26.569937,0.446756,0.00446756,-0.030582,0.416243,0.00416243,-0.743838,,15422.76763
4065,44655.40905,1016.272853,58352253,18.571002,-0.74848,-0.736303,22.243424,0.518262,26.927882,0.448922,0.00448922,-0.030955,0.417878,0.00417878,-0.742292,,15214.9561
4074,44655.40908,1018.522853,58352256,18.663857,-0.747715,-0.735514,22.243571,0.519707,27.079103,0.450088,0.00450088,-0.031514,0.41871,0.0041871,-0.741396,,15315.50925
4083,44655.4091,1020.772853,58352258,18.880094,-0.746344,-0.734232,22.244087,0.522311,27.372687,0.451774,0.00451774,-0.031701,0.419895,0.00419895,-0.740283,,15023.9659
4092,44655.40913,1023.022853,58352260,19.005031,-0.745339,-0.733345,22.244234,0.524265,27.558333,0.453047,0.00453047,-0.032447,0.420601,0.00420601,-0.739368,,15170.58857
4101,44655.40916,1025.272853,58352262,19.214941,-0.743909,-0.732063,22.24475,0.526885,27.894035,0.455022,0.00455022,-0.032633,0.422314,0.00422314,-0.737888,,14864.44816
4110,44655.40918,1027.522853,58352265,19.384379,-0.74269,-0.730913,22.245119,0.52932,28.107966,0.456676,0.00456676,-0.033193,0.423483,0.00423483,-0.736762,,15254.81503
4119,44655.40921,1029.772853,58352267,19.532874,-0.741626,-0.729894,22.245487,0.531469,28.381831,0.458255,0.00458255,-0.033939,0.424375,0.00424375,-0.735686,,15009.58053
4128,44655.40923,1032.022853,58352269,19.673938,-0.740547,-0.728907,22.24593,0.5334,28.520788,0.459438,0.00459438,-0.034218,0.425313,0.00425313,-0.734711,,15031.00635
4137,44655.40926,1034.272853,58352271,19.906734,-0.739029,-0.727428,22.246151,0.536307,28.85596,0.461417,0.00461417,-0.034684,0.426653,0.00426653,-0.733317,,14731.02022
4146,44655.40929,1036.522853,58352274,20.013962,-0.738157,-0.726672,22.24674,0.53792,29.003213,0.462573,0.00462573,-0.035151,0.427422,0.00427422,-0.732458,,14630.70618
4155,44655.40931,1038.772853,58352276,20.17699,-0.737012,-0.725686,22.246888,0.540187,29.262598,0.464215,0.00464215,-0.035617,0.428555,0.00428555,-0.731289,,14744.73715
4164,44655.40934,1041.022853,58352278,20.377812,-0.735598,-0.724437,22.247551,0.542788,29.544398,0.466119,0.00466119,-0.036083,0.429928,0.00429928,-0.729978,,14646.53653
4173,44655.40936,1043.272853,58352280,20.534854,-0.734453,-0.723385,22.247846,0.545021,29.754263,0.467555,0.00467555,-0.036922,0.430633,0.00430633,-0.728886,,14729.30463
4182,44655.40939,1045.522853,58352283,20.718339,-0.73318,-0.722235,22.248436,0.547504,29.998726,0.469253,0.00469253,-0.037388,0.431874,0.00431874,-0.727653,,14693.04885
4191,44655.40942,1047.772853,58352285,20.854738,-0.732099,-0.721249,22.248657,0.549601,30.233818,0.470683,0.00470683,-0.037668,0.432985,0.00432985,-0.72672,,14322.60849
4200,44655.40944,1050.022853,58352287,20.94223,-0.731356,-0.720591,22.248952,0.551052,30.384276,0.471775,0.00471775,-0.038228,0.433519,0.00433519,-0.725935,,14454.14035
4209,44655.40947,1052.272853,58352289,21.178828,-0.729783,-0.719145,22.249615,0.554042,30.726455,0.473841,0.00473841,-0.038787,0.43502,0.0043502,-0.724404,,14311.36173
4218,44655.40949,1054.522853,58352292,21.318767,-0.728582,-0.718028,22.249762,0.556277,30.96528,0.475467,0.00475467,-0.039346,0.436121,0.00436121,-0.723262,,14269.34623
4227,44655.40952,1056.772853,58352294,21.510517,-0.72725,-0.716713,22.250573,0.558907,31.17346,0.477086,0.00477086,-0.039906,0.437198,0.00437198,-0.722099,,14586.29429
4236,44655.40955,1059.022853,58352296,21.660454,-0.726088,-0.715924,22.250721,0.561083,31.384245,0.47858,0.0047858,-0.040372,0.438155,0.00438155,-0.721064,,14600.60184
4245,44655.40957,1061.272853,58352298,21.765445,-0.725136,-0.714938,22.251384,0.562831,31.555686,0.480019,0.00480019,-0.041025,0.438715,0.00438715,-0.719992,,14762.25507
4254,44655.4096,1063.522853,58352301,21.884782,-0.724141,-0.713886,22.251753,0.564786,31.7925,0.481373,0.00481373,-0.041584,0.439785,0.00439785,-0.719019,,14635.1755
4263,44655.40962,1065.772853,58352303,22.062318,-0.722834,-0.7129,22.252269,0.56728,32.020395,0.483024,0.00483024,-0.042423,0.440557,0.00440557,-0.717833,,14588.92573
4272,44655.40965,1068.022853,58352305,22.231995,-0.721614,-0.711519,22.252858,0.569563,32.285494,0.48474,0.0048474,-0.042983,0.441757,0.00441757,-0.716789,,14125.89189
4281,44655.40968,1070.272853,58352307,22.432028,-0.720297,-0.71073,22.253227,0.571972,32.495075,0.486243,0.00486243,-0.043635,0.442559,0.00442559,-0.715489,,13739.66637
4290,44655.4097,1072.522853,58352310,22.519456,-0.719504,-0.709777,22.25389,0.573578,32.606931,0.487252,0.00487252,-0.044195,0.443058,0.00443058,-0.714707,,12863.64891
4299,44655.40973,1074.772853,58352312,22.680437,-0.718287,-0.708725,22.254185,0.575926,32.855934,0.488875,0.00488875,-0.045034,0.443841,0.00443841,-0.713639,,12281.74916
4308,44655.40975,1077.022853,58352314,22.81008,-0.717177,-0.707608,22.255069,0.577971,33.112159,0.490511,0.00490511,-0.045407,0.445099,0.00445099,-0.712458,,11430.27571
4317,44655.40978,1079.272853,58352316,23.020502,-0.715759,-0.706326,22.255291,0.580727,33.370521,0.492323,0.00492323,-0.046526,0.445797,0.00445797,-0.711141,,11125.81251
4326,44655.40981,1081.522853,58352319,23.135103,-0.714776,-0.705373,22.256101,0.582634,33.602078,0.493736,0.00493736,-0.046992,0.446733,0.00446733,-0.710212,,10502.01234
4335,44655.40983,1083.772853,58352321,23.31565,-0.713499,-0.704222,22.256544,0.584954,33.834518,0.495362,0.00495362,-0.047924,0.447437,0.00447437,-0.709014,,10139.73502
4344,44655.40986,1086.022853,58352323,23.528635,-0.712095,-0.703105,22.257354,0.587824,34.07206,0.497065,0.00497065,-0.048577,0.448484,0.00448484,-0.707708,,9967.683069
4353,44655.40988,1088.272853,58352325,23.63708,-0.711099,-0.701954,22.25787,0.589626,34.310921,0.498581,0.00498581,-0.049323,0.449258,0.00449258,-0.706657,,9642.527063
4362,44655.40991,1090.522853,58352328,23.854607,-0.709568,-0.700968,22.258608,0.592534,34.572144,0.500515,0.00500515,-0.050348,0.45026,0.0045026,-0.705268,,9641.993415
4371,44655.40994,1092.772853,58352330,23.904012,-0.708812,-0.700376,22.25905,0.593971,34.637455,0.50139,0.0050139,-0.050908,0.450421,0.00450421,-0.704639,,10095.37862
4380,44655.40996,1095.022853,58352332,23.983644,-0.707673,-0.699095,22.259787,0.596025,34.801278,0.503028,0.00503028,-0.051933,0.451246,0.00451246,-0.703354,,10564.77586
4389,44655.40999,1097.272853,58352334,24.048922,-0.706248,-0.698141,22.260819,0.598646,34.843405,0.504638,0.00504638,-0.053052,0.451613,0.00451613,-0.702152,,11336.2329
4398,44655.41001,1099.522853,58352337,24.128525,-0.704981,-0.697287,22.261482,0.600888,35.007328,0.506392,0.00506392,-0.053985,0.452408,0.00452408,-0.701045,,12069.92091
4407,44655.41004,1101.772853,58352339,24.237718,-0.703633,-0.696005,22.26244,0.603386,35.077252,0.507703,0.00507703,-0.054824,0.452879,0.00452879,-0.699992,,12800.39209
4416,44655.41007,1104.022853,58352341,24.281201,-0.702505,-0.695084,22.262883,0.605329,35.325215,0.509892,0.00509892,-0.056129,0.453802,0.00453802,-0.698693,,13432.09052
4425,44655.41009,1106.272853,58352343,24.422161,-0.70125,-0.694098,22.263767,0.607599,35.423442,0.511079,0.00511079,-0.056875,0.454198,0.00454198,-0.697665,,13488.56045
4434,44655.41012,1108.522853,58352346,24.534347,-0.700022,-0.693014,22.264136,0.609835,35.579465,0.512571,0.00512571,-0.057528,0.455061,0.00455061,-0.696572,,13351.57003
4443,44655.41015,1110.772853,58352348,24.710189,-0.698627,-0.691765,22.26502,0.612379,35.781717,0.514217,0.00514217,-0.058274,0.455943,0.00455943,-0.695399,,13154.77021
4452,44655.41017,1113.022853,58352350,24.839623,-0.697388,-0.690877,22.265462,0.614679,35.9677,0.515763,0.00515763,-0.058926,0.45682,0.0045682,-0.694288,,13701.69541
4461,44655.4102,1115.272853,58352352,24.960403,-0.696305,-0.68999,22.265978,0.616549,36.182839,0.51722,0.0051722,-0.059486,0.457678,0.00457678,-0.693267,,13656.47409
4470,44655.41022,1117.522853,58352355,25.057041,-0.695272,-0.689332,22.266568,0.618406,36.371942,0.518571,0.00518571,-0.060511,0.458187,0.00458187,-0.692307,,13709.49129
4479,44655.41025,1119.772853,58352357,25.282494,-0.693792,-0.687985,22.267084,0.621203,36.639549,0.520428,0.00520428,-0.061164,0.459357,0.00459357,-0.690855,,13789.22371
4488,44655.41028,1122.022853,58352359,25.397783,-0.69273,-0.687229,22.267895,0.623205,36.782581,0.521744,0.00521744,-0.06191,0.459834,0.00459834,-0.68994,,14078.32487
4497,44655.4103,1124.272853,58352361,25.53721,-0.691631,-0.686012,22.268263,0.625233,37.052214,0.523334,0.00523334,-0.062842,0.46049,0.0046049,-0.688874,,13693.87069
4506,44655.41033,1126.522853,58352364,25.747872,-0.690196,-0.684862,22.269295,0.627849,37.297224,0.525046,0.00525046,-0.063681,0.461486,0.00461486,-0.68755,,13486.64774
4515,44655.41035,1128.772853,58352366,25.867123,-0.689175,-0.683744,22.269664,0.629817,37.598462,0.526816,0.00526816,-0.064614,0.462346,0.00462346,-0.686403,,13120.44029
4524,44655.41038,1131.022853,58352368,26.023714,-0.688013,-0.682594,22.270696,0.632108,37.705032,0.527994,0.00527994,-0.06536,0.462721,0.00462721,-0.685458,,13267.14714
4533,44655.41041,1133.272853,58352370,26.14517,-0.686542,-0.681575,22.271064,0.634748,37.879807,0.5298,0.005298,-0.066292,0.463507,0.00463507,-0.684236,,13775.3171
4542,44655.41043,1135.522853,58352373,26.268468,-0.685454,-0.680753,22.271949,0.636758,38.005794,0.531124,0.00531124,-0.067038,0.464179,0.00464179,-0.683205,,14113.86981
4551,44655.41046,1137.772853,58352375,26.46147,-0.684055,-0.679373,22.272538,0.639338,38.327543,0.532986,0.00532986,-0.068064,0.464975,0.00464975,-0.681903,,13838.36564
4560,44655.41048,1140.022853,58352377,26.549685,-0.68323,-0.678715,22.273276,0.640921,38.525334,0.534373,0.00534373,-0.06881,0.465476,0.00465476,-0.681016,,13415.41497
4569,44655.41051,1142.272853,58352379,26.70831,-0.682041,-0.677663,22.274013,0.643105,38.740805,0.53585,0.0053585,-0.069928,0.465955,0.00465955,-0.679792,,13743.81667
4578,44655.41054,1144.522853,58352382,26.906902,-0.680678,-0.676283,22.274971,0.645693,39.014467,0.537651,0.00537651,-0.070861,0.466825,0.00466825,-0.678555,,13255.1128
4587,44655.41056,1146.772853,58352384,27.09625,-0.679363,-0.675198,22.275782,0.648237,39.250089,0.539271,0.00539271,-0.072259,0.467086,0.00467086,-0.677372,,13647.31484
4596,44655.41059,1149.022853,58352386,27.243873,-0.678072,-0.674113,22.27674,0.650634,39.456173,0.540889,0.00540889,-0.073098,0.46779,0.0046779,-0.676175,,13671.94261
4605,44655.41061,1151.272853,58352388,27.336133,-0.677057,-0.673325,22.277624,0.652566,39.625424,0.542309,0.00542309,-0.074311,0.467932,0.00467932,-0.675291,,13708.04779
4614,44655.41064,1153.522853,58352391,27.489588,-0.675693,-0.672273,22.278509,0.654898,39.899,0.54435,0.0054435,-0.075616,0.468803,0.00468803,-0.673727,,13951.26177
4623,44655.41067,1155.772853,58352393,27.631686,-0.674406,-0.670892,22.279541,0.657414,40.052123,0.545685,0.00545685,-0.076735,0.469026,0.00469026,-0.672763,,14101.67355
4632,44655.41069,1158.022853,58352395,27.783231,-0.673175,-0.670038,22.280278,0.659611,40.312528,0.54746,0.0054746,-0.07776,0.469606,0.00469606,-0.671681,,13969.05368
4641,44655.41072,1160.272853,58352397,27.899875,-0.672168,-0.669019,22.281457,0.66156,40.512135,0.548882,0.00548882,-0.079066,0.469816,0.00469816,-0.670521,,13691.90906
4650,44655.41074,1162.522853,58352400,28.080372,-0.670862,-0.667704,22.282268,0.664113,40.769461,0.550632,0.00550632,-0.080371,0.470261,0.00470261,-0.669309,,13383.41146
4659,44655.41077,1164.772853,58352402,28.142675,-0.670131,-0.667014,22.283374,0.665522,40.83681,0.551603,0.00551603,-0.08149,0.470113,0.00470113,-0.668622,,13943.48144
4668,44655.4108,1167.022853,58352404,28.40219,-0.668436,-0.665732,22.284479,0.668785,41.175797,0.553567,0.00553567,-0.083075,0.470492,0.00470492,-0.667157,,13577.76372
4677,44655.41082,1169.272853,58352406,28.475201,-0.667631,-0.66468,22.285732,0.670288,41.276452,0.554716,0.00554716,-0.084473,0.470243,0.00470243,-0.6663,,13589.16195
4686,44655.41085,1171.522853,58352409,28.710177,-0.666158,-0.663661,22.286617,0.673245,41.636322,0.556756,0.00556756,-0.085965,0.470804,0.00470804,-0.664737,,12796.83415
4695,44655.41087,1173.772853,58352411,28.85985,-0.664946,-0.66251,22.288165,0.675496,41.819505,0.558175,0.00558175,-0.087457,0.470718,0.00470718,-0.663711,,12599.18178
4704,44655.4109,1176.022853,58352413,29.02158,-0.663721,-0.661459,22.28927,0.677986,42.05778,0.560053,0.00560053,-0.089229,0.470855,0.00470855,-0.662474,,12394.32981
4713,44655.41093,1178.272853,58352415,29.156562,-0.662664,-0.660111,22.290818,0.680063,42.31494,0.561667,0.00561667,-0.090814,0.470841,0.00470841,-0.661345,,11961.73637
4722,44655.41095,1180.522853,58352418,29.32735,-0.66139,-0.659026,22.292219,0.682571,42.546286,0.563372,0.00563372,-0.092678,0.470667,0.00470667,-0.660106,,11723.742
4731,44655.41098,1182.772853,58352420,29.494788,-0.660127,-0.657514,22.293914,0.684957,42.727498,0.564748,0.00564748,-0.094823,0.469958,0.00469958,-0.659032,,11530.9126
4740,44655.411,1185.022853,58352422,29.556067,-0.659293,-0.657087,22.295167,0.686548,42.860982,0.566037,0.00566037,-0.096874,0.469163,0.00469163,-0.658283,,11579.16643
4749,44655.41103,1187.272853,58352424,29.711568,-0.658072,-0.656068,22.296936,0.68898,43.053474,0.567698,0.00567698,-0.098739,0.468959,0.00468959,-0.656931,,11371.509
4758,44655.41106,1189.522853,58352427,29.88801,-0.656767,-0.65472,22.298558,0.691534,43.312754,0.56936,0.0056936,-0.100697,0.468621,0.00468621,-0.65581,,10868.41105
4767,44655.41108,1191.772853,58352429,30.024885,-0.655615,-0.653701,22.300327,0.693723,43.536427,0.570953,0.00570953,-0.103028,0.467832,0.00467832,-0.654665,,10340.36861
4776,44655.41111,1194.022853,58352431,30.140875,-0.654452,-0.652419,22.302096,0.696042,43.703884,0.572579,0.00572579,-0.105359,0.467221,0.00467221,-0.653497,,10116.95686
4785,44655.41113,1196.272853,58352433,30.267431,-0.653129,-0.651565,22.30416,0.698408,43.887797,0.57435,0.0057435,-0.107876,0.466433,0.00466433,-0.652187,,9652.403933
4794,44655.41116,1198.522853,58352436,30.372915,-0.652075,-0.650316,22.306223,0.700601,44.021464,0.575652,0.00575652,-0.1103,0.465237,0.00465237,-0.651289,,9152.803322
4803,44655.41119,1200.772853,58352438,30.465214,-0.651071,-0.64933,22.308066,0.702526,44.154033,0.576966,0.00576966,-0.113098,0.463869,0.00463869,-0.6504,,8659.951259
4812,44655.41121,1203.022853,58352440,30.577283,-0.649893,-0.648409,22.310572,0.704767,44.351306,0.578691,0.00578691,-0.115895,0.462794,0.00462794,-0.649106,,8425.379398
4821,44655.41124,1205.272853,58352442,30.658706,-0.648913,-0.647259,22.312562,0.706652,44.505675,0.580085,0.00580085,-0.118785,0.461474,0.00461474,-0.648227,,7609.299781
4830,44655.41126,1207.522853,58352445,30.803804,-0.647628,-0.646207,22.315216,0.709215,44.701129,0.581864,0.00581864,-0.121769,0.460211,0.00460211,-0.64672,,7034.509442
4839,44655.41129,1209.772853,58352447,30.934414,-0.646362,-0.644892,22.317796,0.711592,44.875178,0.583432,0.00583432,-0.125125,0.458268,0.00458268,-0.645728,,5844.011289
4848,44655.41132,1212.022853,58352449,31.053979,-0.645125,-0.643873,22.320818,0.713918,45.012785,0.584928,0.00584928,-0.128855,0.456073,0.00456073,-0.644626,,5401.299301
4857,44655.41134,1214.272853,58352451,31.179787,-0.643868,-0.642789,22.323692,0.716436,45.200597,0.58673,0.0058673,-0.132584,0.454299,0.00454299,-0.643221,,4377.653761
4866,44655.41137,1216.522853,58352454,31.210742,-0.642951,-0.641737,22.326862,0.718236,45.337409,0.58837,0.0058837,-0.13678,0.45159,0.0045159,-0.642282,,3107.817118
4875,44655.4114,1218.772853,58352456,31.255541,-0.641988,-0.640981,22.330252,0.720093,45.418,0.589522,0.00589522,-0.140603,0.448919,0.00448919,-0.641325,,2610.60103
4884,44655.41142,1221.022853,58352458,31.402558,-0.640564,-0.639403,22.33379,0.722834,45.487876,0.590927,0.00590927,-0.145265,0.445653,0.00445653,-0.640322,,1315.50493
4893,44655.41145,1223.272853,58352460,31.407577,-0.639628,-0.638811,22.338066,0.724585,45.564169,0.592507,0.00592507,-0.150579,0.441862,0.00441862,-0.639171,,171.8111306
4902,44655.41147,1225.522853,58352463,31.455498,-0.638436,-0.637628,22.342046,0.72693,45.646489,0.5942,0.005942,-0.155987,0.438244,0.00438244,-0.637964,,-1992.863801
4911,44655.4115,1227.772853,58352465,31.604388,-0.636832,-0.636247,22.347205,0.730047,45.816985,0.596087,0.00596087,-0.162047,0.43404,0.0043404,-0.636609,,-4116.096825
4920,44655.41153,1230.022853,58352467,31.595251,-0.635851,-0.635557,22.352144,0.731811,45.827106,0.597451,0.00597451,-0.168574,0.428877,0.00428877,-0.63555,,-5289.948056
4929,44655.41155,1232.272853,58352469,31.64134,-0.634609,-0.634374,22.357746,0.73421,45.919295,0.599181,0.00599181,-0.175474,0.423602,0.00423602,-0.634462,,-8015.21216
4938,44655.41158,1234.522853,58352472,31.635641,-0.633596,-0.633618,22.363643,0.736077,45.869069,0.600439,0.00600439,-0.182933,0.417385,0.00417385,-0.63357,,-11520.05789
4947,44655.4116,1236.772853,58352474,31.698123,-0.632134,-0.632106,22.370424,0.738879,45.948128,0.602245,0.00602245,-0.191604,0.41074,0.0041074,-0.632184,,-16753.50028
4956,44655.41163,1239.022853,58352476,31.696948,-0.630945,-0.630758,22.378163,0.74105,45.953641,0.603932,0.00603932,-0.201114,0.402818,0.00402818,-0.630965,,-20851.1665
4965,44655.41166,1241.272853,58352478,31.606948,-0.630095,-0.630199,22.385976,0.742736,45.852654,0.604949,0.00604949,-0.21137,0.393579,0.00393579,-0.630286,,-26503.05015
4974,44655.41168,1243.522853,58352481,31.606642,-0.62868,-0.629115,22.396148,0.745447,45.874072,0.606992,0.00606992,-0.223678,0.383408,0.00383408,-0.628819,,-24768.28179
4983,44655.41171,1245.772853,58352483,31.543564,-0.627499,-0.627668,22.406467,0.747672,45.72001,0.608573,0.00608573,-0.236824,0.37167,0.0037167,-0.627639,,-36795.66073
4992,44655.41173,1248.022853,58352485,31.444965,-0.626276,-0.626584,22.418924,0.750199,45.594516,0.61017,0.0061017,-0.252675,0.357438,0.00357438,-0.626466,,-46325.65492
5001,44655.41176,1250.272853,58352487,31.251918,-0.625406,-0.625795,22.432192,0.752007,45.304394,0.611366,0.00611366,-0.269457,0.341908,0.00341908,-0.625529,,7410.355499
5010,44655.41179,1252.522853,58352490,31.121957,-0.62396,-0.62425,22.447892,0.754719,45.107905,0.613314,0.00613314,-0.289224,0.324069,0.00324069,-0.624181,,7354.781564
5019,44655.41181,1254.772853,58352492,30.949143,-0.622776,-0.623395,22.462928,0.756862,44.90036,0.61497,0.0061497,-0.308244,0.306725,0.00306725,-0.623043,,7301.227702
5028,44655.41184,1257.022853,58352494,30.718571,-0.621603,-0.622508,22.480176,0.758975,44.553583,0.61622,0.0061622,-0.329782,0.286624,0.00286624,-0.622166,,7230.142319
5037,44655.41186,1259.272853,58352496,30.30307,-0.621364,-0.622343,22.498014,0.759346,43.998442,0.616677,0.00616677,-0.352439,0.264238,0.00264238,-0.621971,,7134.762931
5046,44655.41189,1261.522853,58352499,29.993257,-0.621201,-0.622343,22.512534,0.759522,43.526242,0.616701,0.00616701,-0.372019,0.244682,0.00244682,-0.621832,,7057.916559
5055,44655.41192,1263.772853,58352501,29.781539,-0.620876,-0.622278,22.524107,0.759985,43.209836,0.617091,0.00617091,-0.385446,0.231612,0.00231612,-0.621484,,7002.182174
5064,44655.41194,1266.022853,58352503,29.513907,-0.620883,-0.622672,22.533099,0.759676,42.77671,0.616555,0.00616555,-0.397007,0.219434,0.00219434,-0.621724,,6938.020128
5073,44655.41197,1268.272853,58352505,29.460618,-0.619827,-0.622705,22.54364,0.761563,42.93482,0.618859,0.00618859,-0.410899,0.20796,0.0020796,-0.62044,,6937.738645
5082,44655.41199,1270.522853,58352508,29.197357,-0.619849,-0.622475,22.551526,0.761064,42.353575,0.617722,0.00617722,-0.420596,0.197082,0.00197082,-0.620989,,6856.413565
5091,44655.41202,1272.772853,58352510,28.951184,-0.619175,-0.622705,22.561846,0.761478,42.004741,0.617919,0.00617919,-0.433183,0.18486,0.0018486,-0.620942,,
5097,44655.41204,1274.272853,58352511,27.547533,-0.624156,-0.630692,22.566121,0.750812,41.764657,0.617359,0.00617359,-0.4426,0.174759,0.00174759,-0.623716,,