File: PB3_UCS_8422.csv
Index,Date,Time,Counter,Force(kN),LVDT1,LVDT2,Chain,OutputPower,Stress [MPa],Strain Ax. [%],Strain Ax [-],Strain Rad. [%],Strain Vol. [%],Gemidd
0,44659.50572,0,58380692,-0.30515,-0.128089,-0.102014,22.16743,1.773619,-0.441058,1.357807,0.01357807,0.008745,1.366506,-0.115052
7,44659.50574,1.733478,58380693,-0.307663,-0.128071,-0.10185,22.167651,1.77368,-0.444111,1.357957,0.01357957,0.008373,1.366349,-0.114974
14,44659.50576,3.483478,58380695,-0.306997,-0.12806,-0.10185,22.167651,1.773714,-0.444686,1.357976,0.01357976,0.008745,1.366721,-0.114933
21,44659.50578,5.233478,58380697,-0.309142,-0.128079,-0.101751,22.167651,1.773708,-0.452467,1.358,0.01358,0.008559,1.366559,-0.115022
28,44659.5058,6.983478,58380698,-0.307987,-0.128065,-0.101685,22.167725,1.773665,-0.444599,1.35803,0.0135803,0.008466,1.366496,-0.115007
35,44659.50582,8.733478,58380700,-0.304637,-0.128076,-0.101685,22.167651,1.773728,-0.442687,1.357971,0.01357971,0.008466,1.366551,-0.114987
42,44659.50584,10.483478,58380702,-0.298571,-0.127843,-0.101587,22.167725,1.774019,-0.441551,1.358156,0.01358156,0.008559,1.366759,-0.114841
49,44659.50586,12.233478,58380704,-0.300716,-0.127832,-0.101652,22.167577,1.773981,-0.439992,1.358282,0.01358282,0.008652,1.366934,-0.114719
56,44659.50588,13.983478,58380705,-0.303534,-0.127818,-0.101817,22.167725,1.774028,-0.433319,1.358139,0.01358139,0.008559,1.366748,-0.114784
63,44659.5059,15.733478,58380707,-0.299162,-0.127661,-0.101685,22.16743,1.774359,-0.43295,1.35832,0.0135832,0.008652,1.366919,-0.114693
70,44659.50592,17.483478,58380709,-0.281526,-0.126366,-0.100995,22.167725,1.776066,-0.410581,1.359552,0.01359552,0.008373,1.367945,-0.113831
77,44659.50594,19.233478,58380711,-0.274158,-0.125178,-0.100732,22.167577,1.777715,-0.389896,1.360981,0.01360981,0.008745,1.369686,-0.112812
84,44659.50596,20.983478,58380712,-0.257089,-0.124028,-0.09991,22.167725,1.779549,-0.374589,1.362171,0.01362171,0.008373,1.37055,-0.111999
91,44659.50598,22.733478,58380714,-0.244082,-0.122885,-0.099483,22.167577,1.78128,-0.35049,1.36347,0.0136347,0.008652,1.372122,-0.11104
98,44659.506,24.483478,58380716,-0.228325,-0.121792,-0.098793,22.167725,1.783134,-0.334251,1.364566,0.01364566,0.008652,1.37319,-0.110318
105,44659.50602,26.233478,58380718,-0.211676,-0.120681,-0.097938,22.167651,1.784823,-0.310488,1.365806,0.01365806,0.008559,1.374361,-0.109429
112,44659.50604,27.983478,58380719,-0.203674,-0.119414,-0.097346,22.167725,1.786899,-0.290504,1.367428,0.01367428,0.008559,1.37589,-0.108302
119,44659.50606,29.733478,58380721,-0.18753,-0.118504,-0.09659,22.167651,1.788375,-0.271426,1.36846,0.0136846,0.008466,1.37694,-0.107618
126,44659.50608,31.483478,58380723,-0.174747,-0.11744,-0.095933,22.167651,1.790131,-0.253885,1.36964,0.0136964,0.008466,1.378026,-0.106775
133,44659.5061,33.233478,58380725,-0.158987,-0.116392,-0.095374,22.167798,1.79186,-0.234828,1.370824,0.01370824,0.008466,1.37929,-0.105954
140,44659.50612,34.983478,58380726,-0.138205,-0.115319,-0.094684,22.167651,1.793599,-0.208056,1.372146,0.01372146,0.008466,1.380643,-0.105
147,44659.50614,36.733478,58380728,-0.124045,-0.114246,-0.093764,22.167872,1.795454,-0.185088,1.373509,0.01373509,0.008373,1.381925,-0.104038
154,44659.50616,38.483478,58380730,-0.105975,-0.113171,-0.093369,22.167577,1.797133,-0.160014,1.374588,0.01374588,0.008466,1.383054,-0.103186
161,44659.50618,40.233478,58380732,-0.091835,-0.112053,-0.092712,22.168019,1.798977,-0.137965,1.375923,0.01375923,0.00828,1.384265,-0.102271
168,44659.5062,41.983478,58380733,-0.073837,-0.110985,-0.091989,22.167577,1.800635,-0.113213,1.377176,0.01377176,0.008187,1.385422,-0.101503
175,44659.50622,43.733478,58380735,-0.05667,-0.10993,-0.0912,22.167946,1.802481,-0.076744,1.378362,0.01378362,0.008466,1.386921,-0.100673
182,44659.50624,45.483478,58380737,-0.038843,-0.108915,-0.090608,22.167725,1.804214,-0.055893,1.379659,0.01379659,0.008187,1.388044,-0.099627
189,44659.50626,47.233478,58380739,-0.015631,-0.108001,-0.089819,22.168019,1.805932,-0.017219,1.380949,0.01380949,0.008373,1.389184,-0.098864
196,44659.50629,48.983478,58380740,0.006822,-0.107125,-0.088669,22.167798,1.807576,0.022188,1.382264,0.01382264,0.008187,1.390465,-0.097944
203,44659.50631,50.733478,58380742,0.039374,-0.10633,-0.087617,22.168019,1.80946,0.051566,1.383389,0.01383389,0.008187,1.391734,-0.097037
210,44659.50633,52.483478,58380744,0.061027,-0.105596,-0.086828,22.167798,1.811142,0.083862,1.384648,0.01384648,0.008373,1.392937,-0.096276
217,44659.50635,54.233478,58380746,0.093551,-0.104898,-0.085612,22.168019,1.81293,0.128174,1.385854,0.01385854,0.00828,1.394225,-0.095264
224,44659.50637,55.983478,58380747,0.126813,-0.104203,-0.084724,22.167798,1.814741,0.170503,1.38721,0.0138721,0.008094,1.395304,-0.094484
231,44659.50639,57.733478,58380749,0.15003,-0.103566,-0.083705,22.168093,1.816424,0.209793,1.388426,0.01388426,0.008094,1.396516,-0.093633
238,44659.50641,59.483478,58380751,0.179833,-0.102925,-0.082686,22.167872,1.818123,0.257201,1.389711,0.01389711,0.00828,1.397865,-0.092823
245,44659.50643,61.233478,58380753,0.209171,-0.102326,-0.081635,22.168093,1.819819,0.306709,1.390868,0.01390868,0.008187,1.399041,-0.091912
252,44659.50645,62.983478,58380754,0.245865,-0.101712,-0.080155,22.168093,1.821645,0.357459,1.392099,0.01392099,0.008094,1.400193,-0.091074
259,44659.50647,64.733478,58380756,0.288651,-0.101,-0.078972,22.168093,1.823686,0.411249,1.393721,0.01393721,0.008094,1.40174,-0.08992
266,44659.50649,66.483478,58380758,0.326016,-0.100414,-0.077855,22.168019,1.825412,0.461246,1.394972,0.01394972,0.008094,1.403048,-0.089067
273,44659.50651,68.233478,58380760,0.361493,-0.099794,-0.07654,22.168167,1.827144,0.513617,1.396277,0.01396277,0.007908,1.404266,-0.088293
280,44659.50653,69.983478,58380761,0.389512,-0.09935,-0.075784,22.168241,1.828643,0.558843,1.397233,0.01397233,0.007722,1.404955,-0.087473
287,44659.50655,71.733478,58380763,0.426515,-0.098782,-0.07414,22.168093,1.830273,0.612269,1.398397,0.01398397,0.008094,1.406457,-0.086683
294,44659.50657,73.483478,58380765,0.463671,-0.098237,-0.073483,22.168167,1.832031,0.671891,1.399764,0.01399764,0.007722,1.407522,-0.085678
301,44659.50659,75.233478,58380767,0.506505,-0.097681,-0.071905,22.168093,1.833887,0.730292,1.400896,0.01400896,0.007722,1.408666,-0.084877
308,44659.50661,76.983478,58380768,0.541946,-0.097153,-0.070755,22.168314,1.835609,0.783899,1.402107,0.01402107,0.007722,1.409808,-0.084013
315,44659.50663,78.733478,58380770,0.589235,-0.096608,-0.06944,22.168019,1.837298,0.849712,1.403439,0.01403439,0.007815,1.411252,-0.083039
322,44659.50665,80.483478,58380772,0.632612,-0.096043,-0.068289,22.168314,1.839028,0.911308,1.404625,0.01404625,0.007722,1.412354,-0.082302
329,44659.50667,82.233478,58380774,0.67089,-0.095524,-0.067303,22.168167,1.840901,0.970698,1.405955,0.01405955,0.007629,1.413523,-0.081417
336,44659.50669,83.983478,58380775,0.721625,-0.095009,-0.06589,22.168535,1.842592,1.039019,1.407252,0.01407252,0.007629,1.414931,-0.080465
343,44659.50671,85.733478,58380777,0.763522,-0.094425,-0.064707,22.168314,1.844455,1.104345,1.408501,0.01408501,0.007629,1.416054,-0.079589
350,44659.50673,87.483478,58380779,0.810448,-0.093864,-0.063458,22.168609,1.846173,1.170252,1.409667,0.01409667,0.007629,1.417296,-0.078644
357,44659.50675,89.233478,58380781,0.854133,-0.093356,-0.062143,22.168462,1.847909,1.237298,1.411066,0.01411066,0.007443,1.418584,-0.077744
364,44659.50677,90.983478,58380782,0.904577,-0.092827,-0.060927,22.168683,1.849624,1.309046,1.41236,0.0141236,0.007536,1.419896,-0.076869
371,44659.50679,92.733478,58380784,0.958283,-0.092295,-0.060006,22.168535,1.85146,1.376734,1.413518,0.01413518,0.007257,1.420789,-0.07611
378,44659.50681,94.483478,58380786,1.002059,-0.091772,-0.058461,22.168609,1.853075,1.450964,1.414723,0.01414723,0.007536,1.422237,-0.07517
385,44659.50683,96.233478,58380788,1.06075,-0.091298,-0.057344,22.168609,1.854944,1.532391,1.415956,0.01415956,0.007071,1.423025,-0.074376
392,44659.50685,97.983478,58380789,1.11764,-0.090777,-0.05593,22.168757,1.856705,1.608741,1.41727,0.0141727,0.00735,1.424583,-0.073483
399,44659.50687,99.733478,58380791,1.165973,-0.090308,-0.054944,22.168757,1.858465,1.691697,1.418475,0.01418475,0.007071,1.425513,-0.072614
406,44659.50689,101.483478,58380793,1.225131,-0.089801,-0.053465,22.168757,1.860045,1.771361,1.41983,0.0141983,0.007164,1.426994,-0.071726
413,44659.50691,103.233478,58380795,1.278339,-0.089349,-0.052183,22.168978,1.861921,1.84132,1.420914,0.01420914,0.007164,1.428031,-0.070941
420,44659.50693,104.983478,58380796,1.336508,-0.088892,-0.051131,22.16883,1.863702,1.925958,1.422275,0.01422275,0.006884,1.429159,-0.070016
427,44659.50695,106.733478,58380798,1.391959,-0.088407,-0.049849,22.169125,1.865355,2.010881,1.423486,0.01423486,0.006884,1.430371,-0.069143
434,44659.50697,108.483478,58380800,1.453294,-0.087979,-0.048305,22.168904,1.867206,2.096649,1.424656,0.01424656,0.006884,1.431541,-0.06828
441,44659.50699,110.233478,58380802,1.514971,-0.087515,-0.04722,22.169272,1.868977,2.18802,1.4261,0.014261,0.006884,1.432985,-0.067245
448,44659.50701,111.983478,58380803,1.582054,-0.087078,-0.045971,22.168978,1.870777,2.276229,1.427171,0.01427171,0.006698,1.433873,-0.066529
455,44659.50703,113.733478,58380805,1.625395,-0.086752,-0.044656,22.169272,1.872009,2.347983,1.428305,0.01428305,0.006698,1.435004,-0.065738
462,44659.50705,115.483478,58380807,1.682032,-0.086285,-0.043473,22.169051,1.873932,2.429577,1.429481,0.01429481,0.006605,1.436131,-0.064885
469,44659.50708,117.233478,58380809,1.751192,-0.085834,-0.042388,22.169272,1.875546,2.524889,1.430765,0.01430765,0.006605,1.437371,-0.064075
476,44659.5071,118.983478,58380810,1.813822,-0.085406,-0.040744,22.169199,1.877212,2.618443,1.432,0.01432,0.006512,1.438512,-0.063258
483,44659.50712,120.733478,58380812,1.879544,-0.084949,-0.039463,22.16942,1.87892,2.713142,1.433185,0.01433185,0.006605,1.43979,-0.062325
490,44659.50714,122.483478,58380814,1.963421,-0.084467,-0.037918,22.16942,1.880963,2.822457,1.434652,0.01434652,0.006512,1.441006,-0.061298
497,44659.50716,124.233478,58380816,2.025313,-0.083968,-0.036899,22.169567,1.882707,2.922174,1.43593,0.0143593,0.006047,1.441991,-0.060395
504,44659.50718,125.983478,58380817,2.084651,-0.083536,-0.035617,22.169567,1.88447,3.016417,1.437124,0.01437124,0.005954,1.443159,-0.05957
511,44659.5072,127.733478,58380819,2.152557,-0.083064,-0.034368,22.169715,1.886352,3.111634,1.438425,0.01438425,0.006047,1.444472,-0.05866
518,44659.50722,129.483478,58380821,2.223566,-0.082624,-0.033119,22.169715,1.88786,3.206137,1.439648,0.01439648,0.005861,1.445539,-0.057804
525,44659.50724,131.233478,58380823,2.284505,-0.082226,-0.031935,22.169788,1.889432,3.299706,1.440772,0.01440772,0.005954,1.446726,-0.056992
532,44659.50726,132.983478,58380824,2.379226,-0.081694,-0.029996,22.169936,1.89172,3.436701,1.442417,0.01442417,0.005768,1.448185,-0.05598
539,44659.50728,134.733478,58380826,2.451264,-0.081276,-0.028484,22.169862,1.893576,3.53661,1.443526,0.01443526,0.005582,1.449265,-0.055091
546,44659.5073,136.483478,58380828,2.511757,-0.080879,-0.027531,22.170157,1.89491,3.625132,1.444566,0.01444566,0.005582,1.450148,-0.05421
553,44659.50732,138.233478,58380830,2.5837,-0.080461,-0.026413,22.169936,1.896703,3.726349,1.445955,0.01445955,0.005489,1.451444,-0.053484
560,44659.50734,139.983478,58380831,2.674063,-0.079943,-0.024671,22.170304,1.898975,3.862376,1.447304,0.01447304,0.005303,1.452607,-0.052448
567,44659.50736,141.733478,58380833,2.753065,-0.079486,-0.023554,22.170083,1.900624,3.971887,1.448656,0.01448656,0.005396,1.454052,-0.051473
574,44659.50738,143.483478,58380835,2.825463,-0.079058,-0.022337,22.170452,1.90221,4.07424,1.449895,0.01449895,0.004931,1.454826,-0.050636
581,44659.5074,145.233478,58380837,2.926301,-0.078524,-0.02076,22.170378,1.904416,4.238514,1.451508,0.01451508,0.00521,1.456718,-0.049508
588,44659.50742,146.983478,58380838,2.990683,-0.078096,-0.019445,22.170673,1.905946,4.316345,1.45253,0.0145253,0.004745,1.457275,-0.048854
595,44659.50744,148.733478,58380840,3.074752,-0.077697,-0.017999,22.170526,1.907723,4.438011,1.453701,0.01453701,0.004559,1.458297,-0.047948
602,44659.50746,150.483478,58380842,3.124407,-0.077326,-0.017407,22.170747,1.908988,4.513775,1.454687,0.01454687,0.004838,1.459479,-0.047267
609,44659.50748,152.233478,58380844,3.214944,-0.076842,-0.016092,22.17082,1.910885,4.636958,1.455892,0.01455892,0.004559,1.460358,-0.046441
616,44659.5075,153.983478,58380845,3.297011,-0.076391,-0.014744,22.170968,1.912647,4.767285,1.457076,0.01457076,0.004373,1.461448,-0.045613
623,44659.50752,155.733478,58380847,3.382904,-0.075908,-0.013265,22.170968,1.914477,4.884071,1.458447,0.01458447,0.00428,1.462711,-0.044654
630,44659.50754,157.483478,58380849,3.463958,-0.07546,-0.012115,22.171189,1.916018,5.000158,1.459697,0.01459697,0.00428,1.463911,-0.043825
637,44659.50756,159.233478,58380851,3.550462,-0.074997,-0.010603,22.171263,1.917885,5.131817,1.460852,0.01460852,0.004093,1.464945,-0.042901
644,44659.50758,160.983478,58380852,3.640445,-0.074546,-0.009222,22.171263,1.919698,5.24991,1.462216,0.01462216,0.003907,1.466124,-0.042069
651,44659.5076,162.733478,58380854,3.722393,-0.074085,-0.008335,22.171484,1.921359,5.371765,1.463323,0.01463323,0.003814,1.467125,-0.041097
658,44659.50762,164.483478,58380856,3.811195,-0.073586,-0.006757,22.171484,1.923059,5.508221,1.464738,0.01464738,0.003721,1.468459,-0.04024
665,44659.50764,166.233478,58380858,3.907792,-0.073156,-0.005639,22.171852,1.924951,5.643118,1.466055,0.01466055,0.003349,1.469455,-0.039297
672,44659.50766,167.983478,58380859,3.994011,-0.072682,-0.004292,22.171705,1.92664,5.764289,1.467138,0.01467138,0.003163,1.470307,-0.038571
679,44659.50768,169.733478,58380861,4.083773,-0.072177,-0.00324,22.172073,1.92827,5.893546,1.468461,0.01468461,0.003349,1.47181,-0.037621
686,44659.5077,171.483478,58380863,4.17674,-0.071703,-0.001925,22.171852,1.930075,6.030073,1.469612,0.01469612,0.003163,1.47284,-0.036844
693,44659.50772,173.233478,58380865,4.271215,-0.071204,-0.000446,22.172368,1.931905,6.162911,1.470861,0.01470861,0.002791,1.473792,-0.035982
700,44659.50774,174.983478,58380866,4.355395,-0.070742,0.000803,22.172147,1.93355,6.292324,1.472097,0.01472097,0.002884,1.474981,-0.035077
707,44659.50776,176.733478,58380868,4.482205,-0.07016,0.002381,22.172442,1.935819,6.471557,1.473676,0.01473676,0.002512,1.476126,-0.034001
714,44659.50778,178.483478,58380870,4.56269,-0.069737,0.003367,22.172442,1.937262,6.580661,1.474786,0.01474786,0.002419,1.477205,-0.033225
721,44659.5078,180.233478,58380872,4.63797,-0.069351,0.004386,22.172737,1.938773,6.691827,1.475828,0.01475828,0.002326,1.47807,-0.032443
728,44659.50782,181.983478,58380873,4.735615,-0.068879,0.005734,22.172737,1.940594,6.838752,1.476972,0.01476972,0.002047,1.479019,-0.031563
735,44659.50784,183.733478,58380875,4.83933,-0.068387,0.007081,22.172958,1.942357,6.990821,1.47828,0.0147828,0.001861,1.48014,-0.030763
742,44659.50787,185.483478,58380877,4.94359,-0.067874,0.00833,22.173032,1.944202,7.129031,1.47972,0.0147972,0.001675,1.481395,-0.029773
749,44659.50789,187.233478,58380879,5.012954,-0.067511,0.009119,22.173179,1.945438,7.241282,1.480661,0.01480661,0.001396,1.48211,-0.029078
756,44659.50791,188.983478,58380880,5.116303,-0.067026,0.010368,22.173326,1.947243,7.388753,1.481787,0.01481787,0.001582,1.483351,-0.02834
763,44659.50793,190.733478,58380882,5.21559,-0.066531,0.011617,22.1734,1.948833,7.526268,1.483081,0.01483081,0.001023,1.484203,-0.027353
770,44659.50795,192.483478,58380884,5.315128,-0.066064,0.013064,22.173695,1.950632,7.676522,1.484264,0.01484264,0.00093,1.485149,-0.026627
777,44659.50797,194.233478,58380886,5.418499,-0.065537,0.014214,22.173548,1.952392,7.814154,1.485526,0.01485526,0.001023,1.486549,-0.025712
784,44659.50799,195.983478,58380887,5.586612,-0.064738,0.015923,22.174064,1.954996,8.064692,1.487382,0.01487382,0.000558,1.488005,-0.024414
791,44659.50801,197.733478,58380889,5.68403,-0.064266,0.017402,22.174064,1.956831,8.201254,1.488605,0.01488605,0.000372,1.488926,-0.023471
798,44659.50803,199.483478,58380891,5.78621,-0.063767,0.018553,22.174358,1.958457,8.3603,1.48995,0.0148995,0.000279,1.490136,-0.022736
805,44659.50805,201.233478,58380893,5.896492,-0.063242,0.01967,22.174211,1.960164,8.524017,1.491146,0.01491146,0.000093,1.491238,-0.021717
812,44659.50807,202.983478,58380894,6.002372,-0.062753,0.020985,22.174653,1.962057,8.670276,1.492245,0.01492245,-0.000093,1.492152,-0.021012
819,44659.50809,204.733478,58380896,6.069197,-0.062413,0.021807,22.174506,1.962963,8.76158,1.493213,0.01493213,-0.000186,1.492975,-0.020312
826,44659.50811,206.483478,58380898,6.187195,-0.061885,0.02276,22.174727,1.964827,8.935741,1.49437,0.0149437,-0.000651,1.493834,-0.019445
833,44659.50813,208.233478,58380900,6.295141,-0.06137,0.024206,22.175095,1.966551,9.091044,1.49548,0.0149548,-0.000558,1.494894,-0.018651
840,44659.50815,209.983478,58380901,6.401271,-0.060869,0.02516,22.175022,1.968151,9.245656,1.496728,0.01496728,-0.00093,1.495891,-0.01777
847,44659.50817,211.733478,58380903,6.515772,-0.060307,0.026507,22.175611,1.969986,9.415259,1.498066,0.01498066,-0.001023,1.496963,-0.016875
854,44659.50819,213.483478,58380905,6.638509,-0.059822,0.027493,22.175464,1.971722,9.584022,1.499175,0.01499175,-0.001302,1.497872,-0.016165
861,44659.50821,215.233478,58380907,6.783792,-0.059165,0.02917,22.175759,1.97366,9.769524,1.50063,0.0150063,-0.001489,1.499142,-0.015147
868,44659.50823,216.983478,58380908,6.938616,-0.058395,0.030517,22.175833,1.97607,10.01989,1.502352,0.01502352,-0.001675,1.500678,-0.013984
875,44659.50825,218.733478,58380910,7.080629,-0.057766,0.031799,22.176127,1.977872,10.217875,1.503639,0.01503639,-0.002233,1.501443,-0.013017
882,44659.50827,220.483478,58380912,7.190626,-0.057203,0.032818,22.176275,1.97953,10.387572,1.504869,0.01504869,-0.002512,1.502443,-0.012122
889,44659.50829,222.233478,58380914,7.29642,-0.056639,0.033969,22.176422,1.981257,10.542294,1.505984,0.01505984,-0.002512,1.503473,-0.011401
896,44659.50831,223.983478,58380915,7.412377,-0.056055,0.035382,22.176717,1.983085,10.708322,1.507265,0.01507265,-0.002791,1.504509,-0.010506
903,44659.50833,225.733478,58380917,7.528967,-0.055522,0.036204,22.176791,1.984711,10.876299,1.508462,0.01508462,-0.00307,1.505391,-0.009565
910,44659.50835,227.483478,58380919,7.639174,-0.054955,0.037617,22.177233,1.986486,11.037341,1.509673,0.01509673,-0.003256,1.506416,-0.008822
917,44659.50837,229.233478,58380921,7.769016,-0.054398,0.038636,22.177233,1.988168,11.225251,1.510952,0.01510952,-0.003535,1.507345,-0.007927
924,44659.50839,230.983478,58380922,7.884411,-0.053777,0.039787,22.177528,1.989936,11.389532,1.512156,0.01512156,-0.004093,1.508235,-0.007084
931,44659.50841,232.733478,58380924,8.000277,-0.053232,0.041036,22.177675,1.991644,11.551802,1.513447,0.01513447,-0.004187,1.50926,-0.006182
938,44659.50843,234.483478,58380926,8.124073,-0.052653,0.042219,22.17797,1.993241,11.73818,1.514676,0.01514676,-0.00428,1.51039,-0.005267
945,44659.50845,236.233478,58380928,8.257578,-0.052004,0.043205,22.178118,1.995107,11.920991,1.516024,0.01516024,-0.004652,1.511372,-0.004327
952,44659.50847,237.983478,58380929,8.370511,-0.051411,0.044389,22.178265,1.996963,12.093,1.517135,0.01517135,-0.004838,1.512288,-0.003556
959,44659.50849,239.733478,58380931,8.491509,-0.050822,0.045375,22.178707,1.998654,12.270802,1.518415,0.01518415,-0.005024,1.513356,-0.002707
966,44659.50851,241.483478,58380933,8.561883,-0.050456,0.046131,22.178486,1.999714,12.373341,1.519192,0.01519192,-0.005303,1.513931,-0.002134
973,44659.50853,243.233478,58380935,8.691241,-0.049827,0.047281,22.178928,2.001546,12.557181,1.520519,0.01520519,-0.005396,1.515123,-0.001235
980,44659.50855,244.983478,58380936,8.825192,-0.049244,0.048464,22.178928,2.003127,12.752888,1.521649,0.01521649,-0.005675,1.515963,-0.000452
987,44659.50857,246.733478,58380938,8.956973,-0.048574,0.049516,22.179371,2.005063,12.933473,1.52301,0.0152301,-0.006233,1.516687,0.000508
994,44659.50859,248.483478,58380940,9.150768,-0.047721,0.051357,22.179592,2.007424,13.189551,1.524702,0.01524702,-0.006419,1.518179,0.001731
1001,44659.50861,250.233478,58380942,9.277794,-0.047032,0.052343,22.179887,2.0095,13.403848,1.526123,0.01526123,-0.006791,1.519322,0.002686
1008,44659.50863,251.983478,58380943,9.400813,-0.046409,0.053461,22.180181,2.011044,13.582933,1.527281,0.01527281,-0.007164,1.520174,0.003495
1015,44659.50866,253.733478,58380945,9.502389,-0.045921,0.054545,22.180329,2.01255,13.729388,1.528369,0.01528369,-0.007443,1.520926,0.00424
1022,44659.50868,255.483478,58380947,9.655324,-0.045255,0.055663,22.180697,2.014481,13.962923,1.529771,0.01529771,-0.007722,1.52205,0.005237
1029,44659.5087,257.233478,58380949,9.792056,-0.044533,0.056715,22.180624,2.016231,14.13902,1.531037,0.01531037,-0.008187,1.52285,0.006079
1036,44659.50872,258.983478,58380950,9.925763,-0.043856,0.057931,22.181287,2.018069,14.342775,1.532258,0.01532258,-0.008187,1.524016,0.007058
1043,44659.50874,260.733478,58380952,10.070526,-0.043154,0.059049,22.181213,2.019989,14.546387,1.533625,0.01533625,-0.009024,1.524601,0.007914
1050,44659.50876,262.483478,58380954,10.202369,-0.042503,0.060265,22.181729,2.021828,14.732143,1.534791,0.01534791,-0.008745,1.525963,0.008783
1057,44659.50878,264.233478,58380956,10.324842,-0.04183,0.061317,22.181803,2.023586,14.91615,1.536111,0.01536111,-0.009489,1.526622,0.009672
1064,44659.5088,265.983478,58380957,10.458376,-0.041157,0.062434,22.182172,2.025258,15.116608,1.537331,0.01537331,-0.009769,1.527597,0.01055
1071,44659.50882,267.733478,58380959,10.597728,-0.040513,0.063256,22.182319,2.027106,15.307379,1.538645,0.01538645,-0.009955,1.528621,0.011396
1078,44659.50884,269.483478,58380961,10.666533,-0.040075,0.064209,22.182614,2.028137,15.409487,1.539329,0.01539329,-0.010234,1.529118,0.012004
1085,44659.50886,271.233478,58380963,10.801668,-0.039449,0.065162,22.182835,2.029788,15.601352,1.540582,0.01540582,-0.010606,1.529936,0.012772
1092,44659.50888,272.983478,58380964,10.945772,-0.038727,0.06605,22.182982,2.031725,15.81466,1.541901,0.01541901,-0.010885,1.531016,0.013762
1099,44659.5089,274.733478,58380966,11.077766,-0.038076,0.067266,22.183351,2.033299,15.998059,1.543006,0.01543006,-0.011164,1.53188,0.014522
1106,44659.50892,276.483478,58380968,11.287384,-0.036997,0.068811,22.183719,2.03587,16.302304,1.545004,0.01545004,-0.011722,1.533247,0.0159
1113,44659.50894,278.233478,58380970,11.420569,-0.036334,0.069863,22.184162,2.037652,16.492704,1.546243,0.01546243,-0.012094,1.534191,0.016743
1120,44659.50896,279.983478,58380971,11.560519,-0.03564,0.070947,22.184235,2.039212,16.694213,1.547433,0.01547433,-0.01256,1.534901,0.017552
1127,44659.50898,281.733478,58380973,11.693646,-0.034901,0.072098,22.184678,2.041064,16.890326,1.548723,0.01548723,-0.012653,1.536003,0.018505
1134,44659.509,283.483478,58380975,11.827892,-0.034193,0.073117,22.184751,2.042789,17.091684,1.549933,0.01549933,-0.013304,1.536667,0.01934
1141,44659.50902,285.233478,58380977,11.961468,-0.03354,0.07384,22.185267,2.044388,17.278729,1.551114,0.01551114,-0.013676,1.537606,0.020165
1148,44659.50904,286.983478,58380978,12.086557,-0.032815,0.075056,22.185267,2.046182,17.468737,1.552313,0.01552313,-0.013676,1.538601,0.021026
1155,44659.50906,288.733478,58380980,12.216652,-0.032158,0.075944,22.185931,2.047801,17.652619,1.553551,0.01553551,-0.014048,1.539488,0.021944
1162,44659.50908,290.483478,58380982,12.374692,-0.031378,0.077094,22.185857,2.049642,17.865333,1.554851,0.01554851,-0.014699,1.540305,0.022888
1169,44659.5091,292.233478,58380984,12.521171,-0.030706,0.078179,22.186373,2.051412,18.088854,1.556049,0.01556049,-0.014792,1.541257,0.023711
1176,44659.50912,293.983478,58380985,12.651551,-0.029961,0.079132,22.186447,2.053182,18.267668,1.557261,0.01557261,-0.015351,1.541911,0.024463
1183,44659.50914,295.733478,58380987,12.795074,-0.02924,0.080052,22.186963,2.054898,18.479379,1.55854,0.0155854,-0.01563,1.542799,0.02546
1190,44659.50916,297.483478,58380989,12.935763,-0.028514,0.081302,22.187184,2.056622,18.684736,1.559821,0.01559821,-0.016002,1.543819,0.026304
1197,44659.50918,299.233478,58380991,13.073758,-0.027811,0.082189,22.1877,2.058291,18.882891,1.561065,0.01561065,-0.016467,1.544691,0.027204
1204,44659.5092,300.983478,58380992,13.191353,-0.02715,0.083142,22.1877,2.059811,19.074954,1.562307,0.01562307,-0.016932,1.545377,0.027996
1211,44659.50922,302.733478,58380994,13.354074,-0.026344,0.084424,22.187995,2.061795,19.286802,1.563481,0.01563481,-0.017211,1.54627,0.028818
1218,44659.50924,304.483478,58380996,13.500327,-0.025598,0.08518,22.188216,2.063507,19.511645,1.564903,0.01564903,-0.017769,1.547145,0.029885
1225,44659.50926,306.233478,58380998,13.62229,-0.024936,0.086035,22.188805,2.064994,19.66482,1.565873,0.01565873,-0.017955,1.547992,0.030607
1232,44659.50928,307.983478,58380999,13.771936,-0.024172,0.086988,22.1891,2.066965,19.876055,1.56719,0.0156719,-0.018607,1.548584,0.031438
1239,44659.5093,309.733478,58381001,13.929888,-0.023374,0.088204,22.189321,2.068784,20.128414,1.568526,0.01568526,-0.0187,1.549814,0.032346
1246,44659.50932,311.483478,58381003,14.071717,-0.022656,0.089092,22.189837,2.070521,20.318609,1.569774,0.01569774,-0.019072,1.550662,0.03327
1253,44659.50934,313.233478,58381005,14.209728,-0.021922,0.090209,22.189837,2.072435,20.533673,1.57098,0.0157098,-0.019816,1.551171,0.034068
1260,44659.50936,314.983478,58381006,14.359134,-0.021166,0.091064,22.190427,2.073928,20.749663,1.572257,0.01572257,-0.020188,1.552068,0.034969
1267,44659.50938,316.733478,58381008,14.501711,-0.020429,0.092181,22.190574,2.075811,20.945886,1.573395,0.01573395,-0.020467,1.552922,0.035752
1274,44659.5094,318.483478,58381010,14.64253,-0.019713,0.093069,22.191238,2.077538,21.145187,1.57474,0.0157474,-0.020933,1.553727,0.036702
1281,44659.50942,320.233478,58381012,14.792649,-0.01893,0.094154,22.191238,2.079222,21.380166,1.576024,0.01576024,-0.021398,1.554627,0.037591
1288,44659.50944,321.983478,58381013,14.944965,-0.018144,0.095107,22.191827,2.08103,21.589629,1.577285,0.01577285,-0.02177,1.555552,0.038473
1295,44659.50947,323.733478,58381015,15.014823,-0.017722,0.095731,22.191975,2.082082,21.695464,1.578087,0.01578087,-0.022049,1.556002,0.039009
1302,44659.50949,325.483478,58381017,15.169367,-0.01697,0.096718,22.192343,2.083801,21.926458,1.579278,0.01579278,-0.022607,1.556671,0.039868
1309,44659.50951,327.233478,58381019,15.328157,-0.016158,0.097835,22.192786,2.085731,22.143497,1.580609,0.01580609,-0.023165,1.557472,0.040779
1316,44659.50953,328.983478,58381020,15.527398,-0.015118,0.099249,22.193007,2.08801,22.435629,1.582337,0.01582337,-0.023537,1.558831,0.042029
1323,44659.50955,330.733478,58381022,15.665857,-0.014389,0.100136,22.193818,2.089756,22.629439,1.583426,0.01583426,-0.024003,1.55938,0.042739
1330,44659.50957,332.483478,58381024,15.813993,-0.013636,0.100991,22.193744,2.091475,22.840407,1.584736,0.01584736,-0.024561,1.560175,0.043685
1337,44659.50959,334.233478,58381026,15.939398,-0.01294,0.102141,22.194407,2.09306,23.005415,1.585773,0.01585773,-0.024933,1.560682,0.044428
1344,44659.50961,335.983478,58381027,16.11102,-0.012093,0.103029,22.194555,2.094959,23.264956,1.587164,0.01587164,-0.025491,1.561647,0.045365
1351,44659.50963,337.733478,58381029,16.236579,-0.011325,0.104048,22.195144,2.096766,23.46878,1.588457,0.01588457,-0.025863,1.562679,0.046348
1358,44659.50965,339.483478,58381031,16.39841,-0.010521,0.104935,22.195365,2.098447,23.687188,1.58973,0.0158973,-0.026608,1.563061,0.047199
1365,44659.50967,341.233478,58381033,16.561497,-0.009664,0.106118,22.195881,2.100401,23.926173,1.591042,0.01591042,-0.026794,1.564248,0.048067
1372,44659.50969,342.983478,58381034,16.642123,-0.009202,0.106677,22.196102,2.101353,24.051056,1.591845,0.01591845,-0.027166,1.564636,0.048661
1379,44659.50971,344.733478,58381036,16.85484,-0.008134,0.107959,22.196471,2.103892,24.344132,1.593596,0.01593596,-0.027817,1.565779,0.049888
1386,44659.50973,346.483478,58381038,16.926657,-0.007653,0.108584,22.196987,2.104903,24.454702,1.594354,0.01594354,-0.028375,1.565978,0.050413
1393,44659.50975,348.233478,58381040,17.137841,-0.006629,0.109931,22.197208,2.107233,24.777703,1.596046,0.01596046,-0.02884,1.567249,0.051583
1400,44659.50977,349.983478,58381041,17.286333,-0.005828,0.110819,22.197945,2.109142,24.97657,1.597272,0.01597272,-0.029399,1.56778,0.052386
1407,44659.50979,351.733478,58381043,17.449061,-0.004962,0.111772,22.198093,2.110951,25.208444,1.598616,0.01598616,-0.029957,1.568636,0.053394
1414,44659.50981,353.483478,58381045,17.518921,-0.004508,0.112429,22.198609,2.112088,25.315106,1.599393,0.01599393,-0.030329,1.569035,0.053938
1421,44659.50983,355.233478,58381047,17.741126,-0.003425,0.11381,22.198903,2.114524,25.635415,1.60117,0.0160117,-0.03098,1.57019,0.055181
1428,44659.50985,356.983478,58381048,17.815005,-0.002924,0.114336,22.199419,2.11556,25.732074,1.601766,0.01601766,-0.031259,1.570507,0.055655
1435,44659.50987,358.733478,58381050,18.044409,-0.001836,0.115716,22.199714,2.118002,26.069971,1.603644,0.01603644,-0.03219,1.571488,0.056911
1442,44659.50989,360.483478,58381052,18.196727,-0.001079,0.116702,22.200304,2.119764,26.283498,1.604897,0.01604897,-0.032748,1.572116,0.057788
1449,44659.50991,362.233478,58381054,18.262238,-0.000624,0.117294,22.200599,2.120687,26.392293,1.605571,0.01605571,-0.032934,1.572637,0.058287
1456,44659.50993,363.983478,58381055,18.481671,0.000469,0.118445,22.201115,2.123206,26.697905,1.607296,0.01607296,-0.033678,1.573618,0.059466
1463,44659.50995,365.733478,58381057,18.599971,0.001111,0.119595,22.201557,2.124642,26.870431,1.60838,0.0160838,-0.034236,1.574227,0.060283
1470,44659.50997,367.483478,58381059,18.717182,0.001751,0.120285,22.201778,2.126034,27.051437,1.609521,0.01609521,-0.034701,1.574763,0.061048
1477,44659.50999,369.233478,58381061,18.924826,0.002812,0.121337,22.202663,2.128345,27.343104,1.611106,0.01611106,-0.035353,1.575778,0.062131
1484,44659.51001,370.983478,58381062,19.068826,0.003571,0.12229,22.20281,2.130195,27.564259,1.612301,0.01612301,-0.035818,1.576483,0.062967
1491,44659.51003,372.733478,58381064,19.171236,0.004115,0.123178,22.2034,2.131302,27.700798,1.61319,0.0161319,-0.036562,1.576701,0.063578
1498,44659.51005,374.483478,58381066,19.380168,0.00516,0.124525,22.203768,2.133652,27.931528,1.614689,0.01614689,-0.036934,1.577755,0.064729
1505,44659.51007,376.233478,58381068,19.511672,0.005941,0.125479,22.204358,2.135371,28.198759,1.616066,0.01616066,-0.037679,1.578387,0.065607
1512,44659.51009,377.983478,58381069,19.611875,0.006436,0.126169,22.204874,2.136514,28.344258,1.616937,0.01616937,-0.038423,1.578514,0.06621
1519,44659.51011,379.733478,58381071,19.846909,0.007591,0.127451,22.20539,2.138982,28.657305,1.61863,0.0161863,-0.038981,1.579649,0.067458
1526,44659.51013,381.483478,58381073,19.969562,0.008321,0.128404,22.205906,2.140537,28.853371,1.619844,0.01619844,-0.039539,1.580237,0.068301
1533,44659.51015,383.233478,58381075,20.099462,0.009103,0.129325,22.206201,2.142305,29.041033,1.621107,0.01621107,-0.04019,1.580828,0.069148
1540,44659.51017,384.983478,58381076,20.259847,0.009843,0.130179,22.207011,2.144066,29.284818,1.622305,0.01622305,-0.040749,1.581556,0.069965
1547,44659.51019,386.733478,58381078,20.408668,0.010649,0.131198,22.207233,2.145801,29.492245,1.623619,0.01623619,-0.0414,1.582231,0.070816
1554,44659.51021,388.483478,58381080,20.490317,0.011152,0.131823,22.207822,2.146989,29.618617,1.624467,0.01624467,-0.042144,1.582308,0.071467
1561,44659.51023,390.233478,58381082,20.707023,0.012241,0.133072,22.208338,2.149308,29.925988,1.626151,0.01626151,-0.042888,1.583263,0.072655
1568,44659.51026,391.983478,58381083,20.844653,0.012999,0.134091,22.209002,2.151198,30.117189,1.627309,0.01627309,-0.043447,1.583862,0.073464
1575,44659.51028,393.733478,58381085,21.002037,0.013801,0.135175,22.20937,2.15288,30.34722,1.628605,0.01628605,-0.044284,1.584323,0.074373
1582,44659.5103,395.483478,58381087,21.132155,0.014556,0.135866,22.20996,2.154574,30.546472,1.629836,0.01629836,-0.044935,1.584911,0.075233
1589,44659.51032,397.233478,58381089,21.274635,0.015329,0.136917,22.210623,2.1564,30.752004,1.631073,0.01631073,-0.0454,1.585672,0.076106
1596,44659.51034,398.983478,58381090,21.439008,0.016154,0.137838,22.210992,2.158073,30.978228,1.632333,0.01632333,-0.046331,1.586075,0.07703
1603,44659.51036,400.733478,58381092,21.558074,0.016828,0.138857,22.211876,2.159664,31.087023,1.633189,0.01633189,-0.047075,1.586189,0.077631
1610,44659.51038,402.483478,58381094,21.727099,0.017725,0.139777,22.212171,2.161635,31.391339,1.634786,0.01634786,-0.047633,1.587142,0.078688
1617,44659.5104,404.233478,58381096,21.857147,0.01844,0.140763,22.212982,2.163163,31.557475,1.635937,0.01635937,-0.048563,1.587298,0.079513
1624,44659.51042,405.983478,58381097,22.015911,0.019325,0.141749,22.213203,2.165201,31.812364,1.637332,0.01637332,-0.049401,1.588009,0.080476
1631,44659.51044,407.733478,58381099,22.157333,0.020073,0.142735,22.214235,2.166768,32.002012,1.638493,0.01638493,-0.049959,1.588538,0.081291
1638,44659.51046,409.483478,58381101,22.304712,0.020812,0.143754,22.214603,2.168551,32.24169,1.639831,0.01639831,-0.050703,1.589089,0.082197
1645,44659.51048,411.233478,58381103,22.452483,0.021634,0.144642,22.215562,2.170294,32.437023,1.64101,0.0164101,-0.05182,1.589285,0.083115
1652,44659.5105,412.983478,58381104,22.586032,0.022351,0.145562,22.215856,2.17205,32.646862,1.642293,0.01642293,-0.052471,1.589801,0.083932
1659,44659.51052,414.733478,58381106,22.731087,0.023165,0.146614,22.216815,2.173831,32.859041,1.643686,0.01643686,-0.053122,1.590437,0.084921
1666,44659.51054,416.483478,58381108,22.880157,0.023907,0.1476,22.217331,2.175433,33.075696,1.64479,0.0164479,-0.054425,1.590366,0.085645
1673,44659.51056,418.233478,58381110,23.015378,0.024667,0.148586,22.218215,2.177164,33.274283,1.646088,0.01646088,-0.054983,1.591007,0.086532
1680,44659.51058,419.983478,58381111,23.1665,0.025503,0.149474,22.218878,2.178994,33.479414,1.647367,0.01647367,-0.056192,1.591203,0.087515
1687,44659.5106,421.733478,58381113,23.305684,0.026313,0.150526,22.219542,2.180806,33.674942,1.64852,0.0164852,-0.056936,1.591584,0.088291
1694,44659.51062,423.483478,58381115,23.441141,0.027067,0.151413,22.220132,2.182672,33.874351,1.64979,0.0164979,-0.057681,1.592062,0.089274
1701,44659.51064,425.233478,58381117,23.571595,0.027739,0.152169,22.22109,2.184154,34.088385,1.651029,0.01651029,-0.058611,1.592356,0.090126
1708,44659.51066,426.983478,58381118,23.720384,0.028583,0.153418,22.221753,2.186009,34.267363,1.652246,0.01652246,-0.059821,1.592425,0.090932
1715,44659.51068,428.733478,58381120,23.866363,0.029379,0.154339,22.222564,2.187833,34.477925,1.653535,0.01653535,-0.060844,1.592728,0.09181
1722,44659.5107,430.483478,58381122,24.006971,0.030186,0.155325,22.223448,2.189671,34.678961,1.654797,0.01654797,-0.061681,1.593116,0.092758
1729,44659.51072,432.233478,58381124,24.152105,0.030947,0.156311,22.224186,2.191261,34.903986,1.656036,0.01656036,-0.062798,1.593236,0.093584
1736,44659.51074,433.983478,58381125,24.281955,0.031705,0.15733,22.225291,2.19299,35.099959,1.657299,0.01657299,-0.0641,1.5932,0.094415
1743,44659.51076,435.733478,58381127,24.396768,0.032517,0.158349,22.226028,2.194842,35.24511,1.658512,0.01658512,-0.06503,1.593573,0.095355
1750,44659.51078,437.483478,58381129,24.527394,0.033249,0.159236,22.226986,2.196384,35.45037,1.659791,0.01659791,-0.066333,1.593497,0.096278
1757,44659.5108,439.233478,58381131,24.66624,0.034025,0.160157,22.227871,2.19819,35.655051,1.661085,0.01661085,-0.067356,1.593751,0.097091
1764,44659.51082,440.983478,58381132,24.810238,0.03481,0.161143,22.228829,2.200062,35.842826,1.66238,0.0166238,-0.068473,1.593908,0.097998
1771,44659.51084,442.733478,58381134,24.943685,0.035555,0.16226,22.229861,2.201854,36.036597,1.663567,0.01663567,-0.069961,1.593559,0.098849
1778,44659.51086,444.483478,58381136,25.060397,0.036282,0.163246,22.230819,2.203324,36.219593,1.664757,0.01664757,-0.071264,1.593494,0.099657
1785,44659.51088,446.233478,58381138,25.203794,0.037049,0.164101,22.231999,2.205218,36.412673,1.665957,0.01665957,-0.072287,1.593643,0.100615
1792,44659.5109,447.983478,58381139,25.337218,0.037851,0.165087,22.232957,2.206994,36.617025,1.667323,0.01667323,-0.073869,1.593491,0.101486
1799,44659.51092,449.733478,58381141,25.463044,0.038625,0.166073,22.234357,2.208812,36.799996,1.668595,0.01668595,-0.07545,1.59318,0.102369
1806,44659.51094,451.483478,58381143,25.586228,0.039357,0.167256,22.235316,2.21035,36.964835,1.669729,0.01669729,-0.076846,1.592919,0.103138
1813,44659.51096,453.233478,58381145,25.709422,0.040092,0.168111,22.23679,2.212224,37.144145,1.671012,0.01671012,-0.078334,1.592678,0.104035
1820,44659.51098,454.983478,58381146,25.854791,0.040847,0.169031,22.237674,2.214061,37.349734,1.672293,0.01672293,-0.080009,1.592284,0.104989
1827,44659.511,456.733478,58381148,25.987007,0.041594,0.170083,22.239296,2.215746,37.549128,1.673556,0.01673556,-0.081683,1.591951,0.10587
1834,44659.51102,458.483478,58381150,26.090359,0.042353,0.171135,22.240254,2.217451,37.701428,1.674768,0.01674768,-0.083358,1.591482,0.106663
1841,44659.51105,460.233478,58381152,26.233553,0.043163,0.172154,22.242023,2.219395,37.909616,1.676192,0.01676192,-0.085126,1.591053,0.107659
1848,44659.51107,461.983478,58381153,26.320727,0.043825,0.173173,22.24335,2.22101,38.039042,1.677299,0.01677299,-0.087172,1.590127,0.1084
1855,44659.51109,463.733478,58381155,26.431989,0.044531,0.174192,22.245045,2.222637,38.206984,1.678477,0.01678477,-0.088661,1.58991,0.109323
1862,44659.51111,465.483478,58381157,26.558,0.045332,0.175047,22.246372,2.224443,38.376939,1.679743,0.01679743,-0.090894,1.58885,0.11014
1869,44659.51113,467.233478,58381159,26.658897,0.046027,0.176033,22.248067,2.226195,38.53619,1.681038,0.01681038,-0.092568,1.58847,0.11109
1876,44659.51115,468.983478,58381160,26.792457,0.046848,0.177117,22.249615,2.228043,38.72386,1.68236,0.0168236,-0.09508,1.587333,0.11201
1883,44659.51117,470.733478,58381162,26.920462,0.047644,0.178169,22.251531,2.229928,38.908332,1.683667,0.01683667,-0.097127,1.58654,0.112887
1890,44659.51119,472.483478,58381164,27.026862,0.048362,0.17909,22.253153,2.23155,39.055676,1.684907,0.01684907,-0.099546,1.585269,0.113755
1897,44659.51121,474.233478,58381166,27.135235,0.049091,0.180043,22.255438,2.233125,39.223323,1.686078,0.01686078,-0.102058,1.584103,0.114632
1904,44659.51123,475.983478,58381167,27.242116,0.049839,0.18116,22.257133,2.234961,39.373449,1.687346,0.01687346,-0.104291,1.583053,0.115525
1911,44659.51125,477.733478,58381169,27.358779,0.050617,0.182114,22.259345,2.236795,39.52905,1.688612,0.01688612,-0.106988,1.581608,0.116448
1918,44659.51127,479.483478,58381171,27.457448,0.051332,0.183133,22.261482,2.238336,39.682293,1.689928,0.01689928,-0.109779,1.580112,0.117307
1925,44659.51129,481.233478,58381173,27.566865,0.052105,0.184283,22.263841,2.240166,39.831076,1.691162,0.01691162,-0.11257,1.578592,0.11813
1932,44659.51131,482.983478,58381174,27.652514,0.052794,0.185203,22.2662,2.242044,39.953845,1.69232,0.0169232,-0.115641,1.576679,0.119032
1939,44659.51133,484.733478,58381176,27.743496,0.053524,0.186321,22.268706,2.243595,40.083374,1.693566,0.01693566,-0.118804,1.574763,0.119789
1946,44659.51135,486.483478,58381178,27.844646,0.054248,0.18711,22.271285,2.245386,40.221146,1.694826,0.01694826,-0.122153,1.572673,0.120693
1953,44659.51137,488.233478,58381180,27.927398,0.054996,0.188392,22.274234,2.247209,40.367516,1.696206,0.01696206,-0.125967,1.570281,0.121653
1960,44659.51139,489.983478,58381181,28.011624,0.055679,0.189444,22.277403,2.248973,40.484187,1.697412,0.01697412,-0.129689,1.567724,0.122554
1967,44659.51141,491.733478,58381183,28.094516,0.056415,0.19043,22.280352,2.250684,40.603541,1.698655,0.01698655,-0.133596,1.565059,0.123375
1974,44659.51143,493.483478,58381185,28.158183,0.057091,0.191646,22.283816,2.252499,40.698636,1.699863,0.01699863,-0.137783,1.562137,0.124217
1981,44659.51145,495.233478,58381187,28.2319,0.057776,0.192402,22.287133,2.254283,40.810223,1.701236,0.01701236,-0.142341,1.558962,0.125177
1988,44659.51147,496.983478,58381188,28.313052,0.058519,0.193618,22.291113,2.256082,40.914667,1.702384,0.01702384,-0.146714,1.555676,0.12598
1995,44659.51149,498.733478,58381190,28.370335,0.059253,0.194703,22.294651,2.257903,41.000654,1.703668,0.01703668,-0.151831,1.55192,0.127001
2002,44659.51151,500.483478,58381192,28.410123,0.059795,0.19559,22.298926,2.259341,41.077047,1.704837,0.01704837,-0.156854,1.547983,0.127696
2009,44659.51153,502.233478,58381194,28.471938,0.060513,0.196576,22.302685,2.261058,41.14329,1.705999,0.01705999,-0.161971,1.543968,0.128532
2016,44659.51155,503.983478,58381195,28.51672,0.061183,0.197694,22.307182,2.26281,41.213076,1.707364,0.01707364,-0.167181,1.540207,0.129481
2023,44659.51157,505.733478,58381197,28.587915,0.061937,0.198779,22.31153,2.264603,41.308481,1.708635,0.01708635,-0.172856,1.535779,0.130353
2030,44659.51159,507.483478,58381199,28.596625,0.062468,0.199765,22.316395,2.266169,41.337937,1.709773,0.01709773,-0.178996,1.53091,0.131242
2037,44659.51161,509.233478,58381201,28.654943,0.063197,0.201014,22.32126,2.268002,41.400734,1.710987,0.01710987,-0.185137,1.525833,0.132162
2044,44659.51163,510.983478,58381202,28.684604,0.06384,0.202263,22.32642,2.269856,41.45634,1.712297,0.01712297,-0.191649,1.520566,0.132914
2051,44659.51165,512.733478,58381204,28.710712,0.064482,0.20315,22.331948,2.271646,41.50042,1.71361,0.0171361,-0.198533,1.514968,0.133833
2058,44659.51167,514.483478,58381206,28.747327,0.065176,0.204301,22.337844,2.273529,41.5451,1.714822,0.01714822,-0.205976,1.508893,0.13468
2065,44659.51169,516.233478,58381208,28.752994,0.06581,0.205484,22.344331,2.275209,41.570193,1.716182,0.01716182,-0.21407,1.502148,0.135586
2072,44659.51171,517.983478,58381209,28.780152,0.066537,0.206536,22.350817,2.27734,41.608792,1.717536,0.01717536,-0.222536,1.494849,0.136633
2079,44659.51173,519.733478,58381211,28.737425,0.067058,0.207588,22.357967,2.278836,41.531739,1.718586,0.01718586,-0.231095,1.487617,0.137402
2086,44659.51175,521.483478,58381213,28.69975,0.067624,0.208738,22.364822,2.280261,41.486214,1.719821,0.01719821,-0.23984,1.47998,0.138145
2093,44659.51177,523.233478,58381215,28.66509,0.068277,0.209955,22.373225,2.282162,41.434749,1.721163,0.01721163,-0.250353,1.47081,0.139125
2100,44659.51179,524.983478,58381216,28.608785,0.068959,0.211269,22.383102,2.284334,41.367855,1.722584,0.01722584,-0.26282,1.459758,0.140157
2107,44659.51181,526.733478,58381218,28.464015,0.069498,0.212584,22.395706,2.286152,41.159029,1.723885,0.01723885,-0.278263,1.445506,0.14102
2114,44659.51183,528.483478,58381220,28.174023,0.069749,0.213767,22.412585,2.287599,40.747966,1.724787,0.01724787,-0.299382,1.425444,0.141651
2121,44659.51186,530.233478,58381222,25.324177,0.066967,0.218205,22.520716,2.289116,36.777724,1.72596,0.0172596,-0.430466,1.295436,0.1425
2128,44659.51188,531.983478,58381223,24.43988,0.066134,0.218599,22.555433,2.288993,35.383669,1.725885,0.01725885,-0.479681,1.246168,0.142419
2135,44659.5119,533.733478,58381225,24.082503,0.065836,0.21906,22.570175,2.288993,34.822039,1.72585,0.0172585,-0.498846,1.226983,0.142409
2142,44659.51192,535.483478,58381227,23.888789,0.065705,0.219191,22.578209,2.28907,34.528924,1.725918,0.01725918,-0.509172,1.216827,0.142442
2149,44659.51194,537.233478,58381229,23.697193,0.065503,0.219388,22.585432,2.288973,34.255593,1.725836,0.01725836,-0.518197,1.207608,0.142385
2156,44659.51196,538.983478,58381230,23.564331,0.0654,0.219487,22.591329,2.289068,34.10302,1.726064,0.01726064,-0.526012,1.200053,0.142544
2163,44659.51198,540.733478,58381232,23.49729,0.06554,0.220013,22.596047,2.289559,33.950669,1.726103,0.01726103,-0.531873,1.1942,0.142756
2170,44659.512,542.483478,58381234,23.390488,0.065415,0.220013,22.599585,2.28943,33.797973,1.726157,0.01726157,-0.53671,1.189446,0.142659
2177,44659.51202,544.233478,58381236,23.270033,0.065179,0.21975,22.602386,2.28906,33.629081,1.725915,0.01725915,-0.54006,1.185861,0.142468
2179,44659.51202,544.733478,58381236,23.251256,0.06516,0.219651,22.603196,2.289045,33.617337,1.725968,0.01725968,-0.540897,1.18499,0.14242